Workbook
Name Slicer_Year: #N/A

Sheet Cover Page

Sheet Summary
B2: Scenario: | D2: Base | F2: Afro Brunch and Fitness Studio Co | I2: Last Updated:
C5: Company Name: | F5: Afrobeats Brunch & Fitness Studio
C7: Sector: | F7: Food & Beverage / Boutique Fitness
C10: Owner Equity Contribution | F10: =Assumptions!$C$51 -> 40000
C11: Enterprise Value (DCF) | F11: =Valuation!$B$31 -> 271957.24
C12: Equity Value (DCF) | F12: =Valuation!$B$33 -> 233182.24
C13: Equity Value (EBITDA multiple, Mid case) | F13: =Valuation!$C$41 -> 488753.6
F15: Year 1 | G15: Year 2 | H15: Year 3 | I15: Year 4 | J15: Year 5
C16: Income Statement
C17: Revenue | F17: ='Income Statement'!B8 -> 194579.26 | G17: ='Income Statement'!C8 -> 285569.93 | H17: ='Income Statement'!D8 -> 308415.52 | I17: ='Income Statement'!E8 -> 326920.46 | J17: ='Income Statement'!F8 -> 336728.07
C18: Cost of Sales | F18: =-'Income Statement'!B10 -> -59069.823 | G18: =-'Income Statement'!C10 -> -86777.314 | H18: =-'Income Statement'!D10 -> -93719.499 | I18: =-'Income Statement'!E10 -> -99342.669 | J18: =-'Income Statement'!F10 -> -102322.95
C19: Gross Profit | F19: ='Income Statement'!B11 -> 135509.44 | G19: ='Income Statement'!C11 -> 198792.62 | H19: ='Income Statement'!D11 -> 214696.03 | I19: ='Income Statement'!E11 -> 227577.79 | J19: ='Income Statement'!F11 -> 234405.12
C20: Operating Expenses | F20: =-'Income Statement'!B22 -> -131116.3 | G20: =-'Income Statement'!C22 -> -136244.61 | H20: =-'Income Statement'!D22 -> -137824.28 | I20: =-'Income Statement'!E22 -> -139103.8 | J20: =-'Income Statement'!F22 -> -139781.96
C21: EBITDA | F21: ='Income Statement'!B24 -> 4393.1339 | G21: ='Income Statement'!C24 -> 62548.006 | H21: ='Income Statement'!D24 -> 76871.75 | I21: ='Income Statement'!E24 -> 88473.982 | J21: ='Income Statement'!F24 -> 94623.165
C22: Net Profit After Tax | F22: ='Income Statement'!B29 -> -13256.632 | G22: ='Income Statement'!C29 -> 35732.729 | H22: ='Income Statement'!D29 -> 47226.13 | I22: ='Income Statement'!E29 -> 56736.667 | J22: ='Income Statement'!F29 -> 62220.212
C24: Full detail: Income Statement, Balance Sheet, Cashflow statement, pivot Summary, and Valuation tabs. See Table of Content for a full map of this workbook.

Sheet Table of Content
B1: Scenario: | C1: Base | F1: Afro Brunch and Fitness Studio Co | L1: Last Updated: | M1: =TODAY() -> 46233
B5: S/N | C5: Details
B6: 1 | C6: Dasboard
B7: 2 | C7: Startup costs
B8: 3 | C8: Workings
B9: 4 | C9: Income statement
B10: 5 | C10: Balance Sheet
B11: 6 | C11: CashFlow Statement
B12: 7 | C12: Valuation
B13: 8 | C13: Scenario Analysis
B14: 9 | C14: Data
B15: 10 | C15: Assumptions
B16: 11 | C16: Seasonality Data Breakdown
B17: 12 | C17: Five year monthly
... B22: 17 | C22: Break Even

Sheet Dashboard
F1: Afro Brunch Café and Fitness studio
C2: 2
T23: =AVERAGE('monthly model engine'!Z8:Z68) -> 16849.683
S26: =AVERAGE('monthly model engine'!AU8:AU68) -> 3144.3184

Sheet Startup Costs
B2: Scenario: | C2: Base | E2: Afro Brunch and Fitness Studio Co | F2: Last Updated: | G2: =TODAY() -> 46233
A4: Startup (One-Off) Costs
A5: Capital required before opening day. Ranges reflect UK 2025-26 sources
A6: Item | B6: Low (£) | C6: High (£) | D6: Model Assumption (£) | E6: Source
A7: Rent deposit (3 months) + legal fees | B7: 6000 | C7: 12000 | D7: =Assumptions!$C$10*Assumptions!$C$9/12*Assumptions!$C$11+1500 -> 7500 | E7: Huxley & Co (2026): typical deposit 3-6 months' rent + solicitor fees; linked to Assumptions rent figures plus a £1,500 legal-fee estimate
A8: Café fit-out (light food service, no full kitchen) | B8: 11000 | C8: 30000 | D8: 18000 | E8: Huxley & Co (2026): kitchen fit-out for drinks + light snacks/sandwiches typically £11,000-£30,000
A9: Café equipment (espresso machine, grinder, fridge, dishwasher, POS) | B9: 10000 | C9: 15000 | D9: 12000 | E9: AT Coffee (2025) / Afida (2026): UK café equipment package typically £10,000-£15,000
A10: Fitness studio fit-out (flooring, mirrors, sound, lighting) | B10: 6000 | C10: 25000 | D10: 14000 | E10: CYC Fitness / RDX Wholesale (2026): boutique studio fit-out and specialist kit typically £6,000-£25,000
A11: Fitness equipment (mats, light weights, resistance bands) | B11: 2000 | C11: 8000 | D11: 4000 | E11: RDX Wholesale (2026): boutique studio (yoga/Pilates/dance-style) equipment £2,000-£8,000
A12: Café furniture (tables, chairs, shelving) | B12: 3000 | C12: 5000 | D12: 4000 | E12: AT Coffee (2025): furniture typically £3,000-£5,000
A13: Signage & shopfront | B13: 1000 | C13: 5000 | D13: 3000 | E13: Huxley & Co (2026): bifold doors £2,500-£5,000, canopy £1,000-£5,000; mid-range shopfront assumed
A14: Initial F&B stock | B14: 1500 | C14: 3000 | D14: 2000 | E14: AT Coffee (2025): initial stock (coffee, milk, pastries, packaging) typically £1,500-£3,000
A15: Licences, insurance setup, food hygiene registration, PPL PRS music licence | B15: 500 | C15: 3000 | D15: 2000 | E15: Grove HR (2026): PPL PRS licence £500-£1,500/yr, ICO registration £40/yr, food hygiene registration is free via local council; insurance setup estimated
A16: Marketing & launch campaign | B16: 1000 | C16: 3000 | D16: 2000 | E16: AT Coffee (2025): signage, logo design, launch campaign typically £1,000-£3,000
A17: Subtotal — fit-out, equipment & launch costs | D17: =SUM(D7:D16) -> 68500
A19: Contingency (15% of subtotal above) | D19: =D17*0.15 -> 10275 | E19: Resawod (2026): fit-out quotes routinely run over; build in a 15-20% contingency
A20: Working capital reserve (3 months of fixed operating costs) | D20: ='monthly model engine'!$AK$19*3 -> 31074.697 | E20: AT Coffee / Bellwether Coffee (2026): plan for 3-6 months of fixed costs as a cash buffer before trade builds; linked from Monthly P&L
A22: TOTAL STARTUP CAPITAL REQUIRED | D22: =D17+D19+D20 -> 109849.7
A24: of which: capitalised as fixed assets (fit-out, equipment, furniture, signage) | D24: =D8+D9+D10+D11+D12+D13 -> 55000 | E24: Feeds the opening Balance Sheet as Fixed Assets at cost. Excludes rent deposit, initial stock, licences and launch marketing, which are treated as expensed pre-trading costs.

Sheet Scenario Analysis
B1: Scenario: | C1: Base | E1: Afro Brunch and Fitness Studio Co | F1: Last Updated: | G1: =TODAY() -> 46233
A4: Scenario Switch — Base / Best / Worst Case
A5: ACTIVE SCENARIO: | B5: Base | H5: Worst
H6: Base
A7: Driver | B7: Worst Case | C7: Base Case | D7: Best Case | E7: Selected (active) | F7: Rationale | H7: Best
A8: Steady-state café covers/day | B8: 40 | C8: 65 | D8: 90 | E8: =CHOOSE(MATCH($B$5,{"Worst","Base","Best"},0),B8,C8,D8) -> 65 | F8: No public benchmark exists for this hybrid concept. Worst reflects slow footfall build; Best reflects strong local word-of-mouth.
A9: Classes run per week, steady state | B9: 8 | C9: 14 | D9: 20 | E9: =CHOOSE(MATCH($B$5,{"Worst","Base","Best"},0),B9,C9,D9) -> 14 | F9: Reflects a thinner (Worst) or fuller (Best) class timetable than the base daytime schedule, constrained by instructor availability and demand
A10: Paying monthly members, steady state | B10: 30 | C10: 55 | D10: 85 | E10: =CHOOSE(MATCH($B$5,{"Worst","Base","Best"},0),B10,C10,D10) -> 55 | F10: No benchmark exists for this concept. Worst assumes membership take-up stays low; Best assumes strong conversion from class attendees to members
A11: Year 2 revenue growth vs Year 1 | B11: 0.05 | C11: 0.15 | D11: 0.3 | E11: =CHOOSE(MATCH($B$5,{"Worst","Base","Best"},0),B11,C11,D11) -> 0.15 | F11: ASSUMPTION range, not a forecast — Worst assumes growth stalls after opening buzz fades; Best assumes strong repeat custom and word-of-mouth
A12: Year 3 revenue growth vs Year 2 | B12: 0.02 | C12: 0.08 | D12: 0.15 | E12: =CHOOSE(MATCH($B$5,{"Worst","Base","Best"},0),B12,C12,D12) -> 0.08 | F12: ASSUMPTION range — growth typically moderates as a single site approaches its capacity ceiling
A13: Year 4 revenue growth vs Year 3 | B13: 0 | C13: 0.06 | D13: 0.12 | E13: =CHOOSE(MATCH($B$5,{"Worst","Base","Best"},0),B13,C13,D13) -> 0.06 | F13: ASSUMPTION range - Worst assumes growth has fully stalled by Year 4; Best assumes the site still has room to grow before hitting a capacity ceiling
A14: Year 5 revenue growth vs Year 4 | B14: -0.03 | C14: 0.03 | D14: 0.08 | E14: =CHOOSE(MATCH($B$5,{"Worst","Base","Best"},0),B14,C14,D14) -> 0.03 | F14: ASSUMPTION range - Worst assumes slight decline as the concept ages without reinvestment; Best assumes modest continued growth
A16: NOTE: cost-side assumptions (rent, wages, food cost %, prices) are held constant across scenarios. Only footfall, class demand, membership take-up and multi-year growth vary - the assumptions with no external benchmark, flagged yellow on the Assumption Tab.
A22: Metric | B22: Worst Case | C22: Base Case | D22: Best Case
A23: Year 1 Revenue | B23: 117896 | C23: 194579 | D23: 270110
A24: Year 1 EBITDA | B24: -45246 | C24: 4393 | D24: 52934
A25: Year 5 Revenue | B25: 156104 | C25: 336728 | D25: 623497
A26: Year 5 EBITDA | B26: -20654 | C26: 94623 | D26: 277017
A27: Cash balance, end of Year 1 | B27: -30967 | C27: 14587 | D27: 56387
A28: Cash balance, end of Year 5 | B28: -173811 | C28: 197994 | D28: 677608

Sheet Assumptions
B1: Scenario: | C1: Base | E1: Afro Brunch and Fitness Studio Co | F1: Last Updated: | G1: =TODAY() -> 46233
A5: Assumptions
A6: All UK-sourced or explicitly flagged as an estimate. Location basis: Greater London, non-prime suburban high street, ~800 sq ft.
A7: Category | B7: Assumption | C7: Value | D7: Unit | E7: Source / Note
A8: PREMISES & LOCATION
A9: Premises | B9: Floor area | C9: 800 | D9: sq ft | E9: (small studio, under 1,000 sq ft)
A10: Premises | B10: Annual rent, Greater London suburban high street (non-prime) | C10: 30 | D10: £/sq ft/yr | E10: Huxley & Co (2026): London zones 2-6 typically £2,500-£5,000/month for a small unit; DOUBLE PUC Café (2025): suburban London £25-£50/sq ft vs. £60-£150 prime high street. Midpoint of suburban range used.
A11: Premises | B11: Rent deposit required | C11: 3 | D11: months | E11: Huxley & Co (2026): most landlords require 3-6 months' rent deposit
A12: Premises | B12: Business rates, net of relief (estimate) | C12: 1500 | D12: £/yr | E12: ESTIMATE. Small units are typically well under the £51,000 rateable-value threshold and commonly qualify for Small Business Rate Relief plus 75% Retail, Hospitality & Leisure relief, capped at £110,000/business (gov.uk; DineOpen, 2026). Actual rateable value must be confirmed with the VOA/local council before funding.
A13: Premises | B13: Utilities (gas/electric/water) | C13: 0.03 | D13: % of revenue | E13: Brikly (2026): UK cafés typically pay 2.5-3.5% of revenue on gas and electric
A14: Premises | B14: Insurance (public liability, contents, instructor indemnity) | C14: 1800 | D14: £/yr | E14: ESTIMATE — combined hospitality + fitness liability cover; obtain broker quotes (e.g. specialist gym/café insurers) before funding.
A15: Premises | B15: Card processing fees | C15: 0.0175 | D15: % of card revenue | E15: Brikly (2026): card mix is 90%+ in most UK cafés at an all-in cost of ~1.5-2%
A17: CAFÉ / BRUNCH REVENUE
A18: Café | B18: Trading days per year | C18: 313 | D18: days | E18: 6 days/week x 52 weeks; bsness.co.uk (2026): UK cafés typically trade 300-360 days/yr
A19: Café | B19: Steady-state covers per day | C19: ='Scenario Analysis'!$E$8 -> 65 | D19: covers | E19: ESTIMATE — no public benchmark exists for this hybrid concept.
A20: Café | B20: Average spend per head | C20: 8.5 | D20: £ | E20: bsness.co.uk (2026): UK café average spend per head is £5-£12; a brunch/food-forward menu is assumed to sit toward the upper-middle of this range.
A21: Café | B21: Food & drink cost of sales | C21: 0.3 | D21: % of café revenue | E21: The Caterer / AHBS Ltd benchmark (2025): UK food cost 28-32% of food sales, beverage 18-24% of beverage sales; 30% blended used
A23: FITNESS / AFROBEATS CLASSES
A24: Fitness | B24: Classes run per week, steady state | C24: ='Scenario Analysis'!$E$9 -> 14 | D24: classes | E24: ESTIMATE — a realistic daytime schedule for a small studio (school-run friendly slots)
A25: Fitness | B25: Average attendees per class | C25: 10 | D25: people | E25: ESTIMATE based on 800 sq ft floor capacity for a moderate-intensity dance/fitness class
A26: Fitness | B26: Drop-in class price | C26: 12 | D26: £ | E26: StudioGrowth (2026) and PayScale UK cite UK group fitness classes typically £10-£20-plus; priced at the accessible end to fit a community-first, non-premium positioning
A27: Fitness | B27: Paying monthly members, steady state | C27: ='Scenario Analysis'!$E$10 -> 55 | D27: members | E27: ESTIMATE — no public benchmark for this concept; treat as the number to validate via a pre-launch waiting list or founding-member offer.
A28: Fitness | B28: Monthly membership price (unlimited/bundled classes) | C28: 45 | D28: £/month | E28: Leisure DB 2025 State of the Fitness Industry: average UK gym membership £48.45/month (£76 in London). Priced below the national average to reflect community/accessible positioning.
A29: Fitness | B29: Freelance instructor rate per class | C29: 30 | D29: £/class | E29: Healthworks (2025): £25/hour for freelance class cover; activecareers.org.uk: freelance instructors typically earn up to £35/class outside London and £45/hour in London. Midpoint used for Greater London suburban location.
A31: STAFFING & WAGES
A32: Staffing | B32: Front-of-house / barista hours per week, steady state | C32: 65 | D32: hrs/wk | E32: ESTIMATE — covers opening hours with 2 staff overlapping at peak (e.g. 7am-3pm, 6 days)
A33: Staffing | B33: Front-of-house hourly wage | C33: 13.25 | D33: £/hr | E33: GOV.UK: National Living Wage (21+) is £12.71/hour from 1 April 2026. Set slightly above the statutory floor to aid retention in a customer-facing role.
A34: Staffing | B34: Owner/manager annual salary or draw | C34: 26000 | D34: £/yr | E34: ESTIMATE — below TRAINFITNESS UK fitness-manager guide range (£27,000-£50,000) to reflect a pre-revenue-proven, single-site startup
A35: Staffing | B35: Employer NI + auto-enrolment pension on wages | C35: 0.15 | D35: % of gross wages | E35: ESTIMATE combining current employer NI rate and minimum 3% auto-enrolment pension contribution
A37: OTHER OPERATING COSTS & TAX
A38: Opex | B38: Ongoing marketing | C38: 400 | D38: £/month | E38: ESTIMATE — local social media, launch offers, community partnerships
A39: Opex | B39: POS + class-booking software | C39: 150 | D39: £/month | E39: GoTeamUp (2026): studio/gym management software typically $100-$500/month
A40: Opex | B40: Cleaning, repairs, accountancy, admin | C40: 500 | D40: £/month | E40: ESTIMATE — combined light-touch back-office costs for a single small site
A41: Tax | B41: Corporation tax rate (small profits) | C41: 0.25 | D41: % | E41: bsness.co.uk (2026): current UK Corporation Tax main/small-profits rate is 25% for most small companies — confirm current rate and marginal relief with HMRC/accountant
A42: Tax | B42: VAT registration threshold | C42: 90000 | D42: £ turnover | E42: Current UK VAT registration threshold to be reconfirm on gov.uk before trading, as thresholds are reviewed periodically
A44: GROWTH ASSUMPTIONS (YEARS 2-3)
A45: Growth | B45: Year 2 revenue growth vs Year 1 | C45: ='Scenario Analysis'!$E$11 -> 0.15 | D45: % | E45: ASSUMPTION, not a forecast — a maturing single site commonly grows as awareness builds and word-of-mouth spreads
A46: Growth | B46: Year 3 revenue growth vs Year 2 | C46: ='Scenario Analysis'!$E$12 -> 0.08 | D46: % | E46: ASSUMPTION — growth typically slows as a single site approaches its capacity ceiling.
A48: Fitness | B48: Average classes attended per member, per month | C48: 6 | D48: classes/member/month | E48: ESTIMATE — assumes an unlimited member attends roughly 1.5x/week on average. No public benchmark exists
A50: FINANCING & DEPRECIATION
...

Sheet Seasonality Data Break down
B1: Scenario: | C1: Base | E1: Afro Brunch and Fitness Studio Co | F1: Last Updated: | G1: =TODAY() -> 46233
A4: Seasonality & Marketing Plan (repeats every year, Months 1-12 = Jan-Dec)
A6: Month # | B6: Month | C6: Cafe Seasonality Index | D6: Fitness Seasonality Index | E6: Summer Iced-Drink Spend Uplift (£) | F6: Social Media Ads (£) | G6: Local/Community Marketing (£) | H6: Referral/Loyalty Programme (£) | I6: Total Marketing Base (£) | J6: Rationale
A7: 1 | B7: January | C7: 0.85 | D7: 1.3 | E7: 0 | F7: 300 | G7: 150 | H7: 50 | I7: =F7+G7+H7 -> 500 | J7: Jan: post-holiday spending pullback for cafe; strong New Year fitness-resolution surge; heaviest paid-social push to capture resolution search demand
A8: 2 | B8: February | C8: 0.9 | D8: 1.2 | E8: 0 | F8: 200 | G8: 150 | H8: 50 | I8: =F8+G8+H8 -> 400 | J8: Feb: cafe still building back; fitness resolution demand starting to taper (well-documented gym drop-off pattern)
A9: 3 | B9: March | C9: 0.95 | D9: 1.05 | E9: 0 | F9: 150 | G9: 150 | H9: 50 | I9: =F9+G9+H9 -> 350 | J9: Mar: both approaching baseline as routines normalise
A10: 4 | B10: April | C10: 1 | D10: 1 | E10: 0 | F10: 150 | G10: 150 | H10: 75 | I10: =F10+G10+H10 -> 375 | J10: Apr: baseline month for both
A11: 5 | B11: May | C11: 1.05 | D11: 0.95 | E11: 0 | F11: 150 | G11: 200 | H11: 75 | I11: =F11+G11+H11 -> 425 | J11: May: cafe lifts into Mother's Day/spring; fitness starts easing as weather improves; referral spend ticks up
A12: 6 | B12: June | C12: 1.1 | D12: 0.85 | E12: 0.75 | F12: 250 | G12: 150 | H12: 75 | I12: =F12+G12+H12 -> 475 | J12: Jun: iced-drink/summer menu uplift begins; fitness dips as summer holidays start; summer social campaign begins
A13: 7 | B13: July | C13: 1.15 | D13: 0.8 | E13: 0.75 | F13: 250 | G13: 150 | H13: 75 | I13: =F13+G13+H13 -> 475 | J13: Jul: peak cafe summer trade; fitness at its lowest as holiday season peaks
A14: 8 | B14: August | C14: 1 | D14: 0.85 | E14: 0.75 | F14: 150 | G14: 150 | H14: 75 | I14: =F14+G14+H14 -> 375 | J14: Aug: cafe eases slightly as some regulars travel; fitness still subdued
A15: 9 | B15: September | C15: 0.95 | D15: 1.05 | E15: 0 | F15: 200 | G15: 200 | H15: 75 | I15: =F15+G15+H15 -> 475 | J15: Sep: 'back to routine' bump for fitness; cafe returns to baseline; local partnership push for the new term
A16: 10 | B16: October | C16: 1 | D16: 1 | E16: 0 | F16: 150 | G16: 150 | H16: 50 | I16: =F16+G16+H16 -> 350 | J16: Oct: both at baseline
A17: 11 | B17: November | C17: 1.05 | D17: 0.95 | E17: 0 | F17: 250 | G17: 200 | H17: 75 | I17: =F17+G17+H17 -> 525 | J17: Nov: cafe begins holiday-season lift (gatherings, gifting); fitness dips as routines disrupt; marketing ramps for the festive period
A18: 12 | B18: December | C18: 1.2 | D18: 0.8 | E18: 0 | F18: 300 | G18: 250 | H18: 100 | I18: =F18+G18+H18 -> 650 | J18: Dec: cafe peak (holiday brunches, gifting); fitness at its lowest (well-documented holiday attendance drop); heaviest festive marketing push
A20: Average (should be close to 1.00 for a seasonality index) | C20: =AVERAGE(C7:C18) -> 1.0166667 | D20: =AVERAGE(D7:D18) -> 0.98333333
A22: SOURCING NOTE
A23: These monthly indices are ESTIMATES, not measured local data - built from well-documented general seasonal patterns (January gym-membership surges and summer holiday attendance dips are widely reported industry-wide; UK hospitality holiday-season and summer trade upticks are similarly well documented in general terms) rather than data specific to this concept. There is no public dataset for a combined brunch-cafe/Afrobeats-fitness business.

Sheet 5-Year monthly
B1: Scenario: | C1: Base | E1: Afro Brunch and Fitness Studio Co | F1: Last Updated: | G1: =TODAY() -> 46233
A3: Monthly Profit & Loss
D4: Year 1 | P4: Year 2 | AB4: Year 3 | AN4: Year 4 | AZ4: Year 5
D5: ='monthly model engine'!D8 -> January Y1 | E5: ='monthly model engine'!D9 -> February Y1 | F5: ='monthly model engine'!D10 -> March Y1 | G5: ='monthly model engine'!D11 -> April Y1 | H5: ='monthly model engine'!D12 -> May Y1 | I5: ='monthly model engine'!D13 -> June Y1 | J5: ='monthly model engine'!D14 -> July Y1 | K5: ='monthly model engine'!D15 -> August Y1 | L5: ='monthly model engine'!D16 -> September Y1 | M5: ='monthly model engine'!D17 -> October Y1 | N5: ='monthly model engine'!D18 -> November Y1 | O5: ='monthly model engine'!D19 -> December Y1 | P5: ='monthly model engine'!D20 -> January Y2 | Q5: ='monthly model engine'!D21 -> February Y2 | R5: ='monthly model engine'!D22 -> March Y2 | S5: ='monthly model engine'!D23 -> April Y2 | T5: ='monthly model engine'!D24 -> May Y2 | U5: ='monthly model engine'!D25 -> June Y2 | V5: ='monthly model engine'!D26 -> July Y2 | W5: ='monthly model engine'!D27 -> August Y2 | X5: ='monthly model engine'!D28 -> September Y2 | Y5: ='monthly model engine'!D29 -> October Y2 | Z5: ='monthly model engine'!D30 -> November Y2 | AA5: ='monthly model engine'!D31 -> December Y2 | AB5: ='monthly model engine'!D32 -> January Y3 | AC5: ='monthly model engine'!D33 -> February Y3 | AD5: ='monthly model engine'!D34 -> March Y3 | AE5: ='monthly model engine'!D35 -> April Y3 | AF5: ='monthly model engine'!D36 -> May Y3 | AG5: ='monthly model engine'!D37 -> June Y3 | AH5: ='monthly model engine'!D38 -> July Y3 | AI5: ='monthly model engine'!D39 -> August Y3 | AJ5: ='monthly model engine'!D40 -> September Y3 | AK5: ='monthly model engine'!D41 -> October Y3 | AL5: ='monthly model engine'!D42 -> November Y3 | AM5: ='monthly model engine'!D43 -> December Y3 | AN5: ='monthly model engine'!D44 -> January Y4 | AO5: ='monthly model engine'!D45 -> February Y4 | AP5: ='monthly model engine'!D46 -> March Y4 | AQ5: ='monthly model engine'!D47 -> April Y4 | AR5: ='monthly model engine'!D48 -> May Y4 | AS5: ='monthly model engine'!D49 -> June Y4 | AT5: ='monthly model engine'!D50 -> July Y4 | AU5: ='monthly model engine'!D51 -> August Y4 | AV5: ='monthly model engine'!D52 -> September Y4 | AW5: ='monthly model engine'!D53 -> October Y4 | AX5: ='monthly model engine'!D54 -> November Y4 | AY5: ='monthly model engine'!D55 -> December Y4 | AZ5: ='monthly model engine'!D56 -> January Y5 | BA5: ='monthly model engine'!D57 -> February Y5 | BB5: ='monthly model engine'!D58 -> March Y5 | BC5: ='monthly model engine'!D59 -> April Y5 | BD5: ='monthly model engine'!D60 -> May Y5 | BE5: ='monthly model engine'!D61 -> June Y5 | BF5: ='monthly model engine'!D62 -> July Y5 | BG5: ='monthly model engine'!D63 -> August Y5 | BH5: ='monthly model engine'!D64 -> September Y5 | BI5: ='monthly model engine'!D65 -> October Y5 | BJ5: ='monthly model engine'!D66 -> November Y5 | BK5: ='monthly model engine'!D67 -> December Y5
A7: REVENUE
B8: Cafe revenue | D8: ='monthly model engine'!M8 -> 6124.6927 | E8: ='monthly model engine'!M9 -> 7133.4656 | F8: ='monthly model engine'!M10 -> 8488.1035 | G8: ='monthly model engine'!M11 -> 9799.5083 | H8: ='monthly model engine'!M12 -> 11197.379 | I8: ='monthly model engine'!M13 -> 13800.692 | J8: ='monthly model engine'!M14 -> 15329.746 | K8: ='monthly model engine'!M15 -> 14114.344 | L8: ='monthly model engine'!M16 -> 12869.06 | M8: ='monthly model engine'!M17 -> 13978.71 | N8: ='monthly model engine'!M18 -> 14980.278 | O8: ='monthly model engine'!M19 -> 17293.25 | P8: ='monthly model engine'!M20 -> 14086.793 | Q8: ='monthly model engine'!M21 -> 14915.428 | R8: ='monthly model engine'!M22 -> 15744.063 | S8: ='monthly model engine'!M23 -> 16572.698 | T8: ='monthly model engine'!M24 -> 17401.333 | U8: ='monthly model engine'!M25 -> 19838.494 | V8: ='monthly model engine'!M26 -> 20740.244 | W8: ='monthly model engine'!M27 -> 18034.995 | X8: ='monthly model engine'!M28 -> 15744.063 | Y8: ='monthly model engine'!M29 -> 16572.698 | Z8: ='monthly model engine'!M30 -> 17401.333 | AA8: ='monthly model engine'!M31 -> 19887.237 | AB8: ='monthly model engine'!M32 -> 15213.737 | AC8: ='monthly model engine'!M33 -> 16108.662 | AD8: ='monthly model engine'!M34 -> 17003.588 | AE8: ='monthly model engine'!M35 -> 17898.514 | AF8: ='monthly model engine'!M36 -> 18793.439 | AG8: ='monthly model engine'!M37 -> 21425.574 | AH8: ='monthly model engine'!M38 -> 22399.464 | AI8: ='monthly model engine'!M39 -> 19477.794 | AJ8: ='monthly model engine'!M40 -> 17003.588 | AK8: ='monthly model engine'!M41 -> 17898.514 | AL8: ='monthly model engine'!M42 -> 18793.439 | AM8: ='monthly model engine'!M43 -> 21478.217 | AN8: ='monthly model engine'!M44 -> 16126.561 | AO8: ='monthly model engine'!M45 -> 17075.182 | AP8: ='monthly model engine'!M46 -> 18023.803 | AQ8: ='monthly model engine'!M47 -> 18972.425 | AR8: ='monthly model engine'!M48 -> 19921.046 | AS8: ='monthly model engine'!M49 -> 22711.108 | AT8: ='monthly model engine'!M50 -> 23743.431 | AU8: ='monthly model engine'!M51 -> 20646.462 | AV8: ='monthly model engine'!M52 -> 18023.803 | AW8: ='monthly model engine'!M53 -> 18972.425 | AX8: ='monthly model engine'!M54 -> 19921.046 | AY8: ='monthly model engine'!M55 -> 22766.909 | AZ8: ='monthly model engine'!M56 -> 16610.358 | BA8: ='monthly model engine'!M57 -> 17587.438 | BB8: ='monthly model engine'!M58 -> 18564.517 | BC8: ='monthly model engine'!M59 -> 19541.597 | BD8: ='monthly model engine'!M60 -> 20518.677 | BE8: ='monthly model engine'!M61 -> 23392.441 | BF8: ='monthly model engine'!M62 -> 24455.734 | BG8: ='monthly model engine'!M63 -> 21265.856 | BH8: ='monthly model engine'!M64 -> 18564.517 | BI8: ='monthly model engine'!M65 -> 19541.597 | BJ8: ='monthly model engine'!M66 -> 20518.677 | BK8: ='monthly model engine'!M67 -> 23449.917
B9: Fitness revenue | D9: ='monthly model engine'!W8 -> 3013.1088 | E9: ='monthly model engine'!W9 -> 3337.5974 | F9: ='monthly model engine'!W10 -> 3346.2891 | G9: ='monthly model engine'!W11 -> 3592.5528 | H9: ='monthly model engine'!W12 -> 3743.2082 | I9: ='monthly model engine'!W13 -> 3644.7028 | J9: ='monthly model engine'!W14 -> 3708.4416 | K9: ='monthly model engine'!W15 -> 4186.4829 | L9: ='monthly model engine'!W16 -> 5475.7458 | M9: ='monthly model engine'!W17 -> 5446.7736 | N9: ='monthly model engine'!W18 -> 5339.5765 | O9: ='monthly model engine'!W19 -> 4635.552 | P9: ='monthly model engine'!W20 -> 8662.6878 | Q9: ='monthly model engine'!W21 -> 7996.3272 | R9: ='monthly model engine'!W22 -> 6996.7863 | S9: ='monthly model engine'!W23 -> 6663.606 | T9: ='monthly model engine'!W24 -> 6330.4257 | U9: ='monthly model engine'!W25 -> 5664.0651 | V9: ='monthly model engine'!W26 -> 5330.8848 | W9: ='monthly model engine'!W27 -> 5664.0651 | X9: ='monthly model engine'!W28 -> 6996.7863 | Y9: ='monthly model engine'!W29 -> 6663.606 | Z9: ='monthly model engine'!W30 -> 6330.4257 | AA9: ='monthly model engine'!W31 -> 5330.8848 | AB9: ='monthly model engine'!W32 -> 9355.7028 | AC9: ='monthly model engine'!W33 -> 8636.0334 | AD9: ='monthly model engine'!W34 -> 7556.5292 | AE9: ='monthly model engine'!W35 -> 7196.6945 | AF9: ='monthly model engine'!W36 -> 6836.8598 | AG9: ='monthly model engine'!W37 -> 6117.1903 | AH9: ='monthly model engine'!W38 -> 5757.3556 | AI9: ='monthly model engine'!W39 -> 6117.1903 | AJ9: ='monthly model engine'!W40 -> 7556.5292 | AK9: ='monthly model engine'!W41 -> 7196.6945 | AL9: ='monthly model engine'!W42 -> 6836.8598 | AM9: ='monthly model engine'!W43 -> 5757.3556 | AN9: ='monthly model engine'!W44 -> 9917.045 | AO9: ='monthly model engine'!W45 -> 9154.1954 | AP9: ='monthly model engine'!W46 -> 8009.921 | AQ9: ='monthly model engine'!W47 -> 7628.4961 | AR9: ='monthly model engine'!W48 -> 7247.0713 | AS9: ='monthly model engine'!W49 -> 6484.2217 | AT9: ='monthly model engine'!W50 -> 6102.7969 | AU9: ='monthly model engine'!W51 -> 6484.2217 | AV9: ='monthly model engine'!W52 -> 8009.921 | AW9: ='monthly model engine'!W53 -> 7628.4961 | AX9: ='monthly model engine'!W54 -> 7247.0713 | AY9: ='monthly model engine'!W55 -> 6102.7969 | AZ9: ='monthly model engine'!W56 -> 10214.556 | BA9: ='monthly model engine'!W57 -> 9428.8212 | BB9: ='monthly model engine'!W58 -> 8250.2186 | BC9: ='monthly model engine'!W59 -> 7857.351 | BD9: ='monthly model engine'!W60 -> 7464.4835 | BE9: ='monthly model engine'!W61 -> 6678.7484 | BF9: ='monthly model engine'!W62 -> 6285.8808 | BG9: ='monthly model engine'!W63 -> 6678.7484 | BH9: ='monthly model engine'!W64 -> 8250.2186 | BI9: ='monthly model engine'!W65 -> 7857.351 | BJ9: ='monthly model engine'!W66 -> 7464.4835 | BK9: ='monthly model engine'!W67 -> 6285.8808
B10: TOTAL REVENUE | D10: ='monthly model engine'!X8 -> 9137.8015 | E10: ='monthly model engine'!X9 -> 10471.063 | F10: ='monthly model engine'!X10 -> 11834.393 | G10: ='monthly model engine'!X11 -> 13392.061 | H10: ='monthly model engine'!X12 -> 14940.588 | I10: ='monthly model engine'!X13 -> 17445.394 | J10: ='monthly model engine'!X14 -> 19038.187 | K10: ='monthly model engine'!X15 -> 18300.827 | L10: ='monthly model engine'!X16 -> 18344.806 | M10: ='monthly model engine'!X17 -> 19425.484 | N10: ='monthly model engine'!X18 -> 20319.854 | O10: ='monthly model engine'!X19 -> 21928.802 | P10: ='monthly model engine'!X20 -> 22749.481 | Q10: ='monthly model engine'!X21 -> 22911.755 | R10: ='monthly model engine'!X22 -> 22740.849 | S10: ='monthly model engine'!X23 -> 23236.304 | T10: ='monthly model engine'!X24 -> 23731.759 | U10: ='monthly model engine'!X25 -> 25502.559 | V10: ='monthly model engine'!X26 -> 26071.129 | W10: ='monthly model engine'!X27 -> 23699.06 | X10: ='monthly model engine'!X28 -> 22740.849 | Y10: ='monthly model engine'!X29 -> 23236.304 | Z10: ='monthly model engine'!X30 -> 23731.759 | AA10: ='monthly model engine'!X31 -> 25218.122 | AB10: ='monthly model engine'!X32 -> 24569.44 | AC10: ='monthly model engine'!X33 -> 24744.696 | AD10: ='monthly model engine'!X34 -> 24560.117 | AE10: ='monthly model engine'!X35 -> 25095.208 | AF10: ='monthly model engine'!X36 -> 25630.299 | AG10: ='monthly model engine'!X37 -> 27542.764 | AH10: ='monthly model engine'!X38 -> 28156.819 | AI10: ='monthly model engine'!X39 -> 25594.985 | AJ10: ='monthly model engine'!X40 -> 24560.117 | AK10: ='monthly model engine'!X41 -> 25095.208 | AL10: ='monthly model engine'!X42 -> 25630.299 | AM10: ='monthly model engine'!X43 -> 27235.572 | AN10: ='monthly model engine'!X44 -> 26043.606 | AO10: ='monthly model engine'!X45 -> 26229.377 | AP10: ='monthly model engine'!X46 -> 26033.724 | AQ10: ='monthly model engine'!X47 -> 26600.921 | AR10: ='monthly model engine'!X48 -> 27168.117 | AS10: ='monthly model engine'!X49 -> 29195.33 | AT10: ='monthly model engine'!X50 -> 29846.228 | AU10: ='monthly model engine'!X51 -> 27130.684 | AV10: ='monthly model engine'!X52 -> 26033.724 | AW10: ='monthly model engine'!X53 -> 26600.921 | AX10: ='monthly model engine'!X54 -> 27168.117 | AY10: ='monthly model engine'!X55 -> 28869.706 | AZ10: ='monthly model engine'!X56 -> 26824.914 | BA10: ='monthly model engine'!X57 -> 27016.259 | BB10: ='monthly model engine'!X58 -> 26814.736 | BC10: ='monthly model engine'!X59 -> 27398.948 | BD10: ='monthly model engine'!X60 -> 27983.161 | BE10: ='monthly model engine'!X61 -> 30071.19 | BF10: ='monthly model engine'!X62 -> 30741.615 | BG10: ='monthly model engine'!X63 -> 27944.604 | BH10: ='monthly model engine'!X64 -> 26814.736 | BI10: ='monthly model engine'!X65 -> 27398.948 | BJ10: ='monthly model engine'!X66 -> 27983.161 | BK10: ='monthly model engine'!X67 -> 29735.798
A12: COST OF SALES
B13: Food & drink cost of sales | D13: ='monthly model engine'!N8 -> 1837.4078 | E13: ='monthly model engine'!N9 -> 2140.0397 | F13: ='monthly model engine'!N10 -> 2546.4311 | G13: ='monthly model engine'!N11 -> 2939.8525 | H13: ='monthly model engine'!N12 -> 3359.2138 | I13: ='monthly model engine'!N13 -> 4140.2075 | J13: ='monthly model engine'!N14 -> 4598.9237 | K13: ='monthly model engine'!N15 -> 4234.3031 | L13: ='monthly model engine'!N16 -> 3860.7181 | M13: ='monthly model engine'!N17 -> 4193.6131 | N13: ='monthly model engine'!N18 -> 4494.0833 | O13: ='monthly model engine'!N19 -> 5187.975 | P13: ='monthly model engine'!N20 -> 4226.038 | Q13: ='monthly model engine'!N21 -> 4474.6284 | R13: ='monthly model engine'!N22 -> 4723.2189 | S13: ='monthly model engine'!N23 -> 4971.8094 | T13: ='monthly model engine'!N24 -> 5220.3998 | U13: ='monthly model engine'!N25 -> 5951.5483 | V13: ='monthly model engine'!N26 -> 6222.0732 | W13: ='monthly model engine'!N27 -> 5410.4984 | X13: ='monthly model engine'!N28 -> 4723.2189 | Y13: ='monthly model engine'!N29 -> 4971.8094 | Z13: ='monthly model engine'!N30 -> 5220.3998 | AA13: ='monthly model engine'!N31 -> 5966.1712 | AB13: ='monthly model engine'!N32 -> 4564.121 | AC13: ='monthly model engine'!N33 -> 4832.5987 | AD13: ='monthly model engine'!N34 -> 5101.0764 | AE13: ='monthly model engine'!N35 -> 5369.5541 | AF13: ='monthly model engine'!N36 -> 5638.0318 | AG13: ='monthly model engine'!N37 -> 6427.6721 | AH13: ='monthly model engine'!N38 -> 6719.8391 | AI13: ='monthly model engine'!N39 -> 5843.3383 | AJ13: ='monthly model engine'!N40 -> 5101.0764 | AK13: ='monthly model engine'!N41 -> 5369.5541 | AL13: ='monthly model engine'!N42 -> 5638.0318 | AM13: ='monthly model engine'!N43 -> 6443.465 | AN13: ='monthly model engine'!N44 -> 4837.9683 | AO13: ='monthly model engine'!N45 -> 5122.5546 | AP13: ='monthly model engine'!N46 -> 5407.141 | AQ13: ='monthly model engine'!N47 -> 5691.7274 | AR13: ='monthly model engine'!N48 -> 5976.3137 | AS13: ='monthly model engine'!N49 -> 6813.3325 | AT13: ='monthly model engine'!N50 -> 7123.0294 | AU13: ='monthly model engine'!N51 -> 6193.9386 | AV13: ='monthly model engine'!N52 -> 5407.141 | AW13: ='monthly model engine'!N53 -> 5691.7274 | AX13: ='monthly model engine'!N54 -> 5976.3137 | AY13: ='monthly model engine'!N55 -> 6830.0728 | AZ13: ='monthly model engine'!N56 -> 4983.1073 | BA13: ='monthly model engine'!N57 -> 5276.2313 | BB13: ='monthly model engine'!N58 -> 5569.3552 | BC13: ='monthly model engine'!N59 -> 5862.4792 | BD13: ='monthly model engine'!N60 -> 6155.6032 | BE13: ='monthly model engine'!N61 -> 7017.7324 | BF13: ='monthly model engine'!N62 -> 7336.7203 | BG13: ='monthly model engine'!N63 -> 6379.7568 | BH13: ='monthly model engine'!N64 -> 5569.3552 | BI13: ='monthly model engine'!N65 -> 5862.4792 | BJ13: ='monthly model engine'!N66 -> 6155.6032 | BK13: ='monthly model engine'!N67 -> 7034.975
B14: Freelance instructor costs | D14: ='monthly model engine'!V8 -> 946.3272 | E14: ='monthly model engine'!V9 -> 1048.2394 | F14: ='monthly model engine'!V10 -> 1050.9692 | G14: ='monthly model engine'!V11 -> 1128.3132 | H14: ='monthly model engine'!V12 -> 1175.6296 | I14: ='monthly model engine'!V13 -> 1144.6919 | J14: ='monthly model engine'!V14 -> 1164.7104 | K14: ='monthly model engine'!V15 -> 1314.8489 | L14: ='monthly model engine'!V16 -> 1719.7677 | M14: ='monthly model engine'!V17 -> 1710.6684 | N14: ='monthly model engine'!V18 -> 1677.001 | O14: ='monthly model engine'!V19 -> 1455.888 | P14: ='monthly model engine'!V20 -> 2720.6907 | Q14: ='monthly model engine'!V21 -> 2511.4068 | R14: ='monthly model engine'!V22 -> 2197.481 | S14: ='monthly model engine'!V23 -> 2092.839 | T14: ='monthly model engine'!V24 -> 1988.197 | U14: ='monthly model engine'!V25 -> 1778.9132 | V14: ='monthly model engine'!V26 -> 1674.2712 | W14: ='monthly model engine'!V27 -> 1778.9132 | X14: ='monthly model engine'!V28 -> 2197.481 | Y14: ='monthly model engine'!V29 -> 2092.839 | Z14: ='monthly model engine'!V30 -> 1988.197 | AA14: ='monthly model engine'!V31 -> 1674.2712 | AB14: ='monthly model engine'!V32 -> 2938.346 | AC14: ='monthly model engine'!V33 -> 2712.3193 | AD14: ='monthly model engine'!V34 -> 2373.2794 | AE14: ='monthly model engine'!V35 -> 2260.2661 | AF14: ='monthly model engine'!V36 -> 2147.2528 | AG14: ='monthly model engine'!V37 -> 1921.2262 | AH14: ='monthly model engine'!V38 -> 1808.2129 | AI14: ='monthly model engine'!V39 -> 1921.2262 | AJ14: ='monthly model engine'!V40 -> 2373.2794 | AK14: ='monthly model engine'!V41 -> 2260.2661 | AL14: ='monthly model engine'!V42 -> 2147.2528 | AM14: ='monthly model engine'!V43 -> 1808.2129 | AN14: ='monthly model engine'!V44 -> 3114.6467 | AO14: ='monthly model engine'!V45 -> 2875.0585 | AP14: ='monthly model engine'!V46 -> 2515.6762 | AQ14: ='monthly model engine'!V47 -> 2395.8821 | AR14: ='monthly model engine'!V48 -> 2276.088 | AS14: ='monthly model engine'!V49 -> 2036.4998 | AT14: ='monthly model engine'!V50 -> 1916.7057 | AU14: ='monthly model engine'!V51 -> 2036.4998 | AV14: ='monthly model engine'!V52 -> 2515.6762 | AW14: ='monthly model engine'!V53 -> 2395.8821 | AX14: ='monthly model engine'!V54 -> 2276.088 | AY14: ='monthly model engine'!V55 -> 1916.7057 | AZ14: ='monthly model engine'!V56 -> 3208.0861 | BA14: ='monthly model engine'!V57 -> 2961.3103 | BB14: ='monthly model engine'!V58 -> 2591.1465 | BC14: ='monthly model engine'!V59 -> 2467.7585 | BD14: ='monthly model engine'!V60 -> 2344.3706 | BE14: ='monthly model engine'!V61 -> 2097.5948 | BF14: ='monthly model engine'!V62 -> 1974.2068 | BG14: ='monthly model engine'!V63 -> 2097.5948 | BH14: ='monthly model engine'!V64 -> 2591.1465 | BI14: ='monthly model engine'!V65 -> 2467.7585 | BJ14: ='monthly model engine'!V66 -> 2344.3706 | BK14: ='monthly model engine'!V67 -> 1974.2068
B15: TOTAL COST OF SALES | D15: ='monthly model engine'!Y8 -> 2783.735 | E15: ='monthly model engine'!Y9 -> 3188.279 | F15: ='monthly model engine'!Y10 -> 3597.4002 | G15: ='monthly model engine'!Y11 -> 4068.1657 | H15: ='monthly model engine'!Y12 -> 4534.8434 | I15: ='monthly model engine'!Y13 -> 5284.8994 | J15: ='monthly model engine'!Y14 -> 5763.6341 | K15: ='monthly model engine'!Y15 -> 5549.152 | L15: ='monthly model engine'!Y16 -> 5580.4858 | M15: ='monthly model engine'!Y17 -> 5904.2815 | N15: ='monthly model engine'!Y18 -> 6171.0843 | O15: ='monthly model engine'!Y19 -> 6643.863 | P15: ='monthly model engine'!Y20 -> 6946.7287 | Q15: ='monthly model engine'!Y21 -> 6986.0352 | R15: ='monthly model engine'!Y22 -> 6920.6999 | S15: ='monthly model engine'!Y23 -> 7064.6484 | T15: ='monthly model engine'!Y24 -> 7208.5969 | U15: ='monthly model engine'!Y25 -> 7730.4614 | V15: ='monthly model engine'!Y26 -> 7896.3444 | W15: ='monthly model engine'!Y27 -> 7189.4116 | X15: ='monthly model engine'!Y28 -> 6920.6999 | Y15: ='monthly model engine'!Y29 -> 7064.6484 | Z15: ='monthly model engine'!Y30 -> 7208.5969 | AA15: ='monthly model engine'!Y31 -> 7640.4424 | AB15: ='monthly model engine'!Y32 -> 7502.467 | AC15: ='monthly model engine'!Y33 -> 7544.9181 | AD15: ='monthly model engine'!Y34 -> 7474.3558 | AE15: ='monthly model engine'!Y35 -> 7629.8202 | AF15: ='monthly model engine'!Y36 -> 7785.2846 | AG15: ='monthly model engine'!Y37 -> 8348.8983 | AH15: ='monthly model engine'!Y38 -> 8528.052 | AI15: ='monthly model engine'!Y39 -> 7764.5645 | AJ15: ='monthly model engine'!Y40 -> 7474.3558 | AK15: ='monthly model engine'!Y41 -> 7629.8202 | AL15: ='monthly model engine'!Y42 -> 7785.2846 | AM15: ='monthly model engine'!Y43 -> 8251.6778 | AN15: ='monthly model engine'!Y44 -> 7952.615 | AO15: ='monthly model engine'!Y45 -> 7997.6131 | AP15: ='monthly model engine'!Y46 -> 7922.8172 | AQ15: ='monthly model engine'!Y47 -> 8087.6095 | AR15: ='monthly model engine'!Y48 -> 8252.4017 | AS15: ='monthly model engine'!Y49 -> 8849.8322 | AT15: ='monthly model engine'!Y50 -> 9039.7351 | AU15: ='monthly model engine'!Y51 -> 8230.4384 | AV15: ='monthly model engine'!Y52 -> 7922.8172 | AW15: ='monthly model engine'!Y53 -> 8087.6095 | AX15: ='monthly model engine'!Y54 -> 8252.4017 | AY15: ='monthly model engine'!Y55 -> 8746.7785 | AZ15: ='monthly model engine'!Y56 -> 8191.1934 | BA15: ='monthly model engine'!Y57 -> 8237.5415 | BB15: ='monthly model engine'!Y58 -> 8160.5017 | BC15: ='monthly model engine'!Y59 -> 8330.2377 | BD15: ='monthly model engine'!Y60 -> 8499.9738 | BE15: ='monthly model engine'!Y61 -> 9115.3272 | BF15: ='monthly model engine'!Y62 -> 9310.9271 | BG15: ='monthly model engine'!Y63 -> 8477.3515 | BH15: ='monthly model engine'!Y64 -> 8160.5017 | BI15: ='monthly model engine'!Y65 -> 8330.2377 | BJ15: ='monthly model engine'!Y66 -> 8499.9738 | BK15: ='monthly model engine'!Y67 -> 9009.1819
B17: GROSS PROFIT | D17: ='monthly model engine'!Z8 -> 6354.0665 | E17: ='monthly model engine'!Z9 -> 7282.784 | F17: ='monthly model engine'!Z10 -> 8236.9924 | G17: ='monthly model engine'!Z11 -> 9323.8954 | H17: ='monthly model engine'!Z12 -> 10405.744 | I17: ='monthly model engine'!Z13 -> 12160.495 | J17: ='monthly model engine'!Z14 -> 13274.553 | K17: ='monthly model engine'!Z15 -> 12751.675 | L17: ='monthly model engine'!Z16 -> 12764.32 | M17: ='monthly model engine'!Z17 -> 13521.202 | N17: ='monthly model engine'!Z18 -> 14148.77 | O17: ='monthly model engine'!Z19 -> 15284.939 | P17: ='monthly model engine'!Z20 -> 15802.752 | Q17: ='monthly model engine'!Z21 -> 15925.72 | R17: ='monthly model engine'!Z22 -> 15820.149 | S17: ='monthly model engine'!Z23 -> 16171.656 | T17: ='monthly model engine'!Z24 -> 16523.162 | U17: ='monthly model engine'!Z25 -> 17772.098 | V17: ='monthly model engine'!Z26 -> 18174.784 | W17: ='monthly model engine'!Z27 -> 16509.648 | X17: ='monthly model engine'!Z28 -> 15820.149 | Y17: ='monthly model engine'!Z29 -> 16171.656 | Z17: ='monthly model engine'!Z30 -> 16523.162 | AA17: ='monthly model engine'!Z31 -> 17577.68 | AB17: ='monthly model engine'!Z32 -> 17066.973 | AC17: ='monthly model engine'!Z33 -> 17199.778 | AD17: ='monthly model engine'!Z34 -> 17085.761 | AE17: ='monthly model engine'!Z35 -> 17465.388 | AF17: ='monthly model engine'!Z36 -> 17845.015 | AG17: ='monthly model engine'!Z37 -> 19193.866 | AH17: ='monthly model engine'!Z38 -> 19628.767 | AI17: ='monthly model engine'!Z39 -> 17830.42 | AJ17: ='monthly model engine'!Z40 -> 17085.761 | AK17: ='monthly model engine'!Z41 -> 17465.388 | AL17: ='monthly model engine'!Z42 -> 17845.015 | AM17: ='monthly model engine'!Z43 -> 18983.894 | AN17: ='monthly model engine'!Z44 -> 18090.991 | AO17: ='monthly model engine'!Z45 -> 18231.764 | AP17: ='monthly model engine'!Z46 -> 18110.907 | AQ17: ='monthly model engine'!Z47 -> 18513.311 | AR17: ='monthly model engine'!Z48 -> 18915.715 | AS17: ='monthly model engine'!Z49 -> 20345.498 | AT17: ='monthly model engine'!Z50 -> 20806.493 | AU17: ='monthly model engine'!Z51 -> 18900.245 | AV17: ='monthly model engine'!Z52 -> 18110.907 | AW17: ='monthly model engine'!Z53 -> 18513.311 | AX17: ='monthly model engine'!Z54 -> 18915.715 | AY17: ='monthly model engine'!Z55 -> 20122.928 | AZ17: ='monthly model engine'!Z56 -> 18633.721 | BA17: ='monthly model engine'!Z57 -> 18778.717 | BB17: ='monthly model engine'!Z58 -> 18654.234 | BC17: ='monthly model engine'!Z59 -> 19068.711 | BD17: ='monthly model engine'!Z60 -> 19483.187 | BE17: ='monthly model engine'!Z61 -> 20955.863 | BF17: ='monthly model engine'!Z62 -> 21430.688 | BG17: ='monthly model engine'!Z63 -> 19467.253 | BH17: ='monthly model engine'!Z64 -> 18654.234 | BI17: ='monthly model engine'!Z65 -> 19068.711 | BJ17: ='monthly model engine'!Z66 -> 19483.187 | BK17: ='monthly model engine'!Z67 -> 20726.616
A19: FIXED OPERATING EXPENSES
B20: Rent | D20: ='monthly model engine'!AA8 -> 2000 | E20: ='monthly model engine'!AA9 -> 2000 | F20: ='monthly model engine'!AA10 -> 2000 | G20: ='monthly model engine'!AA11 -> 2000 | H20: ='monthly model engine'!AA12 -> 2000 | I20: ='monthly model engine'!AA13 -> 2000 | J20: ='monthly model engine'!AA14 -> 2000 | K20: ='monthly model engine'!AA15 -> 2000 | L20: ='monthly model engine'!AA16 -> 2000 | M20: ='monthly model engine'!AA17 -> 2000 | N20: ='monthly model engine'!AA18 -> 2000 | O20: ='monthly model engine'!AA19 -> 2000 | P20: ='monthly model engine'!AA20 -> 2000 | Q20: ='monthly model engine'!AA21 -> 2000 | R20: ='monthly model engine'!AA22 -> 2000 | S20: ='monthly model engine'!AA23 -> 2000 | T20: ='monthly model engine'!AA24 -> 2000 | U20: ='monthly model engine'!AA25 -> 2000 | V20: ='monthly model engine'!AA26 -> 2000 | W20: ='monthly model engine'!AA27 -> 2000 | X20: ='monthly model engine'!AA28 -> 2000 | Y20: ='monthly model engine'!AA29 -> 2000 | Z20: ='monthly model engine'!AA30 -> 2000 | AA20: ='monthly model engine'!AA31 -> 2000 | AB20: ='monthly model engine'!AA32 -> 2000 | AC20: ='monthly model engine'!AA33 -> 2000 | AD20: ='monthly model engine'!AA34 -> 2000 | AE20: ='monthly model engine'!AA35 -> 2000 | AF20: ='monthly model engine'!AA36 -> 2000 | AG20: ='monthly model engine'!AA37 -> 2000 | AH20: ='monthly model engine'!AA38 -> 2000 | AI20: ='monthly model engine'!AA39 -> 2000 | AJ20: ='monthly model engine'!AA40 -> 2000 | AK20: ='monthly model engine'!AA41 -> 2000 | AL20: ='monthly model engine'!AA42 -> 2000 | AM20: ='monthly model engine'!AA43 -> 2000 | AN20: ='monthly model engine'!AA44 -> 2000 | AO20: ='monthly model engine'!AA45 -> 2000 | AP20: ='monthly model engine'!AA46 -> 2000 | AQ20: ='monthly model engine'!AA47 -> 2000 | AR20: ='monthly model engine'!AA48 -> 2000 | AS20: ='monthly model engine'!AA49 -> 2000 | AT20: ='monthly model engine'!AA50 -> 2000 | AU20: ='monthly model engine'!AA51 -> 2000 | AV20: ='monthly model engine'!AA52 -> 2000 | AW20: ='monthly model engine'!AA53 -> 2000 | AX20: ='monthly model engine'!AA54 -> 2000 | AY20: ='monthly model engine'!AA55 -> 2000 | AZ20: ='monthly model engine'!AA56 -> 2000 | BA20: ='monthly model engine'!AA57 -> 2000 | BB20: ='monthly model engine'!AA58 -> 2000 | BC20: ='monthly model engine'!AA59 -> 2000 | BD20: ='monthly model engine'!AA60 -> 2000 | BE20: ='monthly model engine'!AA61 -> 2000 | BF20: ='monthly model engine'!AA62 -> 2000 | BG20: ='monthly model engine'!AA63 -> 2000 | BH20: ='monthly model engine'!AA64 -> 2000 | BI20: ='monthly model engine'!AA65 -> 2000 | BJ20: ='monthly model engine'!AA66 -> 2000 | BK20: ='monthly model engine'!AA67 -> 2000
B21: Business rates | D21: ='monthly model engine'!AB8 -> 125 | E21: ='monthly model engine'!AB9 -> 125 | F21: ='monthly model engine'!AB10 -> 125 | G21: ='monthly model engine'!AB11 -> 125 | H21: ='monthly model engine'!AB12 -> 125 | I21: ='monthly model engine'!AB13 -> 125 | J21: ='monthly model engine'!AB14 -> 125 | K21: ='monthly model engine'!AB15 -> 125 | L21: ='monthly model engine'!AB16 -> 125 | M21: ='monthly model engine'!AB17 -> 125 | N21: ='monthly model engine'!AB18 -> 125 | O21: ='monthly model engine'!AB19 -> 125 | P21: ='monthly model engine'!AB20 -> 125 | Q21: ='monthly model engine'!AB21 -> 125 | R21: ='monthly model engine'!AB22 -> 125 | S21: ='monthly model engine'!AB23 -> 125 | T21: ='monthly model engine'!AB24 -> 125 | U21: ='monthly model engine'!AB25 -> 125 | V21: ='monthly model engine'!AB26 -> 125 | W21: ='monthly model engine'!AB27 -> 125 | X21: ='monthly model engine'!AB28 -> 125 | Y21: ='monthly model engine'!AB29 -> 125 | Z21: ='monthly model engine'!AB30 -> 125 | AA21: ='monthly model engine'!AB31 -> 125 | AB21: ='monthly model engine'!AB32 -> 125 | AC21: ='monthly model engine'!AB33 -> 125 | AD21: ='monthly model engine'!AB34 -> 125 | AE21: ='monthly model engine'!AB35 -> 125 | AF21: ='monthly model engine'!AB36 -> 125 | AG21: ='monthly model engine'!AB37 -> 125 | AH21: ='monthly model engine'!AB38 -> 125 | AI21: ='monthly model engine'!AB39 -> 125 | AJ21: ='monthly model engine'!AB40 -> 125 | AK21: ='monthly model engine'!AB41 -> 125 | AL21: ='monthly model engine'!AB42 -> 125 | AM21: ='monthly model engine'!AB43 -> 125 | AN21: ='monthly model engine'!AB44 -> 125 | AO21: ='monthly model engine'!AB45 -> 125 | AP21: ='monthly model engine'!AB46 -> 125 | AQ21: ='monthly model engine'!AB47 -> 125 | AR21: ='monthly model engine'!AB48 -> 125 | AS21: ='monthly model engine'!AB49 -> 125 | AT21: ='monthly model engine'!AB50 -> 125 | AU21: ='monthly model engine'!AB51 -> 125 | AV21: ='monthly model engine'!AB52 -> 125 | AW21: ='monthly model engine'!AB53 -> 125 | AX21: ='monthly model engine'!AB54 -> 125 | AY21: ='monthly model engine'!AB55 -> 125 | AZ21: ='monthly model engine'!AB56 -> 125 | BA21: ='monthly model engine'!AB57 -> 125 | BB21: ='monthly model engine'!AB58 -> 125 | BC21: ='monthly model engine'!AB59 -> 125 | BD21: ='monthly model engine'!AB60 -> 125 | BE21: ='monthly model engine'!AB61 -> 125 | BF21: ='monthly model engine'!AB62 -> 125 | BG21: ='monthly model engine'!AB63 -> 125 | BH21: ='monthly model engine'!AB64 -> 125 | BI21: ='monthly model engine'!AB65 -> 125 | BJ21: ='monthly model engine'!AB66 -> 125 | BK21: ='monthly model engine'!AB67 -> 125
B22: Insurance | D22: ='monthly model engine'!AC8 -> 150 | E22: ='monthly model engine'!AC9 -> 150 | F22: ='monthly model engine'!AC10 -> 150 | G22: ='monthly model engine'!AC11 -> 150 | H22: ='monthly model engine'!AC12 -> 150 | I22: ='monthly model engine'!AC13 -> 150 | J22: ='monthly model engine'!AC14 -> 150 | K22: ='monthly model engine'!AC15 -> 150 | L22: ='monthly model engine'!AC16 -> 150 | M22: ='monthly model engine'!AC17 -> 150 | N22: ='monthly model engine'!AC18 -> 150 | O22: ='monthly model engine'!AC19 -> 150 | P22: ='monthly model engine'!AC20 -> 150 | Q22: ='monthly model engine'!AC21 -> 150 | R22: ='monthly model engine'!AC22 -> 150 | S22: ='monthly model engine'!AC23 -> 150 | T22: ='monthly model engine'!AC24 -> 150 | U22: ='monthly model engine'!AC25 -> 150 | V22: ='monthly model engine'!AC26 -> 150 | W22: ='monthly model engine'!AC27 -> 150 | X22: ='monthly model engine'!AC28 -> 150 | Y22: ='monthly model engine'!AC29 -> 150 | Z22: ='monthly model engine'!AC30 -> 150 | AA22: ='monthly model engine'!AC31 -> 150 | AB22: ='monthly model engine'!AC32 -> 150 | AC22: ='monthly model engine'!AC33 -> 150 | AD22: ='monthly model engine'!AC34 -> 150 | AE22: ='monthly model engine'!AC35 -> 150 | AF22: ='monthly model engine'!AC36 -> 150 | AG22: ='monthly model engine'!AC37 -> 150 | AH22: ='monthly model engine'!AC38 -> 150 | AI22: ='monthly model engine'!AC39 -> 150 | AJ22: ='monthly model engine'!AC40 -> 150 | AK22: ='monthly model engine'!AC41 -> 150 | AL22: ='monthly model engine'!AC42 -> 150 | AM22: ='monthly model engine'!AC43 -> 150 | AN22: ='monthly model engine'!AC44 -> 150 | AO22: ='monthly model engine'!AC45 -> 150 | AP22: ='monthly model engine'!AC46 -> 150 | AQ22: ='monthly model engine'!AC47 -> 150 | AR22: ='monthly model engine'!AC48 -> 150 | AS22: ='monthly model engine'!AC49 -> 150 | AT22: ='monthly model engine'!AC50 -> 150 | AU22: ='monthly model engine'!AC51 -> 150 | AV22: ='monthly model engine'!AC52 -> 150 | AW22: ='monthly model engine'!AC53 -> 150 | AX22: ='monthly model engine'!AC54 -> 150 | AY22: ='monthly model engine'!AC55 -> 150 | AZ22: ='monthly model engine'!AC56 -> 150 | BA22: ='monthly model engine'!AC57 -> 150 | BB22: ='monthly model engine'!AC58 -> 150 | BC22: ='monthly model engine'!AC59 -> 150 | BD22: ='monthly model engine'!AC60 -> 150 | BE22: ='monthly model engine'!AC61 -> 150 | BF22: ='monthly model engine'!AC62 -> 150 | BG22: ='monthly model engine'!AC63 -> 150 | BH22: ='monthly model engine'!AC64 -> 150 | BI22: ='monthly model engine'!AC65 -> 150 | BJ22: ='monthly model engine'!AC66 -> 150 | BK22: ='monthly model engine'!AC67 -> 150
B23: Wages (incl. NI/pension) | D23: ='monthly model engine'!AD8 -> 6783.2324 | E23: ='monthly model engine'!AD9 -> 6783.2324 | F23: ='monthly model engine'!AD10 -> 6783.2324 | G23: ='monthly model engine'!AD11 -> 6783.2324 | H23: ='monthly model engine'!AD12 -> 6783.2324 | I23: ='monthly model engine'!AD13 -> 6783.2324 | J23: ='monthly model engine'!AD14 -> 6783.2324 | K23: ='monthly model engine'!AD15 -> 6783.2324 | L23: ='monthly model engine'!AD16 -> 6783.2324 | M23: ='monthly model engine'!AD17 -> 6783.2324 | N23: ='monthly model engine'!AD18 -> 6783.2324 | O23: ='monthly model engine'!AD19 -> 6783.2324 | P23: ='monthly model engine'!AD20 -> 6783.2324 | Q23: ='monthly model engine'!AD21 -> 6783.2324 | R23: ='monthly model engine'!AD22 -> 6783.2324 | S23: ='monthly model engine'!AD23 -> 6783.2324 | T23: ='monthly model engine'!AD24 -> 6783.2324 | U23: ='monthly model engine'!AD25 -> 6783.2324 | V23: ='monthly model engine'!AD26 -> 6783.2324 | W23: ='monthly model engine'!AD27 -> 6783.2324 | X23: ='monthly model engine'!AD28 -> 6783.2324 | Y23: ='monthly model engine'!AD29 -> 6783.2324 | Z23: ='monthly model engine'!AD30 -> 6783.2324 | AA23: ='monthly model engine'!AD31 -> 6783.2324 | AB23: ='monthly model engine'!AD32 -> 6783.2324 | AC23: ='monthly model engine'!AD33 -> 6783.2324 | AD23: ='monthly model engine'!AD34 -> 6783.2324 | AE23: ='monthly model engine'!AD35 -> 6783.2324 | AF23: ='monthly model engine'!AD36 -> 6783.2324 | AG23: ='monthly model engine'!AD37 -> 6783.2324 | AH23: ='monthly model engine'!AD38 -> 6783.2324 | AI23: ='monthly model engine'!AD39 -> 6783.2324 | AJ23: ='monthly model engine'!AD40 -> 6783.2324 | AK23: ='monthly model engine'!AD41 -> 6783.2324 | AL23: ='monthly model engine'!AD42 -> 6783.2324 | AM23: ='monthly model engine'!AD43 -> 6783.2324 | AN23: ='monthly model engine'!AD44 -> 6783.2324 | AO23: ='monthly model engine'!AD45 -> 6783.2324 | AP23: ='monthly model engine'!AD46 -> 6783.2324 | AQ23: ='monthly model engine'!AD47 -> 6783.2324 | AR23: ='monthly model engine'!AD48 -> 6783.2324 | AS23: ='monthly model engine'!AD49 -> 6783.2324 | AT23: ='monthly model engine'!AD50 -> 6783.2324 | AU23: ='monthly model engine'!AD51 -> 6783.2324 | AV23: ='monthly model engine'!AD52 -> 6783.2324 | AW23: ='monthly model engine'!AD53 -> 6783.2324 | AX23: ='monthly model engine'!AD54 -> 6783.2324 | AY23: ='monthly model engine'!AD55 -> 6783.2324 | AZ23: ='monthly model engine'!AD56 -> 6783.2324 | BA23: ='monthly model engine'!AD57 -> 6783.2324 | BB23: ='monthly model engine'!AD58 -> 6783.2324 | BC23: ='monthly model engine'!AD59 -> 6783.2324 | BD23: ='monthly model engine'!AD60 -> 6783.2324 | BE23: ='monthly model engine'!AD61 -> 6783.2324 | BF23: ='monthly model engine'!AD62 -> 6783.2324 | BG23: ='monthly model engine'!AD63 -> 6783.2324 | BH23: ='monthly model engine'!AD64 -> 6783.2324 | BI23: ='monthly model engine'!AD65 -> 6783.2324 | BJ23: ='monthly model engine'!AD66 -> 6783.2324 | BK23: ='monthly model engine'!AD67 -> 6783.2324
B24: Marketing - social ads | D24: ='monthly model engine'!AE8 -> 300 | E24: ='monthly model engine'!AE9 -> 200 | F24: ='monthly model engine'!AE10 -> 150 | G24: ='monthly model engine'!AE11 -> 150 | H24: ='monthly model engine'!AE12 -> 150 | I24: ='monthly model engine'!AE13 -> 250 | J24: ='monthly model engine'!AE14 -> 250 | K24: ='monthly model engine'!AE15 -> 150 | L24: ='monthly model engine'!AE16 -> 200 | M24: ='monthly model engine'!AE17 -> 150 | N24: ='monthly model engine'!AE18 -> 250 | O24: ='monthly model engine'!AE19 -> 300 | P24: ='monthly model engine'!AE20 -> 345 | Q24: ='monthly model engine'!AE21 -> 230 | R24: ='monthly model engine'!AE22 -> 172.5 | S24: ='monthly model engine'!AE23 -> 172.5 | T24: ='monthly model engine'!AE24 -> 172.5 | U24: ='monthly model engine'!AE25 -> 287.5 | V24: ='monthly model engine'!AE26 -> 287.5 | W24: ='monthly model engine'!AE27 -> 172.5 | X24: ='monthly model engine'!AE28 -> 230 | Y24: ='monthly model engine'!AE29 -> 172.5 | Z24: ='monthly model engine'!AE30 -> 287.5 | AA24: ='monthly model engine'!AE31 -> 345 | AB24: ='monthly model engine'!AE32 -> 372.6 | AC24: ='monthly model engine'!AE33 -> 248.4 | AD24: ='monthly model engine'!AE34 -> 186.3 | AE24: ='monthly model engine'!AE35 -> 186.3 | AF24: ='monthly model engine'!AE36 -> 186.3 | AG24: ='monthly model engine'!AE37 -> 310.5 | AH24: ='monthly model engine'!AE38 -> 310.5 | AI24: ='monthly model engine'!AE39 -> 186.3 | AJ24: ='monthly model engine'!AE40 -> 248.4 | AK24: ='monthly model engine'!AE41 -> 186.3 | AL24: ='monthly model engine'!AE42 -> 310.5 | AM24: ='monthly model engine'!AE43 -> 372.6 | AN24: ='monthly model engine'!AE44 -> 394.956 | AO24: ='monthly model engine'!AE45 -> 263.304 | AP24: ='monthly model engine'!AE46 -> 197.478 | AQ24: ='monthly model engine'!AE47 -> 197.478 | AR24: ='monthly model engine'!AE48 -> 197.478 | AS24: ='monthly model engine'!AE49 -> 329.13 | AT24: ='monthly model engine'!AE50 -> 329.13 | AU24: ='monthly model engine'!AE51 -> 197.478 | AV24: ='monthly model engine'!AE52 -> 263.304 | AW24: ='monthly model engine'!AE53 -> 197.478 | AX24: ='monthly model engine'!AE54 -> 329.13 | AY24: ='monthly model engine'!AE55 -> 394.956 | AZ24: ='monthly model engine'!AE56 -> 406.80468 | BA24: ='monthly model engine'!AE57 -> 271.20312 | BB24: ='monthly model engine'!AE58 -> 203.40234 | BC24: ='monthly model engine'!AE59 -> 203.40234 | BD24: ='monthly model engine'!AE60 -> 203.40234 | BE24: ='monthly model engine'!AE61 -> 339.0039 | BF24: ='monthly model engine'!AE62 -> 339.0039 | BG24: ='monthly model engine'!AE63 -> 203.40234 | BH24: ='monthly model engine'!AE64 -> 271.20312 | BI24: ='monthly model engine'!AE65 -> 203.40234 | BJ24: ='monthly model engine'!AE66 -> 339.0039 | BK24: ='monthly model engine'!AE67 -> 406.80468
B25: Marketing - local/community | D25: ='monthly model engine'!AF8 -> 150 | E25: ='monthly model engine'!AF9 -> 150 | F25: ='monthly model engine'!AF10 -> 150 | G25: ='monthly model engine'!AF11 -> 150 | H25: ='monthly model engine'!AF12 -> 200 | I25: ='monthly model engine'!AF13 -> 150 | J25: ='monthly model engine'!AF14 -> 150 | K25: ='monthly model engine'!AF15 -> 150 | L25: ='monthly model engine'!AF16 -> 200 | M25: ='monthly model engine'!AF17 -> 150 | N25: ='monthly model engine'!AF18 -> 200 | O25: ='monthly model engine'!AF19 -> 250 | P25: ='monthly model engine'!AF20 -> 172.5 | Q25: ='monthly model engine'!AF21 -> 172.5 | R25: ='monthly model engine'!AF22 -> 172.5 | S25: ='monthly model engine'!AF23 -> 172.5 | T25: ='monthly model engine'!AF24 -> 230 | U25: ='monthly model engine'!AF25 -> 172.5 | V25: ='monthly model engine'!AF26 -> 172.5 | W25: ='monthly model engine'!AF27 -> 172.5 | X25: ='monthly model engine'!AF28 -> 230 | Y25: ='monthly model engine'!AF29 -> 172.5 | Z25: ='monthly model engine'!AF30 -> 230 | AA25: ='monthly model engine'!AF31 -> 287.5 | AB25: ='monthly model engine'!AF32 -> 186.3 | AC25: ='monthly model engine'!AF33 -> 186.3 | AD25: ='monthly model engine'!AF34 -> 186.3 | AE25: ='monthly model engine'!AF35 -> 186.3 | AF25: ='monthly model engine'!AF36 -> 248.4 | AG25: ='monthly model engine'!AF37 -> 186.3 | AH25: ='monthly model engine'!AF38 -> 186.3 | AI25: ='monthly model engine'!AF39 -> 186.3 | AJ25: ='monthly model engine'!AF40 -> 248.4 | AK25: ='monthly model engine'!AF41 -> 186.3 | AL25: ='monthly model engine'!AF42 -> 248.4 | AM25: ='monthly model engine'!AF43 -> 310.5 | AN25: ='monthly model engine'!AF44 -> 197.478 | AO25: ='monthly model engine'!AF45 -> 197.478 | AP25: ='monthly model engine'!AF46 -> 197.478 | AQ25: ='monthly model engine'!AF47 -> 197.478 | AR25: ='monthly model engine'!AF48 -> 263.304 | AS25: ='monthly model engine'!AF49 -> 197.478 | AT25: ='monthly model engine'!AF50 -> 197.478 | AU25: ='monthly model engine'!AF51 -> 197.478 | AV25: ='monthly model engine'!AF52 -> 263.304 | AW25: ='monthly model engine'!AF53 -> 197.478 | AX25: ='monthly model engine'!AF54 -> 263.304 | AY25: ='monthly model engine'!AF55 -> 329.13 | AZ25: ='monthly model engine'!AF56 -> 203.40234 | BA25: ='monthly model engine'!AF57 -> 203.40234 | BB25: ='monthly model engine'!AF58 -> 203.40234 | BC25: ='monthly model engine'!AF59 -> 203.40234 | BD25: ='monthly model engine'!AF60 -> 271.20312 | BE25: ='monthly model engine'!AF61 -> 203.40234 | BF25: ='monthly model engine'!AF62 -> 203.40234 | BG25: ='monthly model engine'!AF63 -> 203.40234 | BH25: ='monthly model engine'!AF64 -> 271.20312 | BI25: ='monthly model engine'!AF65 -> 203.40234 | BJ25: ='monthly model engine'!AF66 -> 271.20312 | BK25: ='monthly model engine'!AF67 -> 339.0039
