Workbook

Sheet Product Master
A1: Product ID | B1: Product Name | C1: Category | D1: Supplier | E1: Standard Cost | F1: Retail Price
A2: P01 | B2: Women Basic Tee | C2: Womenswear | D2: Supplier A | E2: 12 | F2: 24
A3: P02 | B3: Women Denim Jacket | C3: Womenswear | D3: Supplier B | E3: 28 | F3: 50
A4: P03 | B4: Men Casual Shirt | C4: Menswear | D4: Supplier C | E4: 15 | F4: 28
A5: P04 | B5: Men Chinos | C5: Menswear | D5: Supplier C | E5: 18 | F5: 35
A6: P05 | B6: Kids Hoodie | C6: Kidswear | D6: Supplier D | E6: 9 | F6: 18
A7: P06 | B7: Kids Jacket | C7: Kidswear | D7: Supplier D | E7: 14 | F7: 30
A8: P07 | B8: Running Shoes | C8: Footwear | D8: Supplier E | E8: 20 | F8: 40
A9: P08 | B9: Fashion Belt | C9: Accessories | D9: Supplier F | E9: 4 | F9: 10
A10: P09 | B10: Handbag | C10: Accessories | D10: Supplier F | E10: 10 | F10: 22

Sheet Store Information
A1: Store ID | B1: Store Location | C1: Region | D1: Store Size (Sq Ft) | E1: Opening Date
A2: S01 | B2: Manchester | C2: North | D2: 12000 | E2: 2015-06-01
A3: S02 | B3: Birmingham | C3: Midlands | D3: 10500 | E3: 2016-09-01
A4: S03 | B4: London Stratford | C4: South | D4: 18000 | E4: 2018-03-01
A5: S04 | B5: Glasgow | C5: Scotland | D5: 9800 | E5: 2019-07-01
A6: S05 | B6: Leeds | C6: North | D6: 11200 | E6: 2020-10-01

Sheet Product mix Analysis
B1: Product Mix Analysis
A3: Row Labels | B3: Sum of Units Sold | C3: Sum of GrossProfit | D3: Average of GP Margin | E3: Sum of Net Sales Revenue | F3: % of Sales
A4: Accessories | B4: 500634 | C4: 3480250.6 | D4: 0.49942981 | E4: 7149684.2 | F4: =E4/$E$9 -> 0.1242731
A5: Footwear | B5: 250591 | C5: 3689266 | D5: 0.41374889 | E5: 8907836.4 | F5: =E5/$E$9 -> 0.15483264
A6: Kidswear | B6: 504175 | C6: 4713610.6 | D6: 0.43378897 | E6: 10760541 | F6: =E6/$E$9 -> 0.18703564
A7: Menswear | B7: 515422 | C7: 5570617.2 | D7: 0.38498461 | E7: 14436800 | F7: =E7/$E$9 -> 0.25093498
A8: Womenswear | B8: 496098 | C8: 5963093.1 | D8: 0.37836764 | E8: 16277172 | F8: =E8/$E$9 -> 0.28292363
A9: Grand Total | B9: 2266920 | C9: 23416838 | D9: 0.42298788 | E9: 57532032

Sheet Sales Transaction(clean)
A1: Transaction ID | B1: Date | C1: Store ID | D1: Product ID | E1: Category | F1: Units Sold | G1: Selling Price | H1: Discount % | I1: Net Sales Revenue | J1: Cost of Sales | K1: Total Revenue | L1: month Key | M1: Store Location | N1: Region | O1: Supplier | P1: Discount Amount | Q1: Revemue per unit | R1: standard product cost per unit | S1: Standard cost | T1: Variance Actual-Std COS | U1: GrossProfit | V1: GP Margin
A2: TX00001 | B2: 2023-01-28 | C2: S01 | D2: P01 | E2: Womenswear | F2: 2680 | G2: 24 | H2: 0.1 | I2: 57888 | J2: 32160 | K2: =Table5[[#This Row],[Selling Price]]*Table5[[#This Row],[Units Sold]] -> 64320 | L2: =TEXT(B2,"yyyy-mm") -> 2023-01 | M2: =VLOOKUP(Table5[[#This Row],[Store ID]],Table4[[Store ID]:[Store Location]],2) -> Manchester | N2: =VLOOKUP(Table5[[#This Row],[Store ID]],Table4[[Store ID]:[Region]],3) -> North | O2: =VLOOKUP(Table5[[#This Row],[Product ID]],'Product Master'!$A$2:$D$10,4) -> Supplier A | P2: =Table5[[#This Row],[Total Revenue]]-Table5[[#This Row],[Net Sales Revenue]] -> 6432 | Q2: =Table5[[#This Row],[Net Sales Revenue]]/Table5[[#This Row],[Units Sold]] -> 21.6 | R2: =VLOOKUP(Table5[[#This Row],[Product ID]],'Product Master'!$A$1:$E$10,5,FALSE) -> 12 | S2: =Table5[[#This Row],[standard product cost per unit]]*Table5[[#This Row],[Units Sold]] -> 32160 | T2: =Table5[[#This Row],[Cost of Sales]]-Table5[[#This Row],[Standard cost]] -> 0 | U2: =Table5[[#This Row],[Net Sales Revenue]]-Table5[[#This Row],[Cost of Sales]] -> 25728 | V2: =Table5[[#This Row],[GrossProfit]]/Table5[[#This Row],[Net Sales Revenue]] -> 0.44444444
A3: TX00002 | B3: 2023-01-28 | C3: S01 | D3: P02 | E3: Womenswear | F3: 2556 | G3: 50 | H3: 0.08 | I3: 117576 | J3: 71568 | K3: =Table5[[#This Row],[Selling Price]]*Table5[[#This Row],[Units Sold]] -> 127800 | L3: =TEXT(B3,"yyyy-mm") -> 2023-01 | M3: =VLOOKUP(Table5[[#This Row],[Store ID]],Table4[[Store ID]:[Store Location]],2) -> Manchester | N3: =VLOOKUP(Table5[[#This Row],[Store ID]],Table4[[Store ID]:[Region]],3) -> North | O3: =VLOOKUP(Table5[[#This Row],[Product ID]],'Product Master'!$A$2:$D$10,4) -> Supplier B | P3: =Table5[[#This Row],[Total Revenue]]-Table5[[#This Row],[Net Sales Revenue]] -> 10224 | Q3: =Table5[[#This Row],[Net Sales Revenue]]/Table5[[#This Row],[Units Sold]] -> 46 | R3: =VLOOKUP(Table5[[#This Row],[Product ID]],'Product Master'!$A$1:$E$10,5,FALSE) -> 28 | S3: =Table5[[#This Row],[standard product cost per unit]]*Table5[[#This Row],[Units Sold]] -> 71568 | T3: =Table5[[#This Row],[Cost of Sales]]-Table5[[#This Row],[Standard cost]] -> 0 | U3: =Table5[[#This Row],[Net Sales Revenue]]-Table5[[#This Row],[Cost of Sales]] -> 46008 | V3: =Table5[[#This Row],[GrossProfit]]/Table5[[#This Row],[Net Sales Revenue]] -> 0.39130435
A4: TX00003 | B4: 2023-01-28 | C4: S01 | D4: P03 | E4: Menswear | F4: 1448 | G4: 28 | H4: 0.09 | I4: 36895.04 | J4: 21720 | K4: =Table5[[#This Row],[Selling Price]]*Table5[[#This Row],[Units Sold]] -> 40544 | L4: =TEXT(B4,"yyyy-mm") -> 2023-01 | M4: =VLOOKUP(Table5[[#This Row],[Store ID]],Table4[[Store ID]:[Store Location]],2) -> Manchester | N4: =VLOOKUP(Table5[[#This Row],[Store ID]],Table4[[Store ID]:[Region]],3) -> North | O4: =VLOOKUP(Table5[[#This Row],[Product ID]],'Product Master'!$A$2:$D$10,4) -> Supplier C | P4: =Table5[[#This Row],[Total Revenue]]-Table5[[#This Row],[Net Sales Revenue]] -> 3648.96 | Q4: =Table5[[#This Row],[Net Sales Revenue]]/Table5[[#This Row],[Units Sold]] -> 25.48 | R4: =VLOOKUP(Table5[[#This Row],[Product ID]],'Product Master'!$A$1:$E$10,5,FALSE) -> 15 | S4: =Table5[[#This Row],[standard product cost per unit]]*Table5[[#This Row],[Units Sold]] -> 21720 | T4: =Table5[[#This Row],[Cost of Sales]]-Table5[[#This Row],[Standard cost]] -> 0 | U4: =Table5[[#This Row],[Net Sales Revenue]]-Table5[[#This Row],[Cost of Sales]] -> 15175.04 | V4: =Table5[[#This Row],[GrossProfit]]/Table5[[#This Row],[Net Sales Revenue]] -> 0.41130298
A5: TX00004 | B5: 2023-01-28 | C5: S01 | D5: P04 | E5: Menswear | F5: 2328 | G5: 35 | H5: 0.07 | I5: 75776.4 | J5: 41904 | K5: =Table5[[#This Row],[Selling Price]]*Table5[[#This Row],[Units Sold]] -> 81480 | L5: =TEXT(B5,"yyyy-mm") -> 2023-01 | M5: =VLOOKUP(Table5[[#This Row],[Store ID]],Table4[[Store ID]:[Store Location]],2) -> Manchester | N5: =VLOOKUP(Table5[[#This Row],[Store ID]],Table4[[Store ID]:[Region]],3) -> North | O5: =VLOOKUP(Table5[[#This Row],[Product ID]],'Product Master'!$A$2:$D$10,4) -> Supplier C | P5: =Table5[[#This Row],[Total Revenue]]-Table5[[#This Row],[Net Sales Revenue]] -> 5703.6 | Q5: =Table5[[#This Row],[Net Sales Revenue]]/Table5[[#This Row],[Units Sold]] -> 32.55 | R5: =VLOOKUP(Table5[[#This Row],[Product ID]],'Product Master'!$A$1:$E$10,5,FALSE) -> 18 | S5: =Table5[[#This Row],[standard product cost per unit]]*Table5[[#This Row],[Units Sold]] -> 41904 | T5: =Table5[[#This Row],[Cost of Sales]]-Table5[[#This Row],[Standard cost]] -> 0 | U5: =Table5[[#This Row],[Net Sales Revenue]]-Table5[[#This Row],[Cost of Sales]] -> 33872.4 | V5: =Table5[[#This Row],[GrossProfit]]/Table5[[#This Row],[Net Sales Revenue]] -> 0.44700461
A6: TX00005 | B6: 2023-01-28 | C6: S01 | D6: P05 | E6: Kidswear | F6: 1784 | G6: 18 | H6: 0.09 | I6: 29221.92 | J6: 16056 | K6: =Table5[[#This Row],[Selling Price]]*Table5[[#This Row],[Units Sold]] -> 32112 | L6: =TEXT(B6,"yyyy-mm") -> 2023-01 | M6: =VLOOKUP(Table5[[#This Row],[Store ID]],Table4[[Store ID]:[Store Location]],2) -> Manchester | N6: =VLOOKUP(Table5[[#This Row],[Store ID]],Table4[[Store ID]:[Region]],3) -> North | O6: =VLOOKUP(Table5[[#This Row],[Product ID]],'Product Master'!$A$2:$D$10,4) -> Supplier D | P6: =Table5[[#This Row],[Total Revenue]]-Table5[[#This Row],[Net Sales Revenue]] -> 2890.08 | Q6: =Table5[[#This Row],[Net Sales Revenue]]/Table5[[#This Row],[Units Sold]] -> 16.38 | R6: =VLOOKUP(Table5[[#This Row],[Product ID]],'Product Master'!$A$1:$E$10,5,FALSE) -> 9 | S6: =Table5[[#This Row],[standard product cost per unit]]*Table5[[#This Row],[Units Sold]] -> 16056 | T6: =Table5[[#This Row],[Cost of Sales]]-Table5[[#This Row],[Standard cost]] -> 0 | U6: =Table5[[#This Row],[Net Sales Revenue]]-Table5[[#This Row],[Cost of Sales]] -> 13165.92 | V6: =Table5[[#This Row],[GrossProfit]]/Table5[[#This Row],[Net Sales Revenue]] -> 0.45054945
A7: TX00006 | B7: 2023-01-28 | C7: S01 | D7: P06 | E7: Kidswear | F7: 2352 | G7: 30 | H7: 0.06 | I7: 66326.4 | J7: 32928 | K7: =Table5[[#This Row],[Selling Price]]*Table5[[#This Row],[Units Sold]] -> 70560 | L7: =TEXT(B7,"yyyy-mm") -> 2023-01 | M7: =VLOOKUP(Table5[[#This Row],[Store ID]],Table4[[Store ID]:[Store Location]],2) -> Manchester | N7: =VLOOKUP(Table5[[#This Row],[Store ID]],Table4[[Store ID]:[Region]],3) -> North | O7: =VLOOKUP(Table5[[#This Row],[Product ID]],'Product Master'!$A$2:$D$10,4) -> Supplier D | P7: =Table5[[#This Row],[Total Revenue]]-Table5[[#This Row],[Net Sales Revenue]] -> 4233.6 | Q7: =Table5[[#This Row],[Net Sales Revenue]]/Table5[[#This Row],[Units Sold]] -> 28.2 | R7: =VLOOKUP(Table5[[#This Row],[Product ID]],'Product Master'!$A$1:$E$10,5,FALSE) -> 14 | S7: =Table5[[#This Row],[standard product cost per unit]]*Table5[[#This Row],[Units Sold]] -> 32928 | T7: =Table5[[#This Row],[Cost of Sales]]-Table5[[#This Row],[Standard cost]] -> 0 | U7: =Table5[[#This Row],[Net Sales Revenue]]-Table5[[#This Row],[Cost of Sales]] -> 33398.4 | V7: =Table5[[#This Row],[GrossProfit]]/Table5[[#This Row],[Net Sales Revenue]] -> 0.5035461
A8: TX00007 | B8: 2023-01-28 | C8: S01 | D8: P07 | E8: Footwear | F8: 1900 | G8: 40 | H8: 0.07 | I8: 70680 | J8: 38000 | K8: =Table5[[#This Row],[Selling Price]]*Table5[[#This Row],[Units Sold]] -> 76000 | L8: =TEXT(B8,"yyyy-mm") -> 2023-01 | M8: =VLOOKUP(Table5[[#This Row],[Store ID]],Table4[[Store ID]:[Store Location]],2) -> Manchester | N8: =VLOOKUP(Table5[[#This Row],[Store ID]],Table4[[Store ID]:[Region]],3) -> North | O8: =VLOOKUP(Table5[[#This Row],[Product ID]],'Product Master'!$A$2:$D$10,4) -> Supplier E | P8: =Table5[[#This Row],[Total Revenue]]-Table5[[#This Row],[Net Sales Revenue]] -> 5320 | Q8: =Table5[[#This Row],[Net Sales Revenue]]/Table5[[#This Row],[Units Sold]] -> 37.2 | R8: =VLOOKUP(Table5[[#This Row],[Product ID]],'Product Master'!$A$1:$E$10,5,FALSE) -> 20 | S8: =Table5[[#This Row],[standard product cost per unit]]*Table5[[#This Row],[Units Sold]] -> 38000 | T8: =Table5[[#This Row],[Cost of Sales]]-Table5[[#This Row],[Standard cost]] -> 0 | U8: =Table5[[#This Row],[Net Sales Revenue]]-Table5[[#This Row],[Cost of Sales]] -> 32680 | V8: =Table5[[#This Row],[GrossProfit]]/Table5[[#This Row],[Net Sales Revenue]] -> 0.46236559
A9: TX00008 | B9: 2023-01-28 | C9: S01 | D9: P08 | E9: Accessories | F9: 1888 | G9: 10 | H9: 0.07 | I9: 17558.4 | J9: 7552 | K9: =Table5[[#This Row],[Selling Price]]*Table5[[#This Row],[Units Sold]] -> 18880 | L9: =TEXT(B9,"yyyy-mm") -> 2023-01 | M9: =VLOOKUP(Table5[[#This Row],[Store ID]],Table4[[Store ID]:[Store Location]],2) -> Manchester | N9: =VLOOKUP(Table5[[#This Row],[Store ID]],Table4[[Store ID]:[Region]],3) -> North | O9: =VLOOKUP(Table5[[#This Row],[Product ID]],'Product Master'!$A$2:$D$10,4) -> Supplier F | P9: =Table5[[#This Row],[Total Revenue]]-Table5[[#This Row],[Net Sales Revenue]] -> 1321.6 | Q9: =Table5[[#This Row],[Net Sales Revenue]]/Table5[[#This Row],[Units Sold]] -> 9.3 | R9: =VLOOKUP(Table5[[#This Row],[Product ID]],'Product Master'!$A$1:$E$10,5,FALSE) -> 4 | S9: =Table5[[#This Row],[standard product cost per unit]]*Table5[[#This Row],[Units Sold]] -> 7552 | T9: =Table5[[#This Row],[Cost of Sales]]-Table5[[#This Row],[Standard cost]] -> 0 | U9: =Table5[[#This Row],[Net Sales Revenue]]-Table5[[#This Row],[Cost of Sales]] -> 10006.4 | V9: =Table5[[#This Row],[GrossProfit]]/Table5[[#This Row],[Net Sales Revenue]] -> 0.56989247
A10: TX00009 | B10: 2023-01-28 | C10: S01 | D10: P09 | E10: Accessories | F10: 1264 | G10: 22 | H10: 0.09 | I10: 25305.28 | J10: 12640 | K10: =Table5[[#This Row],[Selling Price]]*Table5[[#This Row],[Units Sold]] -> 27808 | L10: =TEXT(B10,"yyyy-mm") -> 2023-01 | M10: =VLOOKUP(Table5[[#This Row],[Store ID]],Table4[[Store ID]:[Store Location]],2) -> Manchester | N10: =VLOOKUP(Table5[[#This Row],[Store ID]],Table4[[Store ID]:[Region]],3) -> North | O10: =VLOOKUP(Table5[[#This Row],[Product ID]],'Product Master'!$A$2:$D$10,4) -> Supplier F | P10: =Table5[[#This Row],[Total Revenue]]-Table5[[#This Row],[Net Sales Revenue]] -> 2502.72 | Q10: =Table5[[#This Row],[Net Sales Revenue]]/Table5[[#This Row],[Units Sold]] -> 20.02 | R10: =VLOOKUP(Table5[[#This Row],[Product ID]],'Product Master'!$A$1:$E$10,5,FALSE) -> 10 | S10: =Table5[[#This Row],[standard product cost per unit]]*Table5[[#This Row],[Units Sold]] -> 12640 | T10: =Table5[[#This Row],[Cost of Sales]]-Table5[[#This Row],[Standard cost]] -> 0 | U10: =Table5[[#This Row],[Net Sales Revenue]]-Table5[[#This Row],[Cost of Sales]] -> 12665.28 | V10: =Table5[[#This Row],[GrossProfit]]/Table5[[#This Row],[Net Sales Revenue]] -> 0.5004995
A11: TX00010 | B11: 2023-01-28 | C11: S02 | D11: P01 | E11: Womenswear | F11: 1984 | G11: 24 | H11: 0.09 | I11: 43330.56 | J11: 23808 | K11: =Table5[[#This Row],[Selling Price]]*Table5[[#This Row],[Units Sold]] -> 47616 | L11: =TEXT(B11,"yyyy-mm") -> 2023-01 | M11: =VLOOKUP(Table5[[#This Row],[Store ID]],Table4[[Store ID]:[Store Location]],2) -> Birmingham | N11: =VLOOKUP(Table5[[#This Row],[Store ID]],Table4[[Store ID]:[Region]],3) -> Midlands | O11: =VLOOKUP(Table5[[#This Row],[Product ID]],'Product Master'!$A$2:$D$10,4) -> Supplier A | P11: =Table5[[#This Row],[Total Revenue]]-Table5[[#This Row],[Net Sales Revenue]] -> 4285.44 | Q11: =Table5[[#This Row],[Net Sales Revenue]]/Table5[[#This Row],[Units Sold]] -> 21.84 | R11: =VLOOKUP(Table5[[#This Row],[Product ID]],'Product Master'!$A$1:$E$10,5,FALSE) -> 12 | S11: =Table5[[#This Row],[standard product cost per unit]]*Table5[[#This Row],[Units Sold]] -> 23808 | T11: =Table5[[#This Row],[Cost of Sales]]-Table5[[#This Row],[Standard cost]] -> 0 | U11: =Table5[[#This Row],[Net Sales Revenue]]-Table5[[#This Row],[Cost of Sales]] -> 19522.56 | V11: =Table5[[#This Row],[GrossProfit]]/Table5[[#This Row],[Net Sales Revenue]] -> 0.45054945
A12: TX00011 | B12: 2023-01-28 | C12: S02 | D12: P02 | E12: Womenswear | F12: 1692 | G12: 50 | H12: 0.07 | I12: 78678 | J12: 47376 | K12: =Table5[[#This Row],[Selling Price]]*Table5[[#This Row],[Units Sold]] -> 84600 | L12: =TEXT(B12,"yyyy-mm") -> 2023-01 | M12: =VLOOKUP(Table5[[#This Row],[Store ID]],Table4[[Store ID]:[Store Location]],2) -> Birmingham | N12: =VLOOKUP(Table5[[#This Row],[Store ID]],Table4[[Store ID]:[Region]],3) -> Midlands | O12: =VLOOKUP(Table5[[#This Row],[Product ID]],'Product Master'!$A$2:$D$10,4) -> Supplier B | P12: =Table5[[#This Row],[Total Revenue]]-Table5[[#This Row],[Net Sales Revenue]] -> 5922 | Q12: =Table5[[#This Row],[Net Sales Revenue]]/Table5[[#This Row],[Units Sold]] -> 46.5 | R12: =VLOOKUP(Table5[[#This Row],[Product ID]],'Product Master'!$A$1:$E$10,5,FALSE) -> 28 | S12: =Table5[[#This Row],[standard product cost per unit]]*Table5[[#This Row],[Units Sold]] -> 47376 | T12: =Table5[[#This Row],[Cost of Sales]]-Table5[[#This Row],[Standard cost]] -> 0 | U12: =Table5[[#This Row],[Net Sales Revenue]]-Table5[[#This Row],[Cost of Sales]] -> 31302 | V12: =Table5[[#This Row],[GrossProfit]]/Table5[[#This Row],[Net Sales Revenue]] -> 0.39784946
A13: TX00012 | B13: 2023-01-28 | C13: S02 | D13: P03 | E13: Menswear | F13: 2096 | G13: 28 | H13: 0.08 | I13: 53992.96 | J13: 31440 | K13: =Table5[[#This Row],[Selling Price]]*Table5[[#This Row],[Units Sold]] -> 58688 | L13: =TEXT(B13,"yyyy-mm") -> 2023-01 | M13: =VLOOKUP(Table5[[#This Row],[Store ID]],Table4[[Store ID]:[Store Location]],2) -> Birmingham | N13: =VLOOKUP(Table5[[#This Row],[Store ID]],Table4[[Store ID]:[Region]],3) -> Midlands | O13: =VLOOKUP(Table5[[#This Row],[Product ID]],'Product Master'!$A$2:$D$10,4) -> Supplier C | P13: =Table5[[#This Row],[Total Revenue]]-Table5[[#This Row],[Net Sales Revenue]] -> 4695.04 | Q13: =Table5[[#This Row],[Net Sales Revenue]]/Table5[[#This Row],[Units Sold]] -> 25.76 | R13: =VLOOKUP(Table5[[#This Row],[Product ID]],'Product Master'!$A$1:$E$10,5,FALSE) -> 15 | S13: =Table5[[#This Row],[standard product cost per unit]]*Table5[[#This Row],[Units Sold]] -> 31440 | T13: =Table5[[#This Row],[Cost of Sales]]-Table5[[#This Row],[Standard cost]] -> 0 | U13: =Table5[[#This Row],[Net Sales Revenue]]-Table5[[#This Row],[Cost of Sales]] -> 22552.96 | V13: =Table5[[#This Row],[GrossProfit]]/Table5[[#This Row],[Net Sales Revenue]] -> 0.41770186
... A1081: TX01080 | B1081: 2024-12-28 | C1081: S05 | D1081: P09 | E1081: Accessories | F1081: 2068 | G1081: 22 | H1081: 0.14 | I1081: 39126.56 | J1081: 22334.4 | K1081: =Table5[[#This Row],[Selling Price]]*Table5[[#This Row],[Units Sold]] -> 45496 | L1081: =TEXT(B1081,"yyyy-mm") -> 2024-12 | M1081: =VLOOKUP(Table5[[#This Row],[Store ID]],Table4[[Store ID]:[Store Location]],2) -> Leeds | N1081: =VLOOKUP(Table5[[#This Row],[Store ID]],Table4[[Store ID]:[Region]],3) -> North | O1081: =VLOOKUP(Table5[[#This Row],[Product ID]],'Product Master'!$A$2:$D$10,4) -> Supplier F | P1081: =Table5[[#This Row],[Total Revenue]]-Table5[[#This Row],[Net Sales Revenue]] -> 6369.44 | Q1081: =Table5[[#This Row],[Net Sales Revenue]]/Table5[[#This Row],[Units Sold]] -> 18.92 | R1081: =VLOOKUP(Table5[[#This Row],[Product ID]],'Product Master'!$A$1:$E$10,5,FALSE) -> 10 | S1081: =Table5[[#This Row],[standard product cost per unit]]*Table5[[#This Row],[Units Sold]] -> 20680 | T1081: =Table5[[#This Row],[Cost of Sales]]-Table5[[#This Row],[Standard cost]] -> 1654.4 | U1081: =Table5[[#This Row],[Net Sales Revenue]]-Table5[[#This Row],[Cost of Sales]] -> 16792.16 | V1081: =Table5[[#This Row],[GrossProfit]]/Table5[[#This Row],[Net Sales Revenue]] -> 0.42917548

Sheet Store Analysis
A1: Store ID | B1: Store Location | C1: Region | D1: Total Net Revenue | E1: Total Gross Revenue (pre-discount) | F1: Total Units Sold | G1: Total Cost of Sales | H1: Gross Profit | I1: Gross Margin % | J1: Avg Selling Price (Net, realised) | K1: Discount % | L1: Revenue Share % | M1: Total Operating Expense | N1: Operating Profit | O1: Operating Margin %
A2: S01 | B2: =VLOOKUP(A2,'[1]Store Information'!$A:$B,2,FALSE()) -> Manchester | C2: =VLOOKUP(A2,'[1]Store Information'!$A:$C,3,FALSE()) -> North | D2: =SUMIFS('[1]Sales Transactions (Clean)'!$I$2:$I$1081,'[1]Sales Transactions (Clean)'!$C$2:$C$1081,A2) -> 11765610 | E2: =SUMIFS('[1]Sales Transactions (Clean)'!$K$2:$K$1081,'[1]Sales Transactions (Clean)'!$C$2:$C$1081,A2) -> 13254918 | F2: =SUMIFS('[1]Sales Transactions (Clean)'!$F$2:$F$1081,'[1]Sales Transactions (Clean)'!$C$2:$C$1081,A2) -> 460600 | G2: =SUMIFS('[1]Sales Transactions (Clean)'!$J$2:$J$1081,'[1]Sales Transactions (Clean)'!$C$2:$C$1081,A2) -> 6987658.6 | H2: =D2-G2 -> 4777951.8 | I2: =H2/D2 -> 0.40609468 | J2: =D2/F2 -> 25.544095 | K2: =(E2-D2)/E2 -> 0.11235887 | L2: =D2/SUM($D$2:$D$6) -> 0.20450538 | M2: =SUMIFS('[1]Operating Expenses (Clean)'!$H$2:$H$121,'[1]Operating Expenses (Clean)'!$B$2:$B$121,A2) -> 2586673 | N2: =H2-M2 -> 2191278.8 | O2: =N2/D2 -> 0.18624438
A3: S02 | B3: =VLOOKUP(A3,'[1]Store Information'!$A:$B,2,FALSE()) -> Birmingham | C3: =VLOOKUP(A3,'[1]Store Information'!$A:$C,3,FALSE()) -> Midlands | D3: =SUMIFS('[1]Sales Transactions (Clean)'!$I$2:$I$1081,'[1]Sales Transactions (Clean)'!$C$2:$C$1081,A3) -> 11294839 | E3: =SUMIFS('[1]Sales Transactions (Clean)'!$K$2:$K$1081,'[1]Sales Transactions (Clean)'!$C$2:$C$1081,A3) -> 12680629 | F3: =SUMIFS('[1]Sales Transactions (Clean)'!$F$2:$F$1081,'[1]Sales Transactions (Clean)'!$C$2:$C$1081,A3) -> 446265 | G3: =SUMIFS('[1]Sales Transactions (Clean)'!$J$2:$J$1081,'[1]Sales Transactions (Clean)'!$C$2:$C$1081,A3) -> 6672071.2 | H3: =D3-G3 -> 4622767.9 | I3: =H3/D3 -> 0.40928143 | J3: =D3/F3 -> 25.309713 | K3: =(E3-D3)/E3 -> 0.109284 | L3: =D3/SUM($D$2:$D$6) -> 0.19632262 | M3: =SUMIFS('[1]Operating Expenses (Clean)'!$H$2:$H$121,'[1]Operating Expenses (Clean)'!$B$2:$B$121,A3) -> 2639417 | N3: =H3-M3 -> 1983350.9 | O3: =N3/D3 -> 0.17559798
A4: S03 | B4: =VLOOKUP(A4,'[1]Store Information'!$A:$B,2,FALSE()) -> London Stratford | C4: =VLOOKUP(A4,'[1]Store Information'!$A:$C,3,FALSE()) -> South | D4: =SUMIFS('[1]Sales Transactions (Clean)'!$I$2:$I$1081,'[1]Sales Transactions (Clean)'!$C$2:$C$1081,A4) -> 11556378 | E4: =SUMIFS('[1]Sales Transactions (Clean)'!$K$2:$K$1081,'[1]Sales Transactions (Clean)'!$C$2:$C$1081,A4) -> 13009965 | F4: =SUMIFS('[1]Sales Transactions (Clean)'!$F$2:$F$1081,'[1]Sales Transactions (Clean)'!$C$2:$C$1081,A4) -> 457104 | G4: =SUMIFS('[1]Sales Transactions (Clean)'!$J$2:$J$1081,'[1]Sales Transactions (Clean)'!$C$2:$C$1081,A4) -> 6853607.8 | H4: =D4-G4 -> 4702769.7 | I4: =H4/D4 -> 0.40694151 | J4: =D4/F4 -> 25.281725 | K4: =(E4-D4)/E4 -> 0.11172878 | L4: =D4/SUM($D$2:$D$6) -> 0.20086858 | M4: =SUMIFS('[1]Operating Expenses (Clean)'!$H$2:$H$121,'[1]Operating Expenses (Clean)'!$B$2:$B$121,A4) -> 2597710 | N4: =H4-M4 -> 2105059.7 | O4: =N4/D4 -> 0.18215567
A5: S04 | B5: =VLOOKUP(A5,'[1]Store Information'!$A:$B,2,FALSE()) -> Glasgow | C5: =VLOOKUP(A5,'[1]Store Information'!$A:$C,3,FALSE()) -> Scotland | D5: =SUMIFS('[1]Sales Transactions (Clean)'!$I$2:$I$1081,'[1]Sales Transactions (Clean)'!$C$2:$C$1081,A5) -> 11541197 | E5: =SUMIFS('[1]Sales Transactions (Clean)'!$K$2:$K$1081,'[1]Sales Transactions (Clean)'!$C$2:$C$1081,A5) -> 13012810 | F5: =SUMIFS('[1]Sales Transactions (Clean)'!$F$2:$F$1081,'[1]Sales Transactions (Clean)'!$C$2:$C$1081,A5) -> 455716 | G5: =SUMIFS('[1]Sales Transactions (Clean)'!$J$2:$J$1081,'[1]Sales Transactions (Clean)'!$C$2:$C$1081,A5) -> 6870570.5 | H5: =D5-G5 -> 4670626.3 | I5: =H5/D5 -> 0.40469168 | J5: =D5/F5 -> 25.325415 | K5: =(E5-D5)/E5 -> 0.11308958 | L5: =D5/SUM($D$2:$D$6) -> 0.20060471 | M5: =SUMIFS('[1]Operating Expenses (Clean)'!$H$2:$H$121,'[1]Operating Expenses (Clean)'!$B$2:$B$121,A5) -> 2620519 | N5: =H5-M5 -> 2050107.3 | O5: =N5/D5 -> 0.17763385
A6: S05 | B6: =VLOOKUP(A6,'[1]Store Information'!$A:$B,2,FALSE()) -> Leeds | C6: =VLOOKUP(A6,'[1]Store Information'!$A:$C,3,FALSE()) -> North | D6: =SUMIFS('[1]Sales Transactions (Clean)'!$I$2:$I$1081,'[1]Sales Transactions (Clean)'!$C$2:$C$1081,A6) -> 11374009 | E6: =SUMIFS('[1]Sales Transactions (Clean)'!$K$2:$K$1081,'[1]Sales Transactions (Clean)'!$C$2:$C$1081,A6) -> 12786237 | F6: =SUMIFS('[1]Sales Transactions (Clean)'!$F$2:$F$1081,'[1]Sales Transactions (Clean)'!$C$2:$C$1081,A6) -> 447235 | G6: =SUMIFS('[1]Sales Transactions (Clean)'!$J$2:$J$1081,'[1]Sales Transactions (Clean)'!$C$2:$C$1081,A6) -> 6731286.9 | H6: =D6-G6 -> 4642721.9 | I6: =H6/D6 -> 0.40818694 | J6: =D6/F6 -> 25.43184 | K6: =(E6-D6)/E6 -> 0.11044909 | L6: =D6/SUM($D$2:$D$6) -> 0.19769871 | M6: =SUMIFS('[1]Operating Expenses (Clean)'!$H$2:$H$121,'[1]Operating Expenses (Clean)'!$B$2:$B$121,A6) -> 2592811 | N6: =H6-M6 -> 2049910.9 | O6: =N6/D6 -> 0.18022765
A7: TOTAL / COMPANY | D7: =SUM(D2:D6) -> 57532032 | E7: =SUM(E2:E6) -> 64744559 | F7: =SUM(F2:F6) -> 2266920 | G7: =SUM(G2:G6) -> 34115195 | H7: =SUM(H2:H6) -> 23416838 | I7: =H7/D7 -> 0.4070226 | J7: =D7/F7 -> 25.378943 | K7: =(E7-D7)/E7 -> 0.11139973 | L7: =SUM(L2:L6) -> 1 | M7: =SUM(M2:M6) -> 13037130 | N7: =SUM(N2:N6) -> 10379708 | O7: =N7/D7 -> 0.18041615

Sheet OPEX Analysis
A3: Row Labels | B3: Sum of Total OPEX | C3: sum of Net of sales | D3: Sum of Gross Profit | E3: operating profit | F3: operating margin | G3: OP margin change
A4: 2023-01-28 | B4: 507501 | C4: =SUMIFS(Table5[Net Sales Revenue],Table5[Date],'OPEX Analysis'!A4) -> 2329918.2 | D4: =SUMIFS(Table5[GrossProfit],Table5[Date],'OPEX Analysis'!A4) -> 1057770.2 | E4: =D4-B4 -> 550269.24 | F4: =E4/C4 -> 0.23617534
A5: 2023-02-28 | B5: 507028 | C5: =SUMIFS(Table5[Net Sales Revenue],Table5[Date],'OPEX Analysis'!A5) -> 2487689.4 | D5: =SUMIFS(Table5[GrossProfit],Table5[Date],'OPEX Analysis'!A5) -> 1124933.4 | E5: =D5-B5 -> 617905.44 | F5: =E5/C5 -> 0.24838528 | G5: =(E5-E4)/E4 -> 0.12291474
A6: 2023-03-28 | B6: 502461 | C6: =SUMIFS(Table5[Net Sales Revenue],Table5[Date],'OPEX Analysis'!A6) -> 2444790.6 | D6: =SUMIFS(Table5[GrossProfit],Table5[Date],'OPEX Analysis'!A6) -> 1111450.6 | E6: =D6-B6 -> 608989.6 | F6: =E6/C6 -> 0.24909683 | G6: =(E6-E5)/E5 -> -0.014429133
A7: 2023-04-28 | B7: 519345 | C7: =SUMIFS(Table5[Net Sales Revenue],Table5[Date],'OPEX Analysis'!A7) -> 2436376.6 | D7: =SUMIFS(Table5[GrossProfit],Table5[Date],'OPEX Analysis'!A7) -> 1102248.6 | E7: =D7-B7 -> 582903.56 | F7: =E7/C7 -> 0.23925019 | G7: =(E7-E6)/E6 -> -0.042834952
A8: 2023-05-28 | B8: 505564 | C8: =SUMIFS(Table5[Net Sales Revenue],Table5[Date],'OPEX Analysis'!A8) -> 2336372.3 | D8: =SUMIFS(Table5[GrossProfit],Table5[Date],'OPEX Analysis'!A8) -> 1058776.3 | E8: =D8-B8 -> 553212.28 | F8: =E8/C8 -> 0.23678259 | G8: =(E8-E7)/E7 -> -0.050936865
A9: 2023-06-28 | B9: 519386 | C9: =SUMIFS(Table5[Net Sales Revenue],Table5[Date],'OPEX Analysis'!A9) -> 2423490.8 | D9: =SUMIFS(Table5[GrossProfit],Table5[Date],'OPEX Analysis'!A9) -> 1092142.8 | E9: =D9-B9 -> 572756.8 | F9: =E9/C9 -> 0.23633545 | G9: =(E9-E8)/E8 -> 0.035329151
A10: 2023-07-28 | B10: 511935 | C10: =SUMIFS(Table5[Net Sales Revenue],Table5[Date],'OPEX Analysis'!A10) -> 2219220.2 | D10: =SUMIFS(Table5[GrossProfit],Table5[Date],'OPEX Analysis'!A10) -> 1006856.2 | E10: =D10-B10 -> 494921.16 | F10: =E10/C10 -> 0.2230158 | G10: =(E10-E9)/E9 -> -0.13589649
A11: 2023-08-28 | B11: 515112 | C11: =SUMIFS(Table5[Net Sales Revenue],Table5[Date],'OPEX Analysis'!A11) -> 2450806.5 | D11: =SUMIFS(Table5[GrossProfit],Table5[Date],'OPEX Analysis'!A11) -> 1108602.5 | E11: =D11-B11 -> 593490.48 | F11: =E11/C11 -> 0.2421613 | G11: =(E11-E10)/E10 -> 0.19916166
A12: 2023-09-28 | B12: 509752 | C12: =SUMIFS(Table5[Net Sales Revenue],Table5[Date],'OPEX Analysis'!A12) -> 2400931.4 | D12: =SUMIFS(Table5[GrossProfit],Table5[Date],'OPEX Analysis'!A12) -> 1092019.4 | E12: =D12-B12 -> 582267.36 | F12: =E12/C12 -> 0.24251729 | G12: =(E12-E11)/E11 -> -0.018910362
A13: 2023-10-28 | B13: 526652 | C13: =SUMIFS(Table5[Net Sales Revenue],Table5[Date],'OPEX Analysis'!A13) -> 2284842 | D13: =SUMIFS(Table5[GrossProfit],Table5[Date],'OPEX Analysis'!A13) -> 1041714 | E13: =D13-B13 -> 515062.04 | F13: =E13/C13 -> 0.22542567 | G13: =(E13-E12)/E12 -> -0.11542004
A14: 2023-11-28 | B14: 502965 | C14: =SUMIFS(Table5[Net Sales Revenue],Table5[Date],'OPEX Analysis'!A14) -> 2279626.2 | D14: =SUMIFS(Table5[GrossProfit],Table5[Date],'OPEX Analysis'!A14) -> 1044634.2 | E14: =D14-B14 -> 541669.16 | F14: =E14/C14 -> 0.23761315 | G14: =(E14-E13)/E13 -> 0.051658088
A15: 2023-12-28 | B15: 503692 | C15: =SUMIFS(Table5[Net Sales Revenue],Table5[Date],'OPEX Analysis'!A15) -> 2491954.4 | D15: =SUMIFS(Table5[GrossProfit],Table5[Date],'OPEX Analysis'!A15) -> 1120354.4 | E15: =D15-B15 -> 616662.36 | F15: =E15/C15 -> 0.24746134 | G15: =(E15-E14)/E14 -> 0.13844835
A16: 2024-01-28 | B16: 585628 | C16: =SUMIFS(Table5[Net Sales Revenue],Table5[Date],'OPEX Analysis'!A16) -> 2423695.9 | D16: =SUMIFS(Table5[GrossProfit],Table5[Date],'OPEX Analysis'!A16) -> 865683.54 | E16: =D16-B16 -> 280055.54 | F16: =E16/C16 -> 0.11554896 | G16: =(E16-E15)/E15 -> -0.54585271
... A28: Grand Total | B28: 13037130 | C28: =SUMIFS(Table5[Net Sales Revenue],Table5[Date],'OPEX Analysis'!A28) -> 0 | D28: =SUMIFS(Table5[GrossProfit],Table5[Date],'OPEX Analysis'!A28) -> 0 | E28: =D28-B28 -> -13037130 | F28: =E28/C28 -> #DIV/0! | G28: =(E28-E27)/E27 -> -42.430581

Sheet Operating Expenses(clean)
A1: Month | B1: Store ID | C1: Staff Cost | D1: Rent Expense | E1: Utilities Expense | F1: Marketing Expense | G1: Logistics Cost | H1: Total OPEX | I1: Month (Date) | J1: Storelocation
A2: 2023-01-28 | B2: S01 | C2: 49556 | D2: 22977 | E2: 6952 | F2: 11166 | G2: 6944 | H2: =SUM(Table2[[#This Row],[Staff Cost]:[Logistics Cost]]) -> 97595 | I2: =DATE(YEAR(DATEVALUE(A3)),MONTH(DATEVALUE(A3)),1) -> 44927 | J2: =VLOOKUP(Table2[[#This Row],[Store ID]],Table4[[Store ID]:[Store Location]],2) -> Manchester
A3: 2023-01-28 | B3: S02 | C3: 48918 | D3: 24375 | E3: 6245 | F3: 10253 | G3: 6718 | H3: =SUM(Table2[[#This Row],[Staff Cost]:[Logistics Cost]]) -> 96509 | I3: =DATE(YEAR(DATEVALUE(A4)),MONTH(DATEVALUE(A4)),1) -> 44927 | J3: =VLOOKUP(Table2[[#This Row],[Store ID]],Table4[[Store ID]:[Store Location]],2) -> Birmingham
A4: 2023-01-28 | B4: S03 | C4: 50943 | D4: 25866 | E4: 8761 | F4: 14338 | G4: 7727 | H4: =SUM(Table2[[#This Row],[Staff Cost]:[Logistics Cost]]) -> 107635 | I4: =DATE(YEAR(DATEVALUE(A5)),MONTH(DATEVALUE(A5)),1) -> 44927 | J4: =VLOOKUP(Table2[[#This Row],[Store ID]],Table4[[Store ID]:[Store Location]],2) -> London Stratford
A5: 2023-01-28 | B5: S04 | C5: 52403 | D5: 24200 | E5: 6080 | F5: 14308 | G5: 6828 | H5: =SUM(Table2[[#This Row],[Staff Cost]:[Logistics Cost]]) -> 103819 | I5: =DATE(YEAR(DATEVALUE(A6)),MONTH(DATEVALUE(A6)),1) -> 44927 | J5: =VLOOKUP(Table2[[#This Row],[Store ID]],Table4[[Store ID]:[Store Location]],2) -> Glasgow
A6: 2023-01-28 | B6: S05 | C6: 47852 | D6: 23881 | E6: 6316 | F6: 16578 | G6: 7316 | H6: =SUM(Table2[[#This Row],[Staff Cost]:[Logistics Cost]]) -> 101943 | I6: =DATE(YEAR(DATEVALUE(A7)),MONTH(DATEVALUE(A7)),1) -> 44958 | J6: =VLOOKUP(Table2[[#This Row],[Store ID]],Table4[[Store ID]:[Store Location]],2) -> Leeds
A7: 2023-02-28 | B7: S01 | C7: 50135 | D7: 23054 | E7: 7989 | F7: 17832 | G7: 8168 | H7: =SUM(Table2[[#This Row],[Staff Cost]:[Logistics Cost]]) -> 107178 | I7: =DATE(YEAR(DATEVALUE(A8)),MONTH(DATEVALUE(A8)),1) -> 44958 | J7: =VLOOKUP(Table2[[#This Row],[Store ID]],Table4[[Store ID]:[Store Location]],2) -> Manchester
A8: 2023-02-28 | B8: S02 | C8: 47556 | D8: 23785 | E8: 7732 | F8: 17782 | G8: 8955 | H8: =SUM(Table2[[#This Row],[Staff Cost]:[Logistics Cost]]) -> 105810 | I8: =DATE(YEAR(DATEVALUE(A9)),MONTH(DATEVALUE(A9)),1) -> 44958 | J8: =VLOOKUP(Table2[[#This Row],[Store ID]],Table4[[Store ID]:[Store Location]],2) -> Birmingham
A9: 2023-02-28 | B9: S03 | C9: 50457 | D9: 22269 | E9: 7578 | F9: 10161 | G9: 8894 | H9: =SUM(Table2[[#This Row],[Staff Cost]:[Logistics Cost]]) -> 99359 | I9: =DATE(YEAR(DATEVALUE(A10)),MONTH(DATEVALUE(A10)),1) -> 44958 | J9: =VLOOKUP(Table2[[#This Row],[Store ID]],Table4[[Store ID]:[Store Location]],2) -> London Stratford
A10: 2023-02-28 | B10: S04 | C10: 45241 | D10: 24849 | E10: 8458 | F10: 13454 | G10: 6665 | H10: =SUM(Table2[[#This Row],[Staff Cost]:[Logistics Cost]]) -> 98667 | I10: =DATE(YEAR(DATEVALUE(A11)),MONTH(DATEVALUE(A11)),1) -> 44958 | J10: =VLOOKUP(Table2[[#This Row],[Store ID]],Table4[[Store ID]:[Store Location]],2) -> Glasgow
A11: 2023-02-28 | B11: S05 | C11: 46072 | D11: 22356 | E11: 6222 | F11: 12909 | G11: 8455 | H11: =SUM(Table2[[#This Row],[Staff Cost]:[Logistics Cost]]) -> 96014 | I11: =DATE(YEAR(DATEVALUE(A12)),MONTH(DATEVALUE(A12)),1) -> 44986 | J11: =VLOOKUP(Table2[[#This Row],[Store ID]],Table4[[Store ID]:[Store Location]],2) -> Leeds
A12: 2023-03-28 | B12: S01 | C12: 50867 | D12: 24097 | E12: 8057 | F12: 11308 | G12: 7777 | H12: =SUM(Table2[[#This Row],[Staff Cost]:[Logistics Cost]]) -> 102106 | I12: =DATE(YEAR(DATEVALUE(A13)),MONTH(DATEVALUE(A13)),1) -> 44986 | J12: =VLOOKUP(Table2[[#This Row],[Store ID]],Table4[[Store ID]:[Store Location]],2) -> Manchester
A13: 2023-03-28 | B13: S02 | C13: 49895 | D13: 25533 | E13: 7687 | F13: 12068 | G13: 8882 | H13: =SUM(Table2[[#This Row],[Staff Cost]:[Logistics Cost]]) -> 104065 | I13: =DATE(YEAR(DATEVALUE(A14)),MONTH(DATEVALUE(A14)),1) -> 44986 | J13: =VLOOKUP(Table2[[#This Row],[Store ID]],Table4[[Store ID]:[Store Location]],2) -> Birmingham
... A121: 2024-12-28 | B121: S05 | C121: 52376 | D121: 25087 | E121: 8283 | F121: 17300 | G121: 9187 | H121: =SUM(Table2[[#This Row],[Staff Cost]:[Logistics Cost]]) -> 112233 | I121: =DATE(YEAR(DATEVALUE(A122)),MONTH(DATEVALUE(A122)),1) -> #VALUE! | J121: =VLOOKUP(Table2[[#This Row],[Store ID]],Table4[[Store ID]:[Store Location]],2) -> Leeds

Sheet Marketing Campaign_Data
A1: Campaign ID | B1: Campaign Period | C1: Marketing Channel | D1: Campaign Cost | E1: Sales Generated | F1: RO1
A2: C001 | B2: 2023-01 | C2: Paid Search | D2: 165338 | E2: 516673.64 | F2: =Table3[[#This Row],[Sales Generated]]/Table3[[#This Row],[Campaign Cost]] -> 3.124954
A3: C002 | B3: 2023-02 | C3: Social Media | D3: 100323 | E3: 327261.6 | F3: =Table3[[#This Row],[Sales Generated]]/Table3[[#This Row],[Campaign Cost]] -> 3.2620795
A4: C003 | B4: 2023-03 | C4: Paid Search | D4: 164456 | E4: 494226.07 | F4: =Table3[[#This Row],[Sales Generated]]/Table3[[#This Row],[Campaign Cost]] -> 3.0052176
A5: C004 | B5: 2023-04 | C5: Email | D5: 127365 | E5: 399537.83 | F5: =Table3[[#This Row],[Sales Generated]]/Table3[[#This Row],[Campaign Cost]] -> 3.1369515
A6: C005 | B6: 2023-05 | C6: Email | D6: 106383 | E6: 321779.88 | F6: =Table3[[#This Row],[Sales Generated]]/Table3[[#This Row],[Campaign Cost]] -> 3.0247303
A7: C006 | B7: 2023-06 | C7: TV | D7: 78660 | E7: 253364.06 | F7: =Table3[[#This Row],[Sales Generated]]/Table3[[#This Row],[Campaign Cost]] -> 3.2210025
A8: C007 | B8: 2023-07 | C8: Influencer | D8: 137026 | E8: 467299.32 | F8: =Table3[[#This Row],[Sales Generated]]/Table3[[#This Row],[Campaign Cost]] -> 3.4102967
A9: C008 | B9: 2023-08 | C9: Influencer | D9: 189114 | E9: 596829.75 | F9: =Table3[[#This Row],[Sales Generated]]/Table3[[#This Row],[Campaign Cost]] -> 3.1559258
A10: C009 | B10: 2023-09 | C10: Email | D10: 121245 | E10: 415511.32 | F10: =Table3[[#This Row],[Sales Generated]]/Table3[[#This Row],[Campaign Cost]] -> 3.4270388
A11: C010 | B11: 2023-10 | C11: Social Media | D11: 117821 | E11: 396719.62 | F11: =Table3[[#This Row],[Sales Generated]]/Table3[[#This Row],[Campaign Cost]] -> 3.3671385
A12: C011 | B12: 2023-11 | C12: Influencer | D12: 175857 | E12: 550762.95 | F12: =Table3[[#This Row],[Sales Generated]]/Table3[[#This Row],[Campaign Cost]] -> 3.1318796
A13: C012 | B13: 2023-12 | C13: TV | D13: 194036 | E13: 661591.77 | F13: =Table3[[#This Row],[Sales Generated]]/Table3[[#This Row],[Campaign Cost]] -> 3.4096341
... A25: C024 | B25: 2024-12 | C25: TV | D25: 77252 | E25: 191210.19 | F25: =Table3[[#This Row],[Sales Generated]]/Table3[[#This Row],[Campaign Cost]] -> 2.4751487

Sheet KPI Directory
A1: KPI Directory
A3: KPI | C3: Formula
A4: Revenue Growth % Measures how revenue changes over time. | C4: (Revenue this period – Revenue last period) ÷ Revenue last period × 100
A5: Units Growth % Measures change in units sold. | C5: (Total Units sold this period – Tota Units sold last period) ÷ Total Units sold last period × 100
A6: Discount % Helps to show the average discount applied. | C6: Total discount ÷ Total sales before discount × 100
A7: Gross Margin % helps to show profitability after deducting cost of sales | C7: (Net Sales Revenue – Cost of Sales) ÷ Net Sales Revenue × 100
A8: Operating Margin % helps to show profitability after deducting operating cost | C8: Operating Profit ÷ Net Sales Revenue × 100
A9: Cost of Sales Growth % Measures change in cost of sales. | C9: (COS this period – COS last period) ÷ COS last period × 100
A10: Staff Cost Growth % Measures change in Staff costs. | C10: (Staff Cost this period – Staff Cost last period) ÷ Staff Cost last period × 100
A11: Logistics Cost Growth % Measures change in logistics costs. | C11: (Logistics Cost this period – Logistics Cost last period) ÷ Logistics Cost last period × 100
A12: Marketing ROI Shows Returns generated from marketing spend | C12: Sales Generated ÷ Marketing Spend
A13: Revenue per Store Measures store productivity in terms of total revenue generated | C13: Total Revenue ÷Total Number of Stores
A14: Revenue per Unit Measures average revenue per unit sold | C14: Net Sales Revenue ÷ Units Sold
A18: A. KPI Categories
A20: Financial KPIs
A22: Revenue Growth %
A24: Gross Margin %
A26: Operating Margin %
A28: Revenue per Store
A30: Revenue per Unit
A32: Operational KPIs
A34: Units Growth %
A36: Discount %
A38: Cost of Sales Growth %
A40: Staff Cost Growth %
... A44: Marketing ROI

Sheet Revenue Trend Report
A1: Revenue Trend Report
A4: Month | B4: Net Sales Revenue | C4: Revenue Growth % (MoM) | D4: Revenue Growth % (YoY) | E4: 3-Month Rolling Avg Revenue | F4: Operating Cost
A5: =Calender!A5 -> 2023-01 | B5: =SUMIFS(Table5[Net Sales Revenue],Table5[month Key],'Revenue Trend Report'!A5) -> 2329918.2 | C5: N/A | D5: N/A
A6: =Calender!A6 -> 2023-02 | B6: =SUMIFS(Table5[Net Sales Revenue],Table5[month Key],'Revenue Trend Report'!A6) -> 2487689.4 | C6: =(B6-B5)/B5 -> 0.067715338 | D6: N/A
A7: =Calender!A7 -> 2023-03 | B7: =SUMIFS(Table5[Net Sales Revenue],Table5[month Key],'Revenue Trend Report'!A7) -> 2444790.6 | C7: =(B7-B6)/B6 -> -0.017244452 | D7: N/A | E7: =AVERAGE(B5:B7) -> 2420799.4
A8: =Calender!A8 -> 2023-04 | B8: =SUMIFS(Table5[Net Sales Revenue],Table5[month Key],'Revenue Trend Report'!A8) -> 2436376.6 | C8: =(B8-B7)/B7 -> -0.0034416199 | D8: N/A | E8: =AVERAGE(B6:B8) -> 2456285.5
A9: =Calender!A9 -> 2023-05 | B9: =SUMIFS(Table5[Net Sales Revenue],Table5[month Key],'Revenue Trend Report'!A9) -> 2336372.3 | C9: =(B9-B8)/B8 -> -0.041046315 | D9: N/A | E9: =AVERAGE(B7:B9) -> 2405846.5
A10: =Calender!A10 -> 2023-06 | B10: =SUMIFS(Table5[Net Sales Revenue],Table5[month Key],'Revenue Trend Report'!A10) -> 2423490.8 | C10: =(B10-B9)/B9 -> 0.037287945 | D10: N/A | E10: =AVERAGE(B8:B10) -> 2398746.5
A11: =Calender!A11 -> 2023-07 | B11: =SUMIFS(Table5[Net Sales Revenue],Table5[month Key],'Revenue Trend Report'!A11) -> 2219220.2 | C11: =(B11-B10)/B10 -> -0.084287772 | D11: N/A | E11: =AVERAGE(B9:B11) -> 2326361.1
A12: =Calender!A12 -> 2023-08 | B12: =SUMIFS(Table5[Net Sales Revenue],Table5[month Key],'Revenue Trend Report'!A12) -> 2450806.5 | C12: =(B12-B11)/B11 -> 0.10435482 | D12: N/A | E12: =AVERAGE(B10:B12) -> 2364505.8
A13: =Calender!A13 -> 2023-09 | B13: =SUMIFS(Table5[Net Sales Revenue],Table5[month Key],'Revenue Trend Report'!A13) -> 2400931.4 | C13: =(B13-B12)/B12 -> -0.020350493 | D13: N/A | E13: =AVERAGE(B11:B13) -> 2356986
A14: =Calender!A14 -> 2023-10 | B14: =SUMIFS(Table5[Net Sales Revenue],Table5[month Key],'Revenue Trend Report'!A14) -> 2284842 | C14: =(B14-B13)/B13 -> -0.048351786 | D14: N/A | E14: =AVERAGE(B12:B14) -> 2378860
A15: =Calender!A15 -> 2023-11 | B15: =SUMIFS(Table5[Net Sales Revenue],Table5[month Key],'Revenue Trend Report'!A15) -> 2279626.2 | C15: =(B15-B14)/B14 -> -0.0022828186 | D15: N/A | E15: =AVERAGE(B13:B15) -> 2321799.9
A16: =Calender!A16 -> 2023-12 | B16: =SUMIFS(Table5[Net Sales Revenue],Table5[month Key],'Revenue Trend Report'!A16) -> 2491954.4 | C16: =(B16-B15)/B15 -> 0.093141675 | D16: N/A | E16: =AVERAGE(B14:B16) -> 2352140.9
A17: =Calender!A17 -> 2024-01 | B17: =SUMIFS(Table5[Net Sales Revenue],Table5[month Key],'Revenue Trend Report'!A17) -> 2423695.9 | C17: =(B17-B16)/B16 -> -0.027391553 | D17: =(B17-B5)/B5 -> 0.040249318 | E17: =AVERAGE(B15:B17) -> 2398425.5
A18: =Calender!A18 -> 2024-02 | B18: =SUMIFS(Table5[Net Sales Revenue],Table5[month Key],'Revenue Trend Report'!A18) -> 2357448.7 | C18: =(B18-B17)/B17 -> -0.027333137 | D18: =(B18-B6)/B6 -> -0.052354119 | E18: =AVERAGE(B16:B18) -> 2424366.3
A19: =Calender!A19 -> 2024-03 | B19: =SUMIFS(Table5[Net Sales Revenue],Table5[month Key],'Revenue Trend Report'!A19) -> 2338098.1 | C19: =(B19-B18)/B18 -> -0.0082082424 | D19: =(B19-B7)/B7 -> -0.043640736 | E19: =AVERAGE(B17:B19) -> 2373080.9
A20: =Calender!A20 -> 2024-04 | B20: =SUMIFS(Table5[Net Sales Revenue],Table5[month Key],'Revenue Trend Report'!A20) -> 2357454.1 | C20: =(B20-B19)/B19 -> 0.0082785062 | D20: =(B20-B8)/B8 -> -0.032393375 | E20: =AVERAGE(B18:B20) -> 2351000.3
A21: =Calender!A21 -> 2024-05 | B21: =SUMIFS(Table5[Net Sales Revenue],Table5[month Key],'Revenue Trend Report'!A21) -> 2542740.1 | C21: =(B21-B20)/B20 -> 0.078595787 | D21: =(B21-B9)/B9 -> 0.088328295 | E21: =AVERAGE(B19:B21) -> 2412764.1
A22: =Calender!A22 -> 2024-06 | B22: =SUMIFS(Table5[Net Sales Revenue],Table5[month Key],'Revenue Trend Report'!A22) -> 2447755.6 | C22: =(B22-B21)/B21 -> -0.037355148 | D22: =(B22-B10)/B10 -> 0.010012347 | E22: =AVERAGE(B20:B22) -> 2449316.6
A23: =Calender!A23 -> 2024-07 | B23: =SUMIFS(Table5[Net Sales Revenue],Table5[month Key],'Revenue Trend Report'!A23) -> 2297132.7 | C23: =(B23-B22)/B22 -> -0.061535134 | D23: =(B23-B11)/B11 -> 0.035108053 | E23: =AVERAGE(B21:B23) -> 2429209.5
A24: =Calender!A24 -> 2024-08 | B24: =SUMIFS(Table5[Net Sales Revenue],Table5[month Key],'Revenue Trend Report'!A24) -> 2377319.6 | C24: =(B24-B23)/B23 -> 0.034907392 | D24: =(B24-B12)/B12 -> -0.029984787 | E24: =AVERAGE(B22:B24) -> 2374069.3
A25: =Calender!A25 -> 2024-09 | B25: =SUMIFS(Table5[Net Sales Revenue],Table5[month Key],'Revenue Trend Report'!A25) -> 2373028.6 | C25: =(B25-B24)/B24 -> -0.0018049782 | D25: =(B25-B13)/B13 -> -0.011621657 | E25: =AVERAGE(B23:B25) -> 2349160.3
A26: =Calender!A26 -> 2024-10 | B26: =SUMIFS(Table5[Net Sales Revenue],Table5[month Key],'Revenue Trend Report'!A26) -> 2437406.2 | C26: =(B26-B25)/B25 -> 0.027128877 | D26: =(B26-B14)/B14 -> 0.066772283 | E26: =AVERAGE(B24:B26) -> 2395918.1
A27: =Calender!A27 -> 2024-11 | B27: =SUMIFS(Table5[Net Sales Revenue],Table5[month Key],'Revenue Trend Report'!A27) -> 2538509.6 | C27: =(B27-B26)/B26 -> 0.041479944 | D27: =(B27-B15)/B15 -> 0.113564 | E27: =AVERAGE(B25:B27) -> 2449648.1
A28: =Calender!A28 -> 2024-12 | B28: =SUMIFS(Table5[Net Sales Revenue],Table5[month Key],'Revenue Trend Report'!A28) -> 2455425 | C28: =(B28-B27)/B27 -> -0.032729704 | D28: =(B28-B16)/B16 -> -0.014658936 | E28: =AVERAGE(B26:B28) -> 2477113.6

Sheet Margin compression Analysis
A1: Month | B1: Net Sales Revenue | C1: Cost of Sales | D1: Gross Profit | E1: Gross Margin % | F1: Staff Cost | G1: Rent Expense | H1: Utilities Expense | I1: Marketing Expense | J1: Logistics Cost | K1: Total Operating Expense | L1: Operating Profit | M1: Operating Margin % | N1: Revenue Growth % (MoM) | O1: Total Cost Growth % (MoM) | P1: Growth Gap (Rev - Cost), pts | Q1: Staff Cost Growth % (MoM) | R1: Logistics Cost Growth % (MoM) | S1: Gross Margin % Point Change (MoM) | T1: Operating Margin % Point Change (MoM)
A2: 44927 | B2: ='[1]Revenue Trend Report'!B2 -> 2329918.2 | C2: =SUMIFS('[1]Sales Transactions (Clean)'!$J$2:$J$1081,'[1]Sales Transactions (Clean)'!$L$2:$L$1081,A2) -> 1272148 | D2: =B2-C2 -> 1057770.2 | E2: =D2/B2 -> 0.45399457 | F2: =SUMIFS('[1]Operating Expenses (Clean)'!$C$2:$C$121,'[1]Operating Expenses (Clean)'!$I$2:$I$121,A2) -> 249672 | G2: =SUMIFS('[1]Operating Expenses (Clean)'!$D$2:$D$121,'[1]Operating Expenses (Clean)'!$I$2:$I$121,A2) -> 121299 | H2: =SUMIFS('[1]Operating Expenses (Clean)'!$E$2:$E$121,'[1]Operating Expenses (Clean)'!$I$2:$I$121,A2) -> 34354 | I2: =SUMIFS('[1]Operating Expenses (Clean)'!$F$2:$F$121,'[1]Operating Expenses (Clean)'!$I$2:$I$121,A2) -> 66643 | J2: =SUMIFS('[1]Operating Expenses (Clean)'!$G$2:$G$121,'[1]Operating Expenses (Clean)'!$I$2:$I$121,A2) -> 35533 | K2: =SUM(F2:J2) -> 507501 | L2: =D2-K2 -> 550269.24 | M2: =L2/B2 -> 0.23617534 | N2: n/a | O2: n/a | P2: n/a | Q2: n/a | R2: n/a | S2: n/a | T2: n/a
A3: 44958 | B3: ='[1]Revenue Trend Report'!B3 -> 2487689.4 | C3: =SUMIFS('[1]Sales Transactions (Clean)'!$J$2:$J$1081,'[1]Sales Transactions (Clean)'!$L$2:$L$1081,A3) -> 1362756 | D3: =B3-C3 -> 1124933.4 | E3: =D3/B3 -> 0.45220011 | F3: =SUMIFS('[1]Operating Expenses (Clean)'!$C$2:$C$121,'[1]Operating Expenses (Clean)'!$I$2:$I$121,A3) -> 239461 | G3: =SUMIFS('[1]Operating Expenses (Clean)'!$D$2:$D$121,'[1]Operating Expenses (Clean)'!$I$2:$I$121,A3) -> 116313 | H3: =SUMIFS('[1]Operating Expenses (Clean)'!$E$2:$E$121,'[1]Operating Expenses (Clean)'!$I$2:$I$121,A3) -> 37979 | I3: =SUMIFS('[1]Operating Expenses (Clean)'!$F$2:$F$121,'[1]Operating Expenses (Clean)'!$I$2:$I$121,A3) -> 72138 | J3: =SUMIFS('[1]Operating Expenses (Clean)'!$G$2:$G$121,'[1]Operating Expenses (Clean)'!$I$2:$I$121,A3) -> 41137 | K3: =SUM(F3:J3) -> 507028 | L3: =D3-K3 -> 617905.44 | M3: =L3/B3 -> 0.24838528 | N3: =(B3-B2)/B2 -> 0.067715338 | O3: =((C3+K3)-(C2+K2))/(C2+K2) -> 0.050647628 | P3: =N3-O3 -> 0.01706771 | Q3: =(F3-F2)/F2 -> -0.040897658 | R3: =(J3-J2)/J2 -> 0.15771255 | S3: =E3-E2 -> -0.0017944639 | T3: =M3-M2 -> 0.012209938
A4: 44986 | B4: ='[1]Revenue Trend Report'!B4 -> 2444790.6 | C4: =SUMIFS('[1]Sales Transactions (Clean)'!$J$2:$J$1081,'[1]Sales Transactions (Clean)'!$L$2:$L$1081,A4) -> 1333340 | D4: =B4-C4 -> 1111450.6 | E4: =D4/B4 -> 0.45461996 | F4: =SUMIFS('[1]Operating Expenses (Clean)'!$C$2:$C$121,'[1]Operating Expenses (Clean)'!$I$2:$I$121,A4) -> 244608 | G4: =SUMIFS('[1]Operating Expenses (Clean)'!$D$2:$D$121,'[1]Operating Expenses (Clean)'!$I$2:$I$121,A4) -> 123717 | H4: =SUMIFS('[1]Operating Expenses (Clean)'!$E$2:$E$121,'[1]Operating Expenses (Clean)'!$I$2:$I$121,A4) -> 36125 | I4: =SUMIFS('[1]Operating Expenses (Clean)'!$F$2:$F$121,'[1]Operating Expenses (Clean)'!$I$2:$I$121,A4) -> 59720 | J4: =SUMIFS('[1]Operating Expenses (Clean)'!$G$2:$G$121,'[1]Operating Expenses (Clean)'!$I$2:$I$121,A4) -> 38291 | K4: =SUM(F4:J4) -> 502461 | L4: =D4-K4 -> 608989.6 | M4: =L4/B4 -> 0.24909683 | N4: =(B4-B3)/B3 -> -0.017244452 | O4: =((C4+K4)-(C3+K3))/(C3+K3) -> -0.018174827 | P4: =N4-O4 -> 0.00093037507 | Q4: =(F4-F3)/F3 -> 0.021494106 | R4: =(J4-J3)/J3 -> -0.06918346 | S4: =E4-E3 -> 0.0024198474 | T4: =M4-M3 -> 0.00071155395
A5: 45017 | B5: ='[1]Revenue Trend Report'!B5 -> 2436376.6 | C5: =SUMIFS('[1]Sales Transactions (Clean)'!$J$2:$J$1081,'[1]Sales Transactions (Clean)'!$L$2:$L$1081,A5) -> 1334128 | D5: =B5-C5 -> 1102248.6 | E5: =D5/B5 -> 0.45241305 | F5: =SUMIFS('[1]Operating Expenses (Clean)'!$C$2:$C$121,'[1]Operating Expenses (Clean)'!$I$2:$I$121,A5) -> 258178 | G5: =SUMIFS('[1]Operating Expenses (Clean)'!$D$2:$D$121,'[1]Operating Expenses (Clean)'!$I$2:$I$121,A5) -> 119341 | H5: =SUMIFS('[1]Operating Expenses (Clean)'!$E$2:$E$121,'[1]Operating Expenses (Clean)'!$I$2:$I$121,A5) -> 34757 | I5: =SUMIFS('[1]Operating Expenses (Clean)'!$F$2:$F$121,'[1]Operating Expenses (Clean)'!$I$2:$I$121,A5) -> 72825 | J5: =SUMIFS('[1]Operating Expenses (Clean)'!$G$2:$G$121,'[1]Operating Expenses (Clean)'!$I$2:$I$121,A5) -> 34244 | K5: =SUM(F5:J5) -> 519345 | L5: =D5-K5 -> 582903.56 | M5: =L5/B5 -> 0.23925019 | N5: =(B5-B4)/B4 -> -0.0034416199 | O5: =((C5+K5)-(C4+K4))/(C4+K4) -> 0.0096263157 | P5: =N5-O5 -> -0.013067936 | Q5: =(F5-F4)/F4 -> 0.055476518 | R5: =(J5-J4)/J4 -> -0.10569063 | S5: =E5-E4 -> -0.0022069041 | T5: =M5-M4 -> -0.0098466426
A6: 45047 | B6: ='[1]Revenue Trend Report'!B6 -> 2336372.3 | C6: =SUMIFS('[1]Sales Transactions (Clean)'!$J$2:$J$1081,'[1]Sales Transactions (Clean)'!$L$2:$L$1081,A6) -> 1277596 | D6: =B6-C6 -> 1058776.3 | E6: =D6/B6 -> 0.45317105 | F6: =SUMIFS('[1]Operating Expenses (Clean)'!$C$2:$C$121,'[1]Operating Expenses (Clean)'!$I$2:$I$121,A6) -> 242106 | G6: =SUMIFS('[1]Operating Expenses (Clean)'!$D$2:$D$121,'[1]Operating Expenses (Clean)'!$I$2:$I$121,A6) -> 122561 | H6: =SUMIFS('[1]Operating Expenses (Clean)'!$E$2:$E$121,'[1]Operating Expenses (Clean)'!$I$2:$I$121,A6) -> 37100 | I6: =SUMIFS('[1]Operating Expenses (Clean)'!$F$2:$F$121,'[1]Operating Expenses (Clean)'!$I$2:$I$121,A6) -> 65379 | J6: =SUMIFS('[1]Operating Expenses (Clean)'!$G$2:$G$121,'[1]Operating Expenses (Clean)'!$I$2:$I$121,A6) -> 38418 | K6: =SUM(F6:J6) -> 505564 | L6: =D6-K6 -> 553212.28 | M6: =L6/B6 -> 0.23678259 | N6: =(B6-B5)/B5 -> -0.041046315 | O6: =((C6+K6)-(C5+K5))/(C5+K5) -> -0.03793581 | P6: =N6-O6 -> -0.0031105049 | Q6: =(F6-F5)/F5 -> -0.062251625 | R6: =(J6-J5)/J5 -> 0.12188997 | S6: =E6-E5 -> 0.00075799638 | T6: =M6-M5 -> -0.002467602
A7: 45078 | B7: ='[1]Revenue Trend Report'!B7 -> 2423490.8 | C7: =SUMIFS('[1]Sales Transactions (Clean)'!$J$2:$J$1081,'[1]Sales Transactions (Clean)'!$L$2:$L$1081,A7) -> 1331348 | D7: =B7-C7 -> 1092142.8 | E7: =D7/B7 -> 0.45064863 | F7: =SUMIFS('[1]Operating Expenses (Clean)'!$C$2:$C$121,'[1]Operating Expenses (Clean)'!$I$2:$I$121,A7) -> 254708 | G7: =SUMIFS('[1]Operating Expenses (Clean)'!$D$2:$D$121,'[1]Operating Expenses (Clean)'!$I$2:$I$121,A7) -> 118068 | H7: =SUMIFS('[1]Operating Expenses (Clean)'!$E$2:$E$121,'[1]Operating Expenses (Clean)'!$I$2:$I$121,A7) -> 37088 | I7: =SUMIFS('[1]Operating Expenses (Clean)'!$F$2:$F$121,'[1]Operating Expenses (Clean)'!$I$2:$I$121,A7) -> 70214 | J7: =SUMIFS('[1]Operating Expenses (Clean)'!$G$2:$G$121,'[1]Operating Expenses (Clean)'!$I$2:$I$121,A7) -> 39308 | K7: =SUM(F7:J7) -> 519386 | L7: =D7-K7 -> 572756.8 | M7: =L7/B7 -> 0.23633545 | N7: =(B7-B6)/B6 -> 0.037287945 | O7: =((C7+K7)-(C6+K6))/(C6+K6) -> 0.037895646 | P7: =N7-O7 -> -0.00060770139 | Q7: =(F7-F6)/F6 -> 0.052051581 | R7: =(J7-J6)/J6 -> 0.023166224 | S7: =E7-E6 -> -0.0025224239 | T7: =M7-M6 -> -0.00044713552
A8: 45108 | B8: ='[1]Revenue Trend Report'!B8 -> 2219220.2 | C8: =SUMIFS('[1]Sales Transactions (Clean)'!$J$2:$J$1081,'[1]Sales Transactions (Clean)'!$L$2:$L$1081,A8) -> 1212364 | D8: =B8-C8 -> 1006856.2 | E8: =D8/B8 -> 0.45369819 | F8: =SUMIFS('[1]Operating Expenses (Clean)'!$C$2:$C$121,'[1]Operating Expenses (Clean)'!$I$2:$I$121,A8) -> 246420 | G8: =SUMIFS('[1]Operating Expenses (Clean)'!$D$2:$D$121,'[1]Operating Expenses (Clean)'!$I$2:$I$121,A8) -> 118303 | H8: =SUMIFS('[1]Operating Expenses (Clean)'!$E$2:$E$121,'[1]Operating Expenses (Clean)'!$I$2:$I$121,A8) -> 36153 | I8: =SUMIFS('[1]Operating Expenses (Clean)'!$F$2:$F$121,'[1]Operating Expenses (Clean)'!$I$2:$I$121,A8) -> 75281 | J8: =SUMIFS('[1]Operating Expenses (Clean)'!$G$2:$G$121,'[1]Operating Expenses (Clean)'!$I$2:$I$121,A8) -> 35778 | K8: =SUM(F8:J8) -> 511935 | L8: =D8-K8 -> 494921.16 | M8: =L8/B8 -> 0.2230158 | N8: =(B8-B7)/B7 -> -0.084287772 | O8: =((C8+K8)-(C7+K7))/(C7+K7) -> -0.068316138 | P8: =N8-O8 -> -0.015971634 | Q8: =(F8-F7)/F7 -> -0.032539221 | R8: =(J8-J7)/J7 -> -0.089803602 | S8: =E8-E7 -> 0.0030495592 | T8: =M8-M7 -> -0.013319654
A9: 45139 | B9: ='[1]Revenue Trend Report'!B9 -> 2450806.5 | C9: =SUMIFS('[1]Sales Transactions (Clean)'!$J$2:$J$1081,'[1]Sales Transactions (Clean)'!$L$2:$L$1081,A9) -> 1342204 | D9: =B9-C9 -> 1108602.5 | E9: =D9/B9 -> 0.45234191 | F9: =SUMIFS('[1]Operating Expenses (Clean)'!$C$2:$C$121,'[1]Operating Expenses (Clean)'!$I$2:$I$121,A9) -> 254168 | G9: =SUMIFS('[1]Operating Expenses (Clean)'!$D$2:$D$121,'[1]Operating Expenses (Clean)'!$I$2:$I$121,A9) -> 121038 | H9: =SUMIFS('[1]Operating Expenses (Clean)'!$E$2:$E$121,'[1]Operating Expenses (Clean)'!$I$2:$I$121,A9) -> 41468 | I9: =SUMIFS('[1]Operating Expenses (Clean)'!$F$2:$F$121,'[1]Operating Expenses (Clean)'!$I$2:$I$121,A9) -> 60773 | J9: =SUMIFS('[1]Operating Expenses (Clean)'!$G$2:$G$121,'[1]Operating Expenses (Clean)'!$I$2:$I$121,A9) -> 37665 | K9: =SUM(F9:J9) -> 515112 | L9: =D9-K9 -> 593490.48 | M9: =L9/B9 -> 0.2421613 | N9: =(B9-B8)/B8 -> 0.10435482 | O9: =((C9+K9)-(C8+K8))/(C8+K8) -> 0.077142653 | P9: =N9-O9 -> 0.027212167 | Q9: =(F9-F8)/F8 -> 0.031442253 | R9: =(J9-J8)/J8 -> 0.052741908 | S9: =E9-E8 -> -0.0013562773 | T9: =M9-M8 -> 0.019145498
A10: 45170 | B10: ='[1]Revenue Trend Report'!B10 -> 2400931.4 | C10: =SUMIFS('[1]Sales Transactions (Clean)'!$J$2:$J$1081,'[1]Sales Transactions (Clean)'!$L$2:$L$1081,A10) -> 1308912 | D10: =B10-C10 -> 1092019.4 | E10: =D10/B10 -> 0.45483156 | F10: =SUMIFS('[1]Operating Expenses (Clean)'!$C$2:$C$121,'[1]Operating Expenses (Clean)'!$I$2:$I$121,A10) -> 246628 | G10: =SUMIFS('[1]Operating Expenses (Clean)'!$D$2:$D$121,'[1]Operating Expenses (Clean)'!$I$2:$I$121,A10) -> 123020 | H10: =SUMIFS('[1]Operating Expenses (Clean)'!$E$2:$E$121,'[1]Operating Expenses (Clean)'!$I$2:$I$121,A10) -> 32931 | I10: =SUMIFS('[1]Operating Expenses (Clean)'!$F$2:$F$121,'[1]Operating Expenses (Clean)'!$I$2:$I$121,A10) -> 69307 | J10: =SUMIFS('[1]Operating Expenses (Clean)'!$G$2:$G$121,'[1]Operating Expenses (Clean)'!$I$2:$I$121,A10) -> 37866 | K10: =SUM(F10:J10) -> 509752 | L10: =D10-K10 -> 582267.36 | M10: =L10/B10 -> 0.24251729 | N10: =(B10-B9)/B9 -> -0.020350493 | O10: =((C10+K10)-(C9+K9))/(C9+K9) -> -0.020810675 | P10: =N10-O10 -> 0.00046018224 | Q10: =(F10-F9)/F9 -> -0.029665418 | R10: =(J10-J9)/J9 -> 0.0053365193 | S10: =E10-E9 -> 0.0024896534 | T10: =M10-M9 -> 0.00035598845
A11: 45200 | B11: ='[1]Revenue Trend Report'!B11 -> 2284842 | C11: =SUMIFS('[1]Sales Transactions (Clean)'!$J$2:$J$1081,'[1]Sales Transactions (Clean)'!$L$2:$L$1081,A11) -> 1243128 | D11: =B11-C11 -> 1041714 | E11: =D11/B11 -> 0.45592388 | F11: =SUMIFS('[1]Operating Expenses (Clean)'!$C$2:$C$121,'[1]Operating Expenses (Clean)'!$I$2:$I$121,A11) -> 252401 | G11: =SUMIFS('[1]Operating Expenses (Clean)'!$D$2:$D$121,'[1]Operating Expenses (Clean)'!$I$2:$I$121,A11) -> 120110 | H11: =SUMIFS('[1]Operating Expenses (Clean)'!$E$2:$E$121,'[1]Operating Expenses (Clean)'!$I$2:$I$121,A11) -> 36493 | I11: =SUMIFS('[1]Operating Expenses (Clean)'!$F$2:$F$121,'[1]Operating Expenses (Clean)'!$I$2:$I$121,A11) -> 80035 | J11: =SUMIFS('[1]Operating Expenses (Clean)'!$G$2:$G$121,'[1]Operating Expenses (Clean)'!$I$2:$I$121,A11) -> 37613 | K11: =SUM(F11:J11) -> 526652 | L11: =D11-K11 -> 515062.04 | M11: =L11/B11 -> 0.22542567 | N11: =(B11-B10)/B10 -> -0.048351786 | O11: =((C11+K11)-(C10+K10))/(C10+K10) -> -0.026879072 | P11: =N11-O11 -> -0.021472715 | Q11: =(F11-F10)/F10 -> 0.023407723 | R11: =(J11-J10)/J10 -> -0.0066814557 | S11: =E11-E10 -> 0.0010923148 | T11: =M11-M10 -> -0.01709162
A12: 45231 | B12: ='[1]Revenue Trend Report'!B12 -> 2279626.2 | C12: =SUMIFS('[1]Sales Transactions (Clean)'!$J$2:$J$1081,'[1]Sales Transactions (Clean)'!$L$2:$L$1081,A12) -> 1234992 | D12: =B12-C12 -> 1044634.2 | E12: =D12/B12 -> 0.45824801 | F12: =SUMIFS('[1]Operating Expenses (Clean)'!$C$2:$C$121,'[1]Operating Expenses (Clean)'!$I$2:$I$121,A12) -> 248445 | G12: =SUMIFS('[1]Operating Expenses (Clean)'!$D$2:$D$121,'[1]Operating Expenses (Clean)'!$I$2:$I$121,A12) -> 117433 | H12: =SUMIFS('[1]Operating Expenses (Clean)'!$E$2:$E$121,'[1]Operating Expenses (Clean)'!$I$2:$I$121,A12) -> 38281 | I12: =SUMIFS('[1]Operating Expenses (Clean)'!$F$2:$F$121,'[1]Operating Expenses (Clean)'!$I$2:$I$121,A12) -> 63066 | J12: =SUMIFS('[1]Operating Expenses (Clean)'!$G$2:$G$121,'[1]Operating Expenses (Clean)'!$I$2:$I$121,A12) -> 35740 | K12: =SUM(F12:J12) -> 502965 | L12: =D12-K12 -> 541669.16 | M12: =L12/B12 -> 0.23761315 | N12: =(B12-B11)/B11 -> -0.0022828186 | O12: =((C12+K12)-(C11+K11))/(C11+K11) -> -0.017981331 | P12: =N12-O12 -> 0.015698512 | Q12: =(F12-F11)/F11 -> -0.015673472 | R12: =(J12-J11)/J11 -> -0.049796613 | S12: =E12-E11 -> 0.0023241373 | T12: =M12-M11 -> 0.012187487
A13: 45261 | B13: ='[1]Revenue Trend Report'!B13 -> 2491954.4 | C13: =SUMIFS('[1]Sales Transactions (Clean)'!$J$2:$J$1081,'[1]Sales Transactions (Clean)'!$L$2:$L$1081,A13) -> 1371600 | D13: =B13-C13 -> 1120354.4 | E13: =D13/B13 -> 0.44958864 | F13: =SUMIFS('[1]Operating Expenses (Clean)'!$C$2:$C$121,'[1]Operating Expenses (Clean)'!$I$2:$I$121,A13) -> 236955 | G13: =SUMIFS('[1]Operating Expenses (Clean)'!$D$2:$D$121,'[1]Operating Expenses (Clean)'!$I$2:$I$121,A13) -> 119737 | H13: =SUMIFS('[1]Operating Expenses (Clean)'!$E$2:$E$121,'[1]Operating Expenses (Clean)'!$I$2:$I$121,A13) -> 39272 | I13: =SUMIFS('[1]Operating Expenses (Clean)'!$F$2:$F$121,'[1]Operating Expenses (Clean)'!$I$2:$I$121,A13) -> 71178 | J13: =SUMIFS('[1]Operating Expenses (Clean)'!$G$2:$G$121,'[1]Operating Expenses (Clean)'!$I$2:$I$121,A13) -> 36550 | K13: =SUM(F13:J13) -> 503692 | L13: =D13-K13 -> 616662.36 | M13: =L13/B13 -> 0.24746134 | N13: =(B13-B12)/B12 -> 0.093141675 | O13: =((C13+K13)-(C12+K12))/(C12+K12) -> 0.079020942 | P13: =N13-O13 -> 0.014120733 | Q13: =(F13-F12)/F12 -> -0.04624766 | R13: =(J13-J12)/J12 -> 0.022663682 | S13: =E13-E12 -> -0.0086593785 | T13: =M13-M12 -> 0.0098481847
A14: 45292 | B14: ='[1]Revenue Trend Report'!B14 -> 2423695.9 | C14: =SUMIFS('[1]Sales Transactions (Clean)'!$J$2:$J$1081,'[1]Sales Transactions (Clean)'!$L$2:$L$1081,A14) -> 1558012.3 | D14: =B14-C14 -> 865683.54 | E14: =D14/B14 -> 0.35717499 | F14: =SUMIFS('[1]Operating Expenses (Clean)'!$C$2:$C$121,'[1]Operating Expenses (Clean)'!$I$2:$I$121,A14) -> 293819 | G14: =SUMIFS('[1]Operating Expenses (Clean)'!$D$2:$D$121,'[1]Operating Expenses (Clean)'!$I$2:$I$121,A14) -> 120469 | H14: =SUMIFS('[1]Operating Expenses (Clean)'!$E$2:$E$121,'[1]Operating Expenses (Clean)'!$I$2:$I$121,A14) -> 46537 | I14: =SUMIFS('[1]Operating Expenses (Clean)'!$F$2:$F$121,'[1]Operating Expenses (Clean)'!$I$2:$I$121,A14) -> 82411 | J14: =SUMIFS('[1]Operating Expenses (Clean)'!$G$2:$G$121,'[1]Operating Expenses (Clean)'!$I$2:$I$121,A14) -> 42392 | K14: =SUM(F14:J14) -> 585628 | L14: =D14-K14 -> 280055.54 | M14: =L14/B14 -> 0.11554896 | N14: =(B14-B13)/B13 -> -0.027391553 | O14: =((C14+K14)-(C13+K13))/(C13+K13) -> 0.14309682 | P14: =N14-O14 -> -0.17048837 | Q14: =(F14-F13)/F13 -> 0.23997805 | R14: =(J14-J13)/J13 -> 0.15983584 | S14: =E14-E13 -> -0.092413647 | T14: =M14-M13 -> -0.13191238
... A25: 45627 | B25: ='[1]Revenue Trend Report'!B25 -> 2455425 | C25: =SUMIFS('[1]Sales Transactions (Clean)'!$J$2:$J$1081,'[1]Sales Transactions (Clean)'!$L$2:$L$1081,A25) -> 1574840.9 | D25: =B25-C25 -> 880584.08 | E25: =D25/B25 -> 0.35862797 | F25: =SUMIFS('[1]Operating Expenses (Clean)'!$C$2:$C$121,'[1]Operating Expenses (Clean)'!$I$2:$I$121,A25) -> 275398 | G25: =SUMIFS('[1]Operating Expenses (Clean)'!$D$2:$D$121,'[1]Operating Expenses (Clean)'!$I$2:$I$121,A25) -> 118382 | H25: =SUMIFS('[1]Operating Expenses (Clean)'!$E$2:$E$121,'[1]Operating Expenses (Clean)'!$I$2:$I$121,A25) -> 45455 | I25: =SUMIFS('[1]Operating Expenses (Clean)'!$F$2:$F$121,'[1]Operating Expenses (Clean)'!$I$2:$I$121,A25) -> 86194 | J25: =SUMIFS('[1]Operating Expenses (Clean)'!$G$2:$G$121,'[1]Operating Expenses (Clean)'!$I$2:$I$121,A25) -> 40481 | K25: =SUM(F25:J25) -> 565910 | L25: =D25-K25 -> 314674.08 | M25: =L25/B25 -> 0.12815463 | N25: =(B25-B24)/B24 -> -0.032729704 | O25: =((C25+K25)-(C24+K24))/(C24+K24) -> -0.019774363 | P25: =N25-O25 -> -0.012955341 | Q25: =(F25-F24)/F24 -> 0.008455119 | R25: =(J25-J24)/J24 -> -0.011839086 | S25: =E25-E24 -> 0.0029020087 | T25: =M25-M24 -> -0.011522913

Sheet Variance Analysis
A1: Variance Report — Months where key metrics moved further from their 2-year average than usual
A2: Each of the 8 rate-of-change metrics below (columns B:I) is flagged when it sits more than 1.5 standard deviations away from that metric's own 23-month average (the first month has no prior period, so it is excluded from every growth calculation and from the average/stdev). A month is 'High Variance' overall when 3 or more of its 8 metrics are flagged at once — i.e. several things moved unusually far, together, in that month.
A4: Month | B4: Revenue Growth % (MoM) | C4: Total Cost Growth % (MoM) | D4: Growth Gap, pts | E4: Gross Margin % Pt Chg (MoM) | F4: Operating Margin % Pt Chg (MoM) | G4: Staff Cost Growth % (MoM) | H4: Logistics Cost Growth % (MoM) | I4: Units Growth % (MoM) | J4: # Metrics Flagged | K4: Overall Flag | M4: Gross Margin % (level, for reference) | N4: Operating Margin % (level, for reference)
A5: 44927 | B5: ='[1]Margin Compression Analysis'!N2 -> n/a | C5: ='[1]Margin Compression Analysis'!O2 -> n/a | D5: ='[1]Margin Compression Analysis'!P2 -> n/a | E5: ='[1]Margin Compression Analysis'!S2 -> n/a | F5: ='[1]Margin Compression Analysis'!T2 -> n/a | G5: ='[1]Margin Compression Analysis'!Q2 -> n/a | H5: ='[1]Margin Compression Analysis'!R2 -> n/a | I5: ='[1]Volume vs Price Diagnostic'!C2 -> n/a | J5: n/a | K5: Baseline month | M5: ='[1]Margin Compression Analysis'!E2 -> 0.45399457 | N5: ='[1]Margin Compression Analysis'!M2 -> 0.23617534
