Workbook

Sheet Student Headcount
A1: Vector University: Historical Student Headcount (Monthly Actuals)
A4: Month | B4: FY | C4: UK Undergraduate | D4: MOM Changes | E4: International Undergraduate | F4: MOM Changes | G4: UK Postgraduate | H4: MOM Changes | I4: International Postgraduate | J4: MOM Changes | K4: Postgraduate Research (PGR) | L4: MOM Changes | M4: Total Students
A5: 45139 | B5: FY23/24 | C5: 6000 | D5: =C6-C5 -> 3007 | E5: 1400 | F5: =E6-E5 -> 707 | G5: 184 | H5: =G6-G5 -> 6715 | I5: 192 | J5: =I6-I5 -> 6057 | K5: 748 | L5: =K6-K5 -> 251 | M5: =SUM(C5:K5) -> 25010
A6: 45170 | B6: FY23/24 | C6: 9007 | D6: =C7-C6 -> -44 | E6: 2107 | F6: =E7-E6 -> -24 | G6: 6899 | H6: =G7-G6 -> -1350 | I6: 6249 | J6: =I7-I6 -> -1205 | K6: 999 | L6: =K7-K6 -> 7 | M6: =SUM(C6:K6) -> 22638
A7: 45200 | B7: FY23/24 | C7: 8963 | D7: =C8-C7 -> -47 | E7: 2083 | F7: =E8-E7 -> 0 | G7: 5549 | H7: =G8-G7 -> -1114 | I7: 5044 | J7: =I8-I7 -> -1067 | K7: 1006 | L7: =K8-K7 -> -5 | M7: =SUM(C7:K7) -> 20417
A8: 45231 | B8: FY23/24 | C8: 8916 | D8: =C9-C8 -> 10 | E8: 2083 | F8: =E9-E8 -> -3 | G8: 4435 | H8: =G9-G8 -> -920 | I8: 3977 | J8: =I9-I8 -> -794 | K8: 1001 | L8: =K9-K8 -> -7 | M8: =SUM(C8:K8) -> 18705
A9: 45261 | B9: FY23/24 | C9: 8926 | D9: =C10-C9 -> -42 | E9: 2080 | F9: =E10-E9 -> -7 | G9: 3515 | H9: =G10-G9 -> -220 | I9: 3183 | J9: =I10-I9 -> -270 | K9: 994 | L9: =K10-K9 -> 69 | M9: =SUM(C9:K9) -> 18159
A10: 45292 | B10: FY23/24 | C10: 8884 | D10: =C11-C10 -> 43 | E10: 2073 | F10: =E11-E10 -> -21 | G10: 3295 | H10: =G11-G10 -> -657 | I10: 2913 | J10: =I11-I10 -> -607 | K10: 1063 | L10: =K11-K10 -> 0 | M10: =SUM(C10:K10) -> 16986
A11: 45323 | B11: FY23/24 | C11: 8927 | D11: =C12-C11 -> 55 | E11: 2052 | F11: =E12-E11 -> 10 | G11: 2638 | H11: =G12-G11 -> -542 | I11: 2306 | J11: =I12-I11 -> -468 | K11: 1063 | L11: =K12-K11 -> 10 | M11: =SUM(C11:K11) -> 16041
A12: 45352 | B12: FY23/24 | C12: 8982 | D12: =C13-C12 -> -111 | E12: 2062 | F12: =E13-E12 -> 10 | G12: 2096 | H12: =G13-G12 -> -406 | I12: 1838 | J12: =I13-I12 -> -379 | K12: 1073 | L12: =K13-K12 -> -14 | M12: =SUM(C12:K12) -> 15165
A13: 45383 | B13: FY23/24 | C13: 8871 | D13: =C14-C13 -> -20 | E13: 2072 | F13: =E14-E13 -> -41 | G13: 1690 | H13: =G14-G13 -> -347 | I13: 1459 | J13: =I14-I13 -> -295 | K13: 1059 | L13: =K14-K13 -> 0 | M13: =SUM(C13:K13) -> 14448
A14: 45413 | B14: FY23/24 | C14: 8851 | D14: =C15-C14 -> 45 | E14: 2031 | F14: =E15-E14 -> 23 | G14: 1343 | H14: =G15-G14 -> -257 | I14: 1164 | J14: =I15-I14 -> -241 | K14: 1059 | L14: =K15-K14 -> 3 | M14: =SUM(C14:K14) -> 14018
A15: 45444 | B15: FY23/24 | C15: 8896 | D15: =C16-C15 -> -2793 | E15: 2054 | F15: =E16-E15 -> -639 | G15: 1086 | H15: =G16-G15 -> -221 | I15: 923 | J15: =I16-I15 -> -189 | K15: 1062 | L15: =K16-K15 -> -244 | M15: =SUM(C15:K15) -> 10179
A16: 45474 | B16: FY23/24 | C16: 6103 | D16: =C17-C16 -> -18 | E16: 1415 | F16: =E17-E16 -> -10 | G16: 865 | H16: =G17-G16 -> -173 | I16: 734 | J16: =I17-I16 -> -154 | K16: 818 | L16: =K17-K16 -> -1 | M16: =SUM(C16:K16) -> 9580
... A40: 46204 | B40: FY25/26 | C40: 6242 | D40: =C41-C40 -> 2308.1389 | E40: 1392 | F40: =E41-E40 -> 583.08333 | G40: 943 | H40: =G41-G40 -> 2045.8056 | I40: 689 | J40: =I41-I40 -> 1860.2778 | K40: 934 | L40: =K41-K40 -> 132.08333 | M40: =SUM(C40:K40) -> 16997.306
B41: Average | C41: =AVERAGE(C5:C40) -> 8550.1389 | E41: =AVERAGE(E5:E40) -> 1975.0833 | G41: =AVERAGE(G5:G40) -> 2988.8056 | I41: =AVERAGE(I5:I40) -> 2549.2778 | K41: =AVERAGE(K5:K40) -> 1066.0833 | M41: =AVERAGE(M5:M40) -> 17359.592

Sheet Student Flow Summary
A1: Vector University — Annual Student Flow Summary
A4: Category | B4: FY | C4: Opening Population | D4: New Enrolments | E4: Withdrawals | F4: Graduates / Completions | G4: Closing Population | H4: Retention Rate %
A5: UK Undergraduate | B5: FY23/24 | C5: 6000 | D5: 3000 | E5: 143 | F5: 2767 | G5: =C5+D5-E5-F5 -> 6090 | H5: =1-E5/(C5+D5) -> 0.98411111
A6: UK Undergraduate | B6: FY24/25 | C6: 6090 | D6: 3050 | E6: 154 | F6: 2807 | G6: =C6+D6-E6-F6 -> 6179 | H6: =1-E6/(C6+D6) -> 0.98315098
A7: UK Undergraduate | B7: FY25/26 | C7: 6179 | D7: 3100 | E7: 156 | F7: 2850 | G7: =C7+D7-E7-F7 -> 6273 | H7: =1-E7/(C7+D7) -> 0.98318784
A8: International Undergraduate | B8: FY23/24 | C8: 1400 | D8: 700 | E8: 62 | F8: 624 | G8: =C8+D8-E8-F8 -> 1414 | H8: =1-E8/(C8+D8) -> 0.97047619
A9: International Undergraduate | B9: FY24/25 | C9: 1414 | D9: 745 | E9: 67 | F9: 641 | G9: =C9+D9-E9-F9 -> 1451 | H9: =1-E9/(C9+D9) -> 0.96896711
A10: International Undergraduate | B10: FY25/26 | C10: 1451 | D10: 645 | E10: 66 | F10: 622 | G10: =C10+D10-E10-F10 -> 1408 | H10: =1-E10/(C10+D10) -> 0.96851145
A11: UK Postgraduate | B11: FY23/24 | C11: 184 | D11: 7227 | E11: 524 | F11: 6023 | G11: =C11+D11-E11-F11 -> 864 | H11: =1-E11/(C11+D11) -> 0.92929429
A12: UK Postgraduate | B12: FY24/25 | C12: 864 | D12: 7374 | E12: 585 | F12: 6728 | G12: =C12+D12-E12-F12 -> 925 | H12: =1-E12/(C12+D12) -> 0.92898762
A13: UK Postgraduate | B13: FY25/26 | C13: 925 | D13: 7522 | E13: 600 | F13: 6900 | G13: =C13+D13-E13-F13 -> 947 | H13: =1-E13/(C13+D13) -> 0.92896886
A14: International Postgraduate | B14: FY23/24 | C14: 193 | D14: 6542 | E14: 480 | F14: 5519 | G14: =C14+D14-E14-F14 -> 736 | H14: =1-E14/(C14+D14) -> 0.92873051
A15: International Postgraduate | B15: FY24/25 | C15: 735 | D15: 6861 | E15: 544 | F15: 6252 | G15: =C15+D15-E15-F15 -> 800 | H15: =1-E15/(C15+D15) -> 0.92838336
A16: International Postgraduate | B16: FY25/26 | C16: 801 | D16: 5783 | E16: 472 | F16: 5423 | G16: =C16+D16-E16-F16 -> 689 | H16: =1-E16/(C16+D16) -> 0.92831106
... A19: Postgraduate Research (PGR) | B19: FY25/26 | C19: 878 | D19: 339 | E19: 14 | F19: 273 | G19: =C19+D19-E19-F19 -> 930 | H19: =1-E19/(C19+D19) -> 0.9884963

Sheet Tuition Fee Rates
A1: Vector University — Tuition Fee Rates
A3: Approved annual tuition fee per student (£), by category and financial year.
A5: Student Category | B5: FY23/24 | C5: FY24/25 | D5: FY25/26
A6: UK Undergraduate | B6: 9250 | C6: 9250 | D6: 9535
A7: International Undergraduate | B7: 19000 | C7: 19950 | D7: 20950
A8: UK Postgraduate | B8: 9750 | C8: 10050 | D8: 10350
A9: International Postgraduate | B9: 19500 | C9: 20500 | D9: 21500
A10: Postgraduate Research (PGR) | B10: 6500 | C10: 6700 | D10: 6950

Sheet Income
A1: Vector University — Income (Monthly Actuals)
A4: Month | B4: FY | C4: UK Undergraduate Tuition | D4: International Undergraduate Tuition | E4: UK Postgraduate Tuition | F4: International Postgraduate Tuition | G4: Postgraduate Research (PGR) Tuition | H4: Research Grants & Contracts | I4: Government & Funding Body Grants | J4: Student Accommodation Income | K4: Commercial & Professional Services | L4: Other Operating Income | M4: Total Income
A5: 45139 | B5: FY23/24 | C5: ='Student Headcount'!C5*'Tuition Fee Rates'!B6/12 -> 4625000 | D5: ='Student Headcount'!E5*'Tuition Fee Rates'!B7/12 -> 2216666.7 | E5: ='Student Headcount'!G5*'Tuition Fee Rates'!B8/12 -> 149500 | F5: ='Student Headcount'!I5*'Tuition Fee Rates'!B9/12 -> 312000 | G5: ='Student Headcount'!K5*'Tuition Fee Rates'!B10/12 -> 405166.67 | H5: 2400000 | I5: 3653846 | J5: 1200000 | K5: 675000 | L5: 500000 | M5: =SUM(C5:L5) -> 16137179
A6: 45170 | B6: FY23/24 | C6: ='Student Headcount'!C6*'Tuition Fee Rates'!B6/12 -> 6942895.8 | D6: ='Student Headcount'!E6*'Tuition Fee Rates'!B7/12 -> 3336083.3 | E6: ='Student Headcount'!G6*'Tuition Fee Rates'!B8/12 -> 5605437.5 | F6: ='Student Headcount'!I6*'Tuition Fee Rates'!B9/12 -> 10154625 | G6: ='Student Headcount'!K6*'Tuition Fee Rates'!B10/12 -> 541125 | H6: 2533333 | I6: 548077 | J6: 2600000 | K6: 825000 | L6: 500000 | M6: =SUM(C6:L6) -> 33586577
A7: 45200 | B7: FY23/24 | C7: ='Student Headcount'!C7*'Tuition Fee Rates'!B6/12 -> 6908979.2 | D7: ='Student Headcount'!E7*'Tuition Fee Rates'!B7/12 -> 3298083.3 | E7: ='Student Headcount'!G7*'Tuition Fee Rates'!B8/12 -> 4508562.5 | F7: ='Student Headcount'!I7*'Tuition Fee Rates'!B9/12 -> 8196500 | G7: ='Student Headcount'!K7*'Tuition Fee Rates'!B10/12 -> 544916.67 | H7: 2666667 | I7: 548077 | J7: 2600000 | K7: 825000 | L7: 500000 | M7: =SUM(C7:L7) -> 30596786
A8: 45231 | B8: FY23/24 | C8: ='Student Headcount'!C8*'Tuition Fee Rates'!B6/12 -> 6872750 | D8: ='Student Headcount'!E8*'Tuition Fee Rates'!B7/12 -> 3298083.3 | E8: ='Student Headcount'!G8*'Tuition Fee Rates'!B8/12 -> 3603437.5 | F8: ='Student Headcount'!I8*'Tuition Fee Rates'!B9/12 -> 6462625 | G8: ='Student Headcount'!K8*'Tuition Fee Rates'!B10/12 -> 542208.33 | H8: 2666667 | I8: 3653846 | J8: 2500000 | K8: 750000 | L8: 500000 | M8: =SUM(C8:L8) -> 30849617
A9: 45261 | B9: FY23/24 | C9: ='Student Headcount'!C9*'Tuition Fee Rates'!B6/12 -> 6880458.3 | D9: ='Student Headcount'!E9*'Tuition Fee Rates'!B7/12 -> 3293333.3 | E9: ='Student Headcount'!G9*'Tuition Fee Rates'!B8/12 -> 2855937.5 | F9: ='Student Headcount'!I9*'Tuition Fee Rates'!B9/12 -> 5172375 | G9: ='Student Headcount'!K9*'Tuition Fee Rates'!B10/12 -> 538416.67 | H9: 2800000 | I9: 548077 | J9: 2300000 | K9: 675000 | L9: 500000 | M9: =SUM(C9:L9) -> 25563598
A10: 45292 | B10: FY23/24 | C10: ='Student Headcount'!C10*'Tuition Fee Rates'!B6/12 -> 6848083.3 | D10: ='Student Headcount'!E10*'Tuition Fee Rates'!B7/12 -> 3282250 | E10: ='Student Headcount'!G10*'Tuition Fee Rates'!B8/12 -> 2677187.5 | F10: ='Student Headcount'!I10*'Tuition Fee Rates'!B9/12 -> 4733625 | G10: ='Student Headcount'!K10*'Tuition Fee Rates'!B10/12 -> 575791.67 | H10: 2800000 | I10: 548077 | J10: 2200000 | K10: 750000 | L10: 500000 | M10: =SUM(C10:L10) -> 24915014
A11: 45323 | B11: FY23/24 | C11: ='Student Headcount'!C11*'Tuition Fee Rates'!B6/12 -> 6881229.2 | D11: ='Student Headcount'!E11*'Tuition Fee Rates'!B7/12 -> 3249000 | E11: ='Student Headcount'!G11*'Tuition Fee Rates'!B8/12 -> 2143375 | F11: ='Student Headcount'!I11*'Tuition Fee Rates'!B9/12 -> 3747250 | G11: ='Student Headcount'!K11*'Tuition Fee Rates'!B10/12 -> 575791.67 | H11: 2800000 | I11: 3653846 | J11: 2200000 | K11: 825000 | L11: 500000 | M11: =SUM(C11:L11) -> 26575492
A12: 45352 | B12: FY23/24 | C12: ='Student Headcount'!C12*'Tuition Fee Rates'!B6/12 -> 6923625 | D12: ='Student Headcount'!E12*'Tuition Fee Rates'!B7/12 -> 3264833.3 | E12: ='Student Headcount'!G12*'Tuition Fee Rates'!B8/12 -> 1703000 | F12: ='Student Headcount'!I12*'Tuition Fee Rates'!B9/12 -> 2986750 | G12: ='Student Headcount'!K12*'Tuition Fee Rates'!B10/12 -> 581208.33 | H12: 2666667 | I12: 548077 | J12: 2200000 | K12: 825000 | L12: 500000 | M12: =SUM(C12:L12) -> 22199161
A13: 45383 | B13: FY23/24 | C13: ='Student Headcount'!C13*'Tuition Fee Rates'!B6/12 -> 6838062.5 | D13: ='Student Headcount'!E13*'Tuition Fee Rates'!B7/12 -> 3280666.7 | E13: ='Student Headcount'!G13*'Tuition Fee Rates'!B8/12 -> 1373125 | F13: ='Student Headcount'!I13*'Tuition Fee Rates'!B9/12 -> 2370875 | G13: ='Student Headcount'!K13*'Tuition Fee Rates'!B10/12 -> 573625 | H13: 2666667 | I13: 548077 | J13: 2200000 | K13: 750000 | L13: 500000 | M13: =SUM(C13:L13) -> 21101098
A14: 45413 | B14: FY23/24 | C14: ='Student Headcount'!C14*'Tuition Fee Rates'!B6/12 -> 6822645.8 | D14: ='Student Headcount'!E14*'Tuition Fee Rates'!B7/12 -> 3215750 | E14: ='Student Headcount'!G14*'Tuition Fee Rates'!B8/12 -> 1091187.5 | F14: ='Student Headcount'!I14*'Tuition Fee Rates'!B9/12 -> 1891500 | G14: ='Student Headcount'!K14*'Tuition Fee Rates'!B10/12 -> 573625 | H14: 2533333 | I14: 3653846 | J14: 2000000 | K14: 675000 | L14: 500000 | M14: =SUM(C14:L14) -> 22956887
A15: 45444 | B15: FY23/24 | C15: ='Student Headcount'!C15*'Tuition Fee Rates'!B6/12 -> 6857333.3 | D15: ='Student Headcount'!E15*'Tuition Fee Rates'!B7/12 -> 3252166.7 | E15: ='Student Headcount'!G15*'Tuition Fee Rates'!B8/12 -> 882375 | F15: ='Student Headcount'!I15*'Tuition Fee Rates'!B9/12 -> 1499875 | G15: ='Student Headcount'!K15*'Tuition Fee Rates'!B10/12 -> 575250 | H15: 2533333 | I15: 548077 | J15: 1000000 | K15: 675000 | L15: 500000 | M15: =SUM(C15:L15) -> 18323410
A16: 45474 | B16: FY23/24 | C16: ='Student Headcount'!C16*'Tuition Fee Rates'!B6/12 -> 4704395.8 | D16: ='Student Headcount'!E16*'Tuition Fee Rates'!B7/12 -> 2240416.7 | E16: ='Student Headcount'!G16*'Tuition Fee Rates'!B8/12 -> 702812.5 | F16: ='Student Headcount'!I16*'Tuition Fee Rates'!B9/12 -> 1192750 | G16: ='Student Headcount'!K16*'Tuition Fee Rates'!B10/12 -> 443083.33 | H16: 2933333 | I16: 548077 | J16: 1000000 | K16: 750000 | L16: 500000 | M16: =SUM(C16:L16) -> 15014868
A17: 45505 | B17: FY24/25 | C17: ='Student Headcount'!C17*'Tuition Fee Rates'!C6/12 -> 4690520.8 | D17: ='Student Headcount'!E17*'Tuition Fee Rates'!C7/12 -> 2335812.5 | E17: ='Student Headcount'!G17*'Tuition Fee Rates'!C8/12 -> 579550 | F17: ='Student Headcount'!I17*'Tuition Fee Rates'!C9/12 -> 990833.33 | G17: ='Student Headcount'!K17*'Tuition Fee Rates'!C10/12 -> 456158.33 | H17: 2512500 | I17: 3692308 | J17: 1255000 | K17: 712500 | L17: 516667 | M17: =SUM(C17:L17) -> 17741850
A18: 45536 | B18: FY24/25 | C18: ='Student Headcount'!C18*'Tuition Fee Rates'!C6/12 -> 6992229.2 | D18: ='Student Headcount'!E18*'Tuition Fee Rates'!C7/12 -> 3619262.5 | E18: ='Student Headcount'!G18*'Tuition Fee Rates'!C8/12 -> 6215925 | F18: ='Student Headcount'!I18*'Tuition Fee Rates'!C9/12 -> 11758458 | G18: ='Student Headcount'!K18*'Tuition Fee Rates'!C10/12 -> 596300 | H18: 2652083 | I18: 553846 | J18: 2719167 | K18: 870833 | L18: 516667 | M18: =SUM(C18:L18) -> 36494771
A19: 45566 | B19: FY24/25 | C19: ='Student Headcount'!C19*'Tuition Fee Rates'!C6/12 -> 7019208.3 | D19: ='Student Headcount'!E19*'Tuition Fee Rates'!C7/12 -> 3582687.5 | E19: ='Student Headcount'!G19*'Tuition Fee Rates'!C8/12 -> 4986475 | F19: ='Student Headcount'!I19*'Tuition Fee Rates'!C9/12 -> 9486375 | G19: ='Student Headcount'!K19*'Tuition Fee Rates'!C10/12 -> 599650 | H19: 2791667 | I19: 553846 | J19: 2719167 | K19: 870833 | L19: 516667 | M19: =SUM(C19:L19) -> 33126576
A20: 45597 | B20: FY24/25 | C20: ='Student Headcount'!C20*'Tuition Fee Rates'!C6/12 -> 7039250 | D20: ='Student Headcount'!E20*'Tuition Fee Rates'!C7/12 -> 3531150 | E20: ='Student Headcount'!G20*'Tuition Fee Rates'!C8/12 -> 3944625 | F20: ='Student Headcount'!I20*'Tuition Fee Rates'!C9/12 -> 7438083.3 | G20: ='Student Headcount'!K20*'Tuition Fee Rates'!C10/12 -> 597416.67 | H20: 2791667 | I20: 3692308 | J20: 2614583 | K20: 791667 | L20: 516667 | M20: =SUM(C20:L20) -> 32957417
A21: 45627 | B21: FY24/25 | C21: ='Student Headcount'!C21*'Tuition Fee Rates'!C6/12 -> 6943666.7 | D21: ='Student Headcount'!E21*'Tuition Fee Rates'!C7/12 -> 3547775 | E21: ='Student Headcount'!G21*'Tuition Fee Rates'!C8/12 -> 3172450 | F21: ='Student Headcount'!I21*'Tuition Fee Rates'!C9/12 -> 5898875 | G21: ='Student Headcount'!K21*'Tuition Fee Rates'!C10/12 -> 602441.67 | H21: 2931250 | I21: 553846 | J21: 2405417 | K21: 712500 | L21: 516667 | M21: =SUM(C21:L21) -> 27284888
A22: 45658 | B22: FY24/25 | C22: ='Student Headcount'!C22*'Tuition Fee Rates'!C6/12 -> 6969875 | D22: ='Student Headcount'!E22*'Tuition Fee Rates'!C7/12 -> 3547775 | E22: ='Student Headcount'!G22*'Tuition Fee Rates'!C8/12 -> 2963075 | F22: ='Student Headcount'!I22*'Tuition Fee Rates'!C9/12 -> 5430791.7 | G22: ='Student Headcount'!K22*'Tuition Fee Rates'!C10/12 -> 640408.33 | H22: 2931250 | I22: 553846 | J22: 2300833 | K22: 791667 | L22: 516667 | M22: =SUM(C22:L22) -> 26646188
A23: 45689 | B23: FY24/25 | C23: ='Student Headcount'!C23*'Tuition Fee Rates'!C6/12 -> 6898958.3 | D23: ='Student Headcount'!E23*'Tuition Fee Rates'!C7/12 -> 3522837.5 | E23: ='Student Headcount'!G23*'Tuition Fee Rates'!C8/12 -> 2334950 | F23: ='Student Headcount'!I23*'Tuition Fee Rates'!C9/12 -> 4344291.7 | G23: ='Student Headcount'!K23*'Tuition Fee Rates'!C10/12 -> 637616.67 | H23: 2931250 | I23: 3692308 | J23: 2300833 | K23: 870833 | L23: 516667 | M23: =SUM(C23:L23) -> 28050545
A24: 45717 | B24: FY24/25 | C24: ='Student Headcount'!C24*'Tuition Fee Rates'!C6/12 -> 6914375 | D24: ='Student Headcount'!E24*'Tuition Fee Rates'!C7/12 -> 3531150 | E24: ='Student Headcount'!G24*'Tuition Fee Rates'!C8/12 -> 1901962.5 | F24: ='Student Headcount'!I24*'Tuition Fee Rates'!C9/12 -> 3396166.7 | G24: ='Student Headcount'!K24*'Tuition Fee Rates'!C10/12 -> 639291.67 | H24: 2791667 | I24: 553846 | J24: 2300833 | K24: 870833 | L24: 516667 | M24: =SUM(C24:L24) -> 23416792
A25: 45748 | B25: FY24/25 | C25: ='Student Headcount'!C25*'Tuition Fee Rates'!C6/12 -> 6881229.2 | D25: ='Student Headcount'!E25*'Tuition Fee Rates'!C7/12 -> 3504550 | E25: ='Student Headcount'!G25*'Tuition Fee Rates'!C8/12 -> 1497450 | F25: ='Student Headcount'!I25*'Tuition Fee Rates'!C9/12 -> 2719666.7 | G25: ='Student Headcount'!K25*'Tuition Fee Rates'!C10/12 -> 634825 | H25: 2791667 | I25: 553846 | J25: 2300833 | K25: 791667 | L25: 516667 | M25: =SUM(C25:L25) -> 22192401
A26: 45778 | B26: FY24/25 | C26: ='Student Headcount'!C26*'Tuition Fee Rates'!C6/12 -> 6937500 | D26: ='Student Headcount'!E26*'Tuition Fee Rates'!C7/12 -> 3511200 | E26: ='Student Headcount'!G26*'Tuition Fee Rates'!C8/12 -> 1216050 | F26: ='Student Headcount'!I26*'Tuition Fee Rates'!C9/12 -> 2155916.7 | G26: ='Student Headcount'!K26*'Tuition Fee Rates'!C10/12 -> 639291.67 | H26: 2652083 | I26: 3692308 | J26: 2091667 | K26: 712500 | L26: 516667 | M26: =SUM(C26:L26) -> 24125183
A27: 45809 | B27: FY24/25 | C27: ='Student Headcount'!C27*'Tuition Fee Rates'!C6/12 -> 6884312.5 | D27: ='Student Headcount'!E27*'Tuition Fee Rates'!C7/12 -> 3517850 | E27: ='Student Headcount'!G27*'Tuition Fee Rates'!C8/12 -> 963962.5 | F27: ='Student Headcount'!I27*'Tuition Fee Rates'!C9/12 -> 1703208.3 | G27: ='Student Headcount'!K27*'Tuition Fee Rates'!C10/12 -> 634825 | H27: 2652083 | I27: 553846 | J27: 1045833 | K27: 712500 | L27: 516667 | M27: =SUM(C27:L27) -> 19185087
A28: 45839 | B28: FY24/25 | C28: ='Student Headcount'!C28*'Tuition Fee Rates'!C6/12 -> 4770687.5 | D28: ='Student Headcount'!E28*'Tuition Fee Rates'!C7/12 -> 2402312.5 | E28: ='Student Headcount'!G28*'Tuition Fee Rates'!C8/12 -> 778875 | F28: ='Student Headcount'!I28*'Tuition Fee Rates'!C9/12 -> 1373500 | G28: ='Student Headcount'!K28*'Tuition Fee Rates'!C10/12 -> 492450 | H28: 3070833 | I28: 553846 | J28: 1045833 | K28: 791667 | L28: 516667 | M28: =SUM(C28:L28) -> 15796671
A29: 45870 | B29: FY25/26 | C29: ='Student Headcount'!C29*'Tuition Fee Rates'!D6/12 -> 4906552.1 | D29: ='Student Headcount'!E29*'Tuition Fee Rates'!D7/12 -> 2529712.5 | E29: ='Student Headcount'!G29*'Tuition Fee Rates'!D8/12 -> 639112.5 | F29: ='Student Headcount'!I29*'Tuition Fee Rates'!D9/12 -> 1141291.7 | G29: ='Student Headcount'!K29*'Tuition Fee Rates'!D10/12 -> 504454.17 | H29: 2610000 | I29: 3653846 | J29: 1310000 | K29: 750000 | L29: 541667 | M29: =SUM(C29:L29) -> 18586636
A30: 45901 | B30: FY25/26 | C30: ='Student Headcount'!C30*'Tuition Fee Rates'!D6/12 -> 7349895.8 | D30: ='Student Headcount'!E30*'Tuition Fee Rates'!D7/12 -> 3634825 | E30: ='Student Headcount'!G30*'Tuition Fee Rates'!D8/12 -> 6513600 | F30: ='Student Headcount'!I30*'Tuition Fee Rates'!D9/12 -> 10624583 | G30: ='Student Headcount'!K30*'Tuition Fee Rates'!D10/12 -> 662566.67 | H30: 2755000 | I30: 548077 | J30: 2838333 | K30: 916667 | L30: 541667 | M30: =SUM(C30:L30) -> 36385215
A31: 45931 | B31: FY25/26 | C31: ='Student Headcount'!C31*'Tuition Fee Rates'!D6/12 -> 7236270.4 | D31: ='Student Headcount'!E31*'Tuition Fee Rates'!D7/12 -> 3638316.7 | E31: ='Student Headcount'!G31*'Tuition Fee Rates'!D8/12 -> 5299200 | F31: ='Student Headcount'!I31*'Tuition Fee Rates'!D9/12 -> 8404708.3 | G31: ='Student Headcount'!K31*'Tuition Fee Rates'!D10/12 -> 653879.17 | H31: 2900000 | I31: 548077 | J31: 2838333 | K31: 916667 | L31: 541667 | M31: =SUM(C31:L31) -> 32977119
A32: 45962 | B32: FY25/26 | C32: ='Student Headcount'!C32*'Tuition Fee Rates'!D6/12 -> 7311755.8 | D32: ='Student Headcount'!E32*'Tuition Fee Rates'!D7/12 -> 3599908.3 | E32: ='Student Headcount'!G32*'Tuition Fee Rates'!D8/12 -> 4244362.5 | F32: ='Student Headcount'!I32*'Tuition Fee Rates'!D9/12 -> 6731291.7 | G32: ='Student Headcount'!K32*'Tuition Fee Rates'!D10/12 -> 652141.67 | H32: 2900000 | I32: 3653846 | J32: 2729167 | K32: 833333 | L32: 541667 | M32: =SUM(C32:L32) -> 33197473
A33: 45992 | B33: FY25/26 | C33: ='Student Headcount'!C33*'Tuition Fee Rates'!D6/12 -> 7322880 | D33: ='Student Headcount'!E33*'Tuition Fee Rates'!D7/12 -> 3601654.2 | E33: ='Student Headcount'!G33*'Tuition Fee Rates'!D8/12 -> 3364612.5 | F33: ='Student Headcount'!I33*'Tuition Fee Rates'!D9/12 -> 5319458.3 | G33: ='Student Headcount'!K33*'Tuition Fee Rates'!D10/12 -> 657933.33 | H33: 3045000 | I33: 548077 | J33: 2510833 | K33: 750000 | L33: 541667 | M33: =SUM(C33:L33) -> 27662115
A34: 46023 | B34: FY25/26 | C34: ='Student Headcount'!C34*'Tuition Fee Rates'!D6/12 -> 7318907.1 | D34: ='Student Headcount'!E34*'Tuition Fee Rates'!D7/12 -> 3599908.3 | E34: ='Student Headcount'!G34*'Tuition Fee Rates'!D8/12 -> 3111900 | F34: ='Student Headcount'!I34*'Tuition Fee Rates'!D9/12 -> 4885875 | G34: ='Student Headcount'!K34*'Tuition Fee Rates'!D10/12 -> 697895.83 | H34: 3045000 | I34: 548077 | J34: 2401667 | K34: 833333 | L34: 541667 | M34: =SUM(C34:L34) -> 26984230
A35: 46054 | B35: FY25/26 | C35: ='Student Headcount'!C35*'Tuition Fee Rates'!D6/12 -> 7235475.8 | D35: ='Student Headcount'!E35*'Tuition Fee Rates'!D7/12 -> 3613875 | E35: ='Student Headcount'!G35*'Tuition Fee Rates'!D8/12 -> 2490900 | F35: ='Student Headcount'!I35*'Tuition Fee Rates'!D9/12 -> 3861041.7 | G35: ='Student Headcount'!K35*'Tuition Fee Rates'!D10/12 -> 701370.83 | H35: 3045000 | I35: 3653846 | J35: 2401667 | K35: 916667 | L35: 541667 | M35: =SUM(C35:L35) -> 28461510
A36: 46082 | B36: FY25/26 | C36: ='Student Headcount'!C36*'Tuition Fee Rates'!D6/12 -> 7271232.1 | D36: ='Student Headcount'!E36*'Tuition Fee Rates'!D7/12 -> 3608637.5 | E36: ='Student Headcount'!G36*'Tuition Fee Rates'!D8/12 -> 1982887.5 | F36: ='Student Headcount'!I36*'Tuition Fee Rates'!D9/12 -> 3067333.3 | G36: ='Student Headcount'!K36*'Tuition Fee Rates'!D10/12 -> 709479.17 | H36: 2900000 | I36: 548077 | J36: 2401667 | K36: 916667 | L36: 541667 | M36: =SUM(C36:L36) -> 23947648
A37: 46113 | B37: FY25/26 | C37: ='Student Headcount'!C37*'Tuition Fee Rates'!D6/12 -> 7237859.6 | D37: ='Student Headcount'!E37*'Tuition Fee Rates'!D7/12 -> 3545787.5 | E37: ='Student Headcount'!G37*'Tuition Fee Rates'!D8/12 -> 1605975 | F37: ='Student Headcount'!I37*'Tuition Fee Rates'!D9/12 -> 2476083.3 | G37: ='Student Headcount'!K37*'Tuition Fee Rates'!D10/12 -> 695579.17 | H37: 2900000 | I37: 548077 | J37: 2401667 | K37: 833333 | L37: 541667 | M37: =SUM(C37:L37) -> 22786029
A38: 46143 | B38: FY25/26 | C38: ='Student Headcount'!C38*'Tuition Fee Rates'!D6/12 -> 7234681.2 | D38: ='Student Headcount'!E38*'Tuition Fee Rates'!D7/12 -> 3547533.3 | E38: ='Student Headcount'!G38*'Tuition Fee Rates'!D8/12 -> 1272187.5 | F38: ='Student Headcount'!I38*'Tuition Fee Rates'!D9/12 -> 1947541.7 | G38: ='Student Headcount'!K38*'Tuition Fee Rates'!D10/12 -> 696158.33 | H38: 2755000 | I38: 3653846 | J38: 2183333 | K38: 750000 | L38: 541667 | M38: =SUM(C38:L38) -> 24581948
A39: 46174 | B39: FY25/26 | C39: ='Student Headcount'!C39*'Tuition Fee Rates'!D6/12 -> 7305399.2 | D39: ='Student Headcount'!E39*'Tuition Fee Rates'!D7/12 -> 3568483.3 | E39: ='Student Headcount'!G39*'Tuition Fee Rates'!D8/12 -> 1021200 | F39: ='Student Headcount'!I39*'Tuition Fee Rates'!D9/12 -> 1555166.7 | G39: ='Student Headcount'!K39*'Tuition Fee Rates'!D10/12 -> 699054.17 | H39: 2755000 | I39: 548077 | J39: 1091667 | K39: 750000 | L39: 541667 | M39: =SUM(C39:L39) -> 19835714
A40: 46204 | B40: FY25/26 | C40: ='Student Headcount'!C40*'Tuition Fee Rates'!D6/12 -> 4959789.2 | D40: ='Student Headcount'!E40*'Tuition Fee Rates'!D7/12 -> 2430200 | E40: ='Student Headcount'!G40*'Tuition Fee Rates'!D8/12 -> 813337.5 | F40: ='Student Headcount'!I40*'Tuition Fee Rates'!D9/12 -> 1234458.3 | G40: ='Student Headcount'!K40*'Tuition Fee Rates'!D10/12 -> 540941.67 | H40: 3190000 | I40: 548077 | J40: 1091667 | K40: 833333 | L40: 541667 | M40: =SUM(C40:L40) -> 16183471
B42: FY Total (all 3 years) | C42: =SUM(C5:C40) -> 2.3973797e+08 | D42: =SUM(D5:D40) -> 1.1830054e+08 | E42: =SUM(E5:E40) -> 90210562 | F42: =SUM(F5:F40) -> 156665750 | G42: =SUM(G5:G40) -> 21512338 | H42: =SUM(H5:H40) -> 100300000 | I42: =SUM(I5:I40) -> 57200000 | J42: =SUM(J5:J40) -> 75300000 | ... M42: =SUM(M5:M40) -> 9.0642716e+08
A46: NOTE
...

Sheet Staff Costs
A1: Vector University — Staff Costs & Workforce (Monthly Actuals)
A4: Month | B4: FY | C4: Academic Staff Costs | D4: Professional Services Staff Costs | E4: Total Staff Costs | F4: Academic FTE | G4: Professional Services FTE
A5: 45139 | B5: FY23/24 | C5: 9833333 | D5: 5166667 | E5: =SUM(C5:D5) -> 15000000 | F5: 1150 | G5: 980
A6: 45170 | B6: FY23/24 | C6: 9833333 | D6: 5166667 | E6: =SUM(C6:D6) -> 15000000 | F6: 1150 | G6: 980
A7: 45200 | B7: FY23/24 | C7: 9833333 | D7: 5166667 | E7: =SUM(C7:D7) -> 15000000 | F7: 1150 | G7: 980
A8: 45231 | B8: FY23/24 | C8: 9833333 | D8: 5166667 | E8: =SUM(C8:D8) -> 15000000 | F8: 1150 | G8: 980
A9: 45261 | B9: FY23/24 | C9: 9833333 | D9: 5166667 | E9: =SUM(C9:D9) -> 15000000 | F9: 1150 | G9: 980
A10: 45292 | B10: FY23/24 | C10: 9833333 | D10: 5166667 | E10: =SUM(C10:D10) -> 15000000 | F10: 1150 | G10: 980
A11: 45323 | B11: FY23/24 | C11: 9833333 | D11: 5166667 | E11: =SUM(C11:D11) -> 15000000 | F11: 1150 | G11: 980
A12: 45352 | B12: FY23/24 | C12: 9833333 | D12: 5166667 | E12: =SUM(C12:D12) -> 15000000 | F12: 1150 | G12: 980
A13: 45383 | B13: FY23/24 | C13: 9833333 | D13: 5166667 | E13: =SUM(C13:D13) -> 15000000 | F13: 1150 | G13: 980
A14: 45413 | B14: FY23/24 | C14: 9833333 | D14: 5166667 | E14: =SUM(C14:D14) -> 15000000 | F14: 1150 | G14: 980
A15: 45444 | B15: FY23/24 | C15: 9833333 | D15: 5166667 | E15: =SUM(C15:D15) -> 15000000 | F15: 1150 | G15: 980
A16: 45474 | B16: FY23/24 | C16: 9833333 | D16: 5166667 | E16: =SUM(C16:D16) -> 15000000 | F16: 1150 | G16: 980
... A40: 46204 | B40: FY25/26 | C40: 10875000 | D40: 5683333 | E40: =SUM(C40:D40) -> 16558333 | F40: 1230 | G40: 1040

Sheet Operating Expenditure
A1: Vector University — Operating Expenditure (Monthly Actuals)
A4: Month | B4: FY | C4: Utilities | D4: Utilities MOM% | E4: IT & Digital Services | F4: IT MOM% | G4: Estates & Maintenance | H4: Estate&m MOM% | I4: Student Services | J4: Student s MOM% | K4: Marketing & Recruitment | L4: Marketing & Recruitment MOM% | M4: Professional Fees | N4: Professional fees MOM% | O4: Administration | P4: Admin Fees MOM% | Q4: Other Operating Expenditure | R4: other operating Expenditure MOM% | S4: Total Operating Expenditure
A5: 45139 | B5: FY23/24 | C5: 954545 | D5: =(C5-C6)/C5 -> -0.14285759 | E5: 1333333 | F5: =(E6-E5)/E5 -> 0 | G5: 2325203 | H5: =(G6-G5)/G5 -> 0 | I5: 1504132 | J5: =(I5-I6)/I5 -> 0.28571429 | K5: 1200000 | L5: =(K6-K5)/K5 -> -0.5 | M5: 333333 | N5: =(M5-M6)/M5 -> 0 | O5: 750000 | P5: =(O5-O6)/O5 -> 0 | Q5: 666667 | R5: =(Q6-Q5)/Q5 -> 0 | S5: =SUM(C5:Q5) -> 9067212.6
A6: 45170 | B6: FY23/24 | C6: 1090909 | D6: =(C6-C7)/C6 -> -0.24999977 | E6: 1333333 | F6: =(E7-E6)/E6 -> 0 | G6: 2325203 | H6: =(G7-G6)/G6 -> -0.38461545 | I6: 1074380 | J6: =(I6-I7)/I6 -> 0.1 | K6: 600000 | L6: =(K7-K6)/K6 -> -0.125 | M6: 333333 | N6: =(M6-M7)/M6 -> 0 | O6: 750000 | P6: =(O6-O7)/O6 -> 0 | Q6: 666667 | R6: =(Q7-Q6)/Q6 -> 0 | S6: =SUM(C6:Q6) -> 8173824.3
A7: 45200 | B7: FY23/24 | C7: 1363636 | D7: =(C7-C8)/C7 -> -0.30000015 | E7: 1333333 | F7: =(E8-E7)/E7 -> 0 | G7: 1430894 | H7: =(G8-G7)/G7 -> 0 | I7: 966942 | J7: =(I7-I8)/I7 -> 0 | K7: 525000 | L7: =(K8-K7)/K7 -> 0 | M7: 333333 | N7: =(M7-M8)/M7 -> 0 | O7: 750000 | P7: =(O7-O8)/O7 -> 0 | Q7: 666667 | R7: =(Q8-Q7)/Q7 -> 0 | S7: =SUM(C7:Q7) -> 7369804.7
A8: 45231 | B8: FY23/24 | C8: 1772727 | D8: =(C8-C9)/C8 -> -0.076923294 | E8: 1333333 | F8: =(E9-E8)/E8 -> 0 | G8: 1430894 | H8: =(G9-G8)/G8 -> 0 | I8: 966942 | J8: =(I8-I9)/I8 -> -0.44444444 | K8: 525000 | L8: =(K9-K8)/K8 -> 0.85714286 | M8: 333333 | N8: =(M8-M9)/M8 -> 0 | O8: 750000 | P8: =(O8-O9)/O8 -> 0 | Q8: 666667 | R8: =(Q9-Q8)/Q8 -> 0 | S8: =SUM(C8:Q8) -> 7778896.3
A9: 45261 | B9: FY23/24 | C9: 1909091 | D9: =(C9-C10)/C9 -> 0.071428759 | E9: 1333333 | F9: =(E10-E9)/E9 -> 0 | G9: 1430894 | H9: =(G10-G9)/G9 -> 0 | I9: 1396694 | J9: =(I9-I10)/I9 -> 0.23076923 | K9: 975000 | L9: =(K10-K9)/K9 -> 0.076923077 | M9: 333333 | N9: =(M9-M10)/M9 -> 0 | O9: 750000 | P9: =(O9-O10)/O9 -> 0 | Q9: 666667 | R9: =(Q10-Q9)/Q9 -> 0 | S9: =SUM(C9:Q9) -> 8795012.4
A10: 45292 | B10: FY23/24 | C10: 1772727 | D10: =(C10-C11)/C10 -> 0.15384602 | E10: 1333333 | F10: =(E11-E10)/E10 -> 0 | G10: 1430894 | H10: =(G11-G10)/G10 -> 0 | I10: 1074380 | J10: =(I10-I11)/I10 -> 0.1 | K10: 1050000 | L10: =(K11-K10)/K10 -> -0.071428571 | M10: 333333 | N10: =(M10-M11)/M10 -> -2.7500038 | O10: 750000 | P10: =(O10-O11)/O10 -> 0 | Q10: 666667 | R10: =(Q11-Q10)/Q10 -> 0 | S10: =SUM(C10:Q10) -> 8411331.4
A11: 45323 | B11: FY23/24 | C11: 1500000 | D11: =(C11-C12)/C11 -> 0.181818 | E11: 1333333 | F11: =(E12-E11)/E11 -> 0 | G11: 1430894 | H11: =(G12-G11)/G11 -> 0.12500017 | I11: 966942 | J11: =(I11-I12)/I11 -> 0 | K11: 975000 | L11: =(K12-K11)/K11 -> -0.30769231 | M11: 1250000 | N11: =(M11-M12)/M11 -> 0.7333336 | O11: 750000 | P11: =(O11-O12)/O11 -> 0 | Q11: 666667 | R11: =(Q12-Q11)/Q11 -> 0 | S11: =SUM(C11:Q11) -> 8872836.7
A12: 45352 | B12: FY23/24 | C12: 1227273 | D12: =(C12-C13)/C12 -> 0.22222277 | E12: 1333333 | F12: =(E13-E12)/E12 -> 0 | G12: 1609756 | H12: =(G13-G12)/G12 -> 0 | I12: 966942 | J12: =(I12-I13)/I12 -> 0 | K12: 675000 | L12: =(K13-K12)/K12 -> -0.22222222 | M12: 333333 | N12: =(M12-M13)/M12 -> 0 | O12: 750000 | P12: =(O12-O13)/O12 -> 0 | Q12: 666667 | R12: =(Q13-Q12)/Q12 -> 0 | S12: =SUM(C12:Q12) -> 7562304
A13: 45383 | B13: FY23/24 | C13: 954545 | D13: =(C13-C14)/C13 -> 0.14285654 | E13: 1333333 | F13: =(E14-E13)/E13 -> 0 | G13: 1609756 | H13: =(G14-G13)/G13 -> 0.2222225 | I13: 966942 | J13: =(I13-I14)/I13 -> 0 | K13: 525000 | L13: =(K14-K13)/K13 -> -0.14285714 | M13: 333333 | N13: =(M13-M14)/M13 -> 0 | O13: 750000 | P13: =(O13-O14)/O13 -> 0 | Q13: 666667 | R13: =(Q14-Q13)/Q13 -> 0 | S13: =SUM(C13:Q13) -> 7139576.2
A14: 45413 | B14: FY23/24 | C14: 818182 | D14: =(C14-C15)/C14 -> 0 | E14: 1333333 | F14: =(E15-E14)/E14 -> 0 | G14: 1967480 | H14: =(G15-G14)/G14 -> 0.27272704 | I14: 966942 | J14: =(I14-I15)/I14 -> -0.11111111 | K14: 450000 | L14: =(K15-K14)/K14 -> 0 | M14: 333333 | N14: =(M14-M15)/M14 -> 0 | O14: 750000 | P14: =(O14-O15)/O14 -> 0 | Q14: 666667 | R14: =(Q15-Q14)/Q14 -> 0 | S14: =SUM(C14:Q14) -> 7285937.2
A15: 45444 | B15: FY23/24 | C15: 818182 | D15: =(C15-C16)/C15 -> 0 | E15: 1333333 | F15: =(E16-E15)/E15 -> 0 | G15: 2504065 | H15: =(G16-G15)/G15 -> 0 | I15: 1074380 | J15: =(I15-I16)/I15 -> 0 | K15: 450000 | L15: =(K16-K15)/K15 -> 1.3333333 | M15: 333333 | N15: =(M15-M16)/M15 -> -0.25000225 | O15: 750000 | P15: =(O15-O16)/O15 -> 0 | Q15: 666667 | R15: =(Q16-Q15)/Q15 -> 0 | S15: =SUM(C15:Q15) -> 7929961.1
A16: 45474 | B16: FY23/24 | C16: 818182 | D16: =(C16-C17)/C16 -> -0.25999961 | E16: 1333333 | F16: =(E17-E16)/E16 -> 0.050000263 | G16: 2504065 | H16: =(G17-G16)/G16 -> -0.033441624 | I16: 1074380 | J16: =(I16-I17)/I16 -> -0.44307694 | K16: 1050000 | L16: =(K17-K16)/K16 -> 0.18095238 | M16: 416667 | N16: =(M16-M17)/M16 -> 0.18400065 | O16: 750000 | P16: =(O16-O17)/O16 -> -0.033333333 | Q16: 666667 | R16: =(Q17-Q16)/Q16 -> 0.024998988 | S16: =SUM(C16:Q16) -> 8613293.6
... A40: 46204 | B40: FY25/26 | C40: 954545 | D40: =(C40-C41)/C40 -> 1 | E40: 1466667 | F40: =(E41-E40)/E40 -> -1 | G40: 2708943 | H40: =(G41-G40)/G40 -> -1 | I40: 1140496 | J40: =(I40-I41)/I40 -> 1 | K40: 1120000 | L40: =(K41-K40)/K40 -> -1 | M40: 433333 | N40: =(M40-M41)/M40 -> 1 | O40: 800000 | P40: =(O40-O41)/O40 -> 1 | Q40: 700000 | R40: =(Q41-Q40)/Q40 -> -1 | S40: =SUM(C40:Q40) -> 9323985

Sheet Income Statement
A1: Vector University — Forecast Income Statement (Monthly Summary)
A4: Month | B4: FY | C4: Total Income | D4: Total Staff Costs | E4: Total Operating Expenditure | F4: Operating Surplus / (Deficit) | G4: Operating Margin %
A5: 45139 | B5: FY23/24 | C5: =Income!M5 -> 16137179 | D5: ='Staff Costs'!E5 -> 15000000 | E5: ='Operating Expenditure'!S5 -> 9067212.6 | F5: =C5-D5-E5 -> -7930033.3 | G5: =F5/C5 -> -0.49141384
A6: 45170 | B6: FY23/24 | C6: =Income!M6 -> 33586577 | D6: ='Staff Costs'!E6 -> 15000000 | E6: ='Operating Expenditure'!S6 -> 8173824.3 | F6: =C6-D6-E6 -> 10412752 | G6: =F6/C6 -> 0.3100272
A7: 45200 | B7: FY23/24 | C7: =Income!M7 -> 30596786 | D7: ='Staff Costs'!E7 -> 15000000 | E7: ='Operating Expenditure'!S7 -> 7369804.7 | F7: =C7-D7-E7 -> 8226981 | G7: =F7/C7 -> 0.26888383
A8: 45231 | B8: FY23/24 | C8: =Income!M8 -> 30849617 | D8: ='Staff Costs'!E8 -> 15000000 | E8: ='Operating Expenditure'!S8 -> 7778896.3 | F8: =C8-D8-E8 -> 8070720.8 | G8: =F8/C8 -> 0.26161494
A9: 45261 | B9: FY23/24 | C9: =Income!M9 -> 25563598 | D9: ='Staff Costs'!E9 -> 15000000 | E9: ='Operating Expenditure'!S9 -> 8795012.4 | F9: =C9-D9-E9 -> 1768585.5 | G9: =F9/C9 -> 0.069183746
A10: 45292 | B10: FY23/24 | C10: =Income!M10 -> 24915014 | D10: ='Staff Costs'!E10 -> 15000000 | E10: ='Operating Expenditure'!S10 -> 8411331.4 | F10: =C10-D10-E10 -> 1503683.1 | G10: =F10/C10 -> 0.060352486
A11: 45323 | B11: FY23/24 | C11: =Income!M11 -> 26575492 | D11: ='Staff Costs'!E11 -> 15000000 | E11: ='Operating Expenditure'!S11 -> 8872836.7 | F11: =C11-D11-E11 -> 2702655.1 | G11: =F11/C11 -> 0.10169727
A12: 45352 | B12: FY23/24 | C12: =Income!M12 -> 22199161 | D12: ='Staff Costs'!E12 -> 15000000 | E12: ='Operating Expenditure'!S12 -> 7562304 | F12: =C12-D12-E12 -> -363143.33 | G12: =F12/C12 -> -0.016358426
A13: 45383 | B13: FY23/24 | C13: =Income!M13 -> 21101098 | D13: ='Staff Costs'!E13 -> 15000000 | E13: ='Operating Expenditure'!S13 -> 7139576.2 | F13: =C13-D13-E13 -> -1038478.1 | G13: =F13/C13 -> -0.049214408
A14: 45413 | B14: FY23/24 | C14: =Income!M14 -> 22956887 | D14: ='Staff Costs'!E14 -> 15000000 | E14: ='Operating Expenditure'!S14 -> 7285937.2 | F14: =C14-D14-E14 -> 670950.17 | G14: =F14/C14 -> 0.029226531
A15: 45444 | B15: FY23/24 | C15: =Income!M15 -> 18323410 | D15: ='Staff Costs'!E15 -> 15000000 | E15: ='Operating Expenditure'!S15 -> 7929961.1 | F15: =C15-D15-E15 -> -4606551.1 | G15: =F15/C15 -> -0.2514025
A16: 45474 | B16: FY23/24 | C16: =Income!M16 -> 15014868 | D16: ='Staff Costs'!E16 -> 15000000 | E16: ='Operating Expenditure'!S16 -> 8613293.6 | F16: =C16-D16-E16 -> -8598425.3 | G16: =F16/C16 -> -0.57266072
... A40: 46204 | B40: FY25/26 | C40: =Income!M40 -> 16183471 | D40: ='Staff Costs'!E40 -> 16558333 | E40: ='Operating Expenditure'!S40 -> 9323985 | F40: =C40-D40-E40 -> -9698847.3 | G40: =F40/C40 -> -0.59930577
A43: Annual Summary (£)
A44: FY | B44: Total Income | C44: Total Staff Costs | D44: Total Operating Expenditure | E44: Operating Surplus / (Deficit) | F44: Operating Margin % | G44: YOY Income
A45: FY23/24 | B45: =SUM(C5:C16) -> 2.8781969e+08 | C45: =SUM(D5:D16) -> 180000000 | D45: =SUM(E5:E16) -> 96999991 | E45: =SUM(F5:F16) -> 10819697 | F45: =E45/B45 -> 0.037591927 | G45: =(B46-B45)/B45 -> 0.066703853
A46: FY24/25 | B46: =SUM(C17:C28) -> 3.0701837e+08 | C46: =SUM(D17:D28) -> 189500004 | D46: =SUM(E17:E28) -> 1.0119999e+08 | E46: =SUM(F17:F28) -> 16318375 | F46: =E46/B46 -> 0.053151136 | G46: =(B46-B45)/B46 -> 0.062532682
A47: FY25/26 | B47: =SUM(C29:C40) -> 3.1158911e+08 | C47: =SUM(D29:D40) -> 198699996 | D47: =SUM(E29:E40) -> 1.055e+08 | E47: =SUM(F29:F40) -> 7389111.5 | F47: =E47/B47 -> 0.02371428 | G47: =(B47-B46)/B47 -> 0.014669119

Sheet Cash Position
A1: Vector University — Cash Position (Monthly)
A4: Month | B4: FY | C4: Opening Cash | D4: Operating Surplus / (Deficit) | E4: Capital Expenditure | F4: Closing Cash
A5: 45139 | B5: FY23/24 | C5: 42000000 | D5: ='Income Statement'!F5 -> -7930033.3 | E5: 750000 | F5: =C5+D5-E5 -> 33319967
A6: 45170 | B6: FY23/24 | C6: =F5 -> 33319967 | D6: ='Income Statement'!F6 -> 10412752 | E6: 750000 | F6: =C6+D6-E6 -> 42982719
A7: 45200 | B7: FY23/24 | C7: =F6 -> 42982719 | D7: ='Income Statement'!F7 -> 8226981 | E7: 750000 | F7: =C7+D7-E7 -> 50459700
A8: 45231 | B8: FY23/24 | C8: =F7 -> 50459700 | D8: ='Income Statement'!F8 -> 8070720.8 | E8: 750000 | F8: =C8+D8-E8 -> 57780421
A9: 45261 | B9: FY23/24 | C9: =F8 -> 57780421 | D9: ='Income Statement'!F9 -> 1768585.5 | E9: 750000 | F9: =C9+D9-E9 -> 58799006
A10: 45292 | B10: FY23/24 | C10: =F9 -> 58799006 | D10: ='Income Statement'!F10 -> 1503683.1 | E10: 750000 | F10: =C10+D10-E10 -> 59552689
A11: 45323 | B11: FY23/24 | C11: =F10 -> 59552689 | D11: ='Income Statement'!F11 -> 2702655.1 | E11: 750000 | F11: =C11+D11-E11 -> 61505344
A12: 45352 | B12: FY23/24 | C12: =F11 -> 61505344 | D12: ='Income Statement'!F12 -> -363143.33 | E12: 750000 | F12: =C12+D12-E12 -> 60392201
A13: 45383 | B13: FY23/24 | C13: =F12 -> 60392201 | D13: ='Income Statement'!F13 -> -1038478.1 | E13: 750000 | F13: =C13+D13-E13 -> 58603723
A14: 45413 | B14: FY23/24 | C14: =F13 -> 58603723 | D14: ='Income Statement'!F14 -> 670950.17 | E14: 750000 | F14: =C14+D14-E14 -> 58524673
A15: 45444 | B15: FY23/24 | C15: =F14 -> 58524673 | D15: ='Income Statement'!F15 -> -4606551.1 | E15: 750000 | F15: =C15+D15-E15 -> 53168122
A16: 45474 | B16: FY23/24 | C16: =F15 -> 53168122 | D16: ='Income Statement'!F16 -> -8598425.3 | E16: 750000 | F16: =C16+D16-E16 -> 43819697
A17: 45505 | B17: FY24/25 | C17: =F16 -> 43819697 | D17: ='Income Statement'!F17 -> -7489796.6 | E17: 791667 | F17: =C17+D17-E17 -> 35538233
... A40: 46204 | B40: FY25/26 | C40: =F39 -> 58559364 | D40: ='Income Statement'!F40 -> -9698847.3 | E40: 833333 | F40: =C40+D40-E40 -> 48027183

Sheet Historical performance
A1: Vector University — Historical Performance Analysis
A3: Total Expenditure
A5: FY | B5: Sum of Total Operating Expenditure | C5: YOY
A6: FY23/24 | B6: 96999991 | C6: =(B7-B6)/B6 -> 0.043298973
A7: FY24/25 | B7: 1.0119999e+08 | C7: =(B8-B7)/B7 -> 0.042490215
A8: FY25/26 | B8: 1.055e+08 | C8: -
A9: Total Result | B9: 3.0369998e+08
A11: Breakdown of Total Operating Expenditure 1
B14: Data | F14: Utilities yoy % | G14: IT and digital services YOY % | H14: Estate and maintenance YOY%
A15: FY | B15: Sum of Total Operating Expenditure | C15: Sum of Utilities | D15: Sum of IT & Digital Services | E15: Sum of Estates & Maintenance | F15: =C15/B15 -> #VALUE! | G15: =D15/B15 -> #VALUE! | H15: =E15/B15 -> #VALUE!
A16: FY23/24 | B16: 96999991 | C16: 14999999 | D16: 15999996 | E16: 21999998 | F16: =C16/B16 -> 0.15463918 | G16: =D16/B16 -> 0.16494843 | H16: =E16/B16 -> 0.22680412
A17: FY24/25 | B17: 1.0119999e+08 | C17: 16199998 | D17: 16800000 | E17: 22900000 | F17: =C17/B17 -> 0.16007905 | G17: =D17/B17 -> 0.16600792 | H17: =E17/B17 -> 0.22628461
A18: FY25/26 | B18: 1.055e+08 | C18: 17499998 | D18: 17600004 | E18: 23799996 | F18: =C18/B18 -> 0.16587676 | G18: =D18/B18 -> 0.16682468 | H18: =E18/B18 -> 0.22559238
A19: Total Result | B19: 3.0369998e+08 | C19: 48699995 | D19: 50400000 | E19: 68699994
A21: Breakdown of Total Operating Expenditure 2
B23: Data | H23: Student Services yoy % | I23: Marketing&Recruitment YOY % | J23: Professional Fees YOY% | K23: Admin Fees YOY% | L23: Other OperatingExpenses YOY%
A24: FY | B24: Sum of Total Operating Expenditure | C24: Sum of Student Services | D24: Sum of Marketing & Recruitment | E24: Sum of Professional Fees | F24: Sum of Administration | G24: Sum of Other Operating Expenditure | H24: =C24/B24 -> #VALUE! | I24: =D24/B24 -> #VALUE! | J24: =E24/B24 -> #VALUE! | K24: =F24/B24 -> #VALUE! | L24: =G24/B24 -> #VALUE!
A25: FY23/24 | B25: 96999991 | C25: 12999998 | D25: 9000000 | E25: 4999997 | F25: 9000000 | G25: 8000004 | H25: =C25/B25 -> 0.13402061 | I25: =D25/B25 -> 0.092783514 | J25: =E25/B25 -> 0.051546366 | K25: =F25/B25 -> 0.092783514 | L25: =G25/B25 -> 0.082474276
A26: FY24/25 | B26: 1.0119999e+08 | C26: 13399998 | D26: 9300000 | E26: 5100000 | F26: 9300000 | G26: 8199996 | H26: =C26/B26 -> 0.13241106 | I26: =D26/B26 -> 0.091897242 | J26: =E26/B26 -> 0.050395262 | K26: =F26/B26 -> 0.091897242 | L26: =G26/B26 -> 0.081027636
A27: FY25/26 | B27: 1.055e+08 | C27: 13799999 | D27: 9600000 | E27: 5200003 | F27: 9600000 | G27: 8400000 | H27: =C27/B27 -> 0.13080568 | I27: =D27/B27 -> 0.090995261 | J27: =E27/B27 -> 0.049289128 | K27: =F27/B27 -> 0.090995261 | L27: =G27/B27 -> 0.079620853
A28: Total Result | B28: 3.0369998e+08 | C28: 40199995 | D28: 27900000 | E28: 15300000 | F28: 27900000 | G28: 24600000
A30: Breakdown of Total income
B32: Data
A33: FY | B33: Sum of Total Income | C33: Sum of UK Undergraduate Tuition | D33: Sum of International Undergraduate Tuition | E33: Sum of UK Postgraduate Tuition | F33: Sum of International Postgraduate Tuition | G33: Sum of Postgraduate Research (PGR) Tuition | H33: Sum of Research Grants & Contracts | I33: Sum of Government & Funding Body Grants | J33: Sum of Student Accommodation Income | K33: Sum of Commercial & Professional Services | L33: Sum of Other Operating Income
A34: FY23/24 | B34: 2.8781969e+08 | C34: 78105458 | D34: 37227333 | E34: 27295938 | F34: 48720750 | G34: 6470208.3 | H34: 32000000 | I34: 19000000 | J34: 24000000 | K34: 9000000 | L34: 6000000
A35: FY24/25 | B35: 3.0701837e+08 | C35: 78941812 | D35: 40154362 | E35: 30555350 | F35: 56696167 | G35: 7170675 | H35: 33500000 | I35: 19200000 | J35: 25099999 | K35: 9500000 | L35: 6200004
A36: FY25/26 | B36: 3.1158911e+08 | C36: 82690698 | D36: 40918842 | E36: 32359275 | F36: 51248833 | G36: 7871454.2 | H36: 34800000 | I36: 19000000 | J36: 26200001 | K36: 10000000 | L36: 6500004
A37: Total Result | B37: 9.0642716e+08 | C37: 2.3973797e+08 | D37: 1.1830054e+08 | E37: 90210562 | F37: 156665750 | G37: 21512338 | H37: 100300000 | I37: 57200000 | J37: 75300000 | K37: 28500000 | L37: 18700008

Sheet Historical KPI Summary
A1: Vector University — Historical KPI Summary & Corrected Analysis (FY23/24 – FY25/26)
A2: Corrects and extends the Day 2 historical review: annual KPI trend, tuition income ranking, and international recruitment dependency.
A4: A. Annual Financial KPI Trend
A5: FY | B5: Total Income (£) | C5: Income YoY % | D5: Total Staff Costs (£) | E5: Staff Cost YoY % | F5: Total Operating Expenditure (£) | G5: Opex YoY % | H5: Operating Surplus / (Deficit) (£) | I5: Operating Margin %
A6: FY23/24 | B6: ='Income Statement'!B45 -> 2.8781969e+08 | C6: ='Income Statement'!G45 -> 0.066703853 | D6: ='Income Statement'!C45 -> 180000000 | E6: n/a (no FY22/23 baseline) | F6: ='Income Statement'!D45 -> 96999991 | G6: n/a (no FY22/23 baseline) | H6: ='Income Statement'!E45 -> 10819697 | I6: ='Income Statement'!F45 -> 0.037591927
A7: FY24/25 | B7: ='Income Statement'!B46 -> 3.0701837e+08 | C7: ='Income Statement'!G46 -> 0.062532682 | D7: ='Income Statement'!C46 -> 189500004 | E7: =D7/D6-1 -> 0.0527778 | F7: ='Income Statement'!D46 -> 1.0119999e+08 | G7: =F7/F6-1 -> 0.043298973 | H7: ='Income Statement'!E46 -> 16318375 | I7: ='Income Statement'!F46 -> 0.053151136
A8: FY25/26 | B8: ='Income Statement'!B47 -> 3.1158911e+08 | C8: ='Income Statement'!G47 -> 0.014669119 | D8: ='Income Statement'!C47 -> 198699996 | E8: =D8/D7-1 -> 0.048548769 | F8: ='Income Statement'!D47 -> 1.055e+08 | G8: =F8/F7-1 -> 0.042490215 | H8: ='Income Statement'!E47 -> 7389111.5 | I8: ='Income Statement'!F47 -> 0.02371428
A10: B. Key Findings (corrected per 15-Sep-2026 feedback)
A11: 1. Income growth decelerated sharply from 6.7% in FY24/25 to just 1.5% in FY25/26 (after 6.3% growth the year before), while staff cost growth (5.3% → 4.9%) and operating cost growth (4.3% → 4.2%) continued at a broadly similar pace. Because staff costs and operating expenditure together represent c.90% of total costs and cannot be reduced as quickly as income can fall, a period of income deceleration compresses profitability disproportionately — exactly what the FY25/26 numbers show.
A12: 2. Operating margin rose from 3.8% (FY23/24) to a peak of 5.3% (FY24/25), then fell sharply to 2.4% (FY25/26). In cash terms, operating surplus fell from £16.32m in FY24/25 to £7.39m in FY25/26 — a decline of approximately 54.7% in a single year. This is the single most important finding in the historical data and is an early warning indicator for financial sustainability if income growth does not recover.
A13: 3. Correction: UK Undergraduate tuition, not International Postgraduate, is the University's largest individual tuition category — £82.69m in FY25/26 versus £51.25m for International Postgraduate. International Postgraduate is nonetheless the largest single INTERNATIONAL income stream and, combined with International Undergraduate (£40.92m), international tuition (£92.17m) represents c.42.9% of tuition income and c.29.6% of total University income — a material, though not majority, dependency (see Section D).
A15: C. Tuition Income by Category — FY25/26 (Ranked, Corrected)
A16: Rank | B16: Category | C16: FY25/26 Tuition Income (£) | D16: % of Total Tuition Income
A17: 1 | B17: UK Undergraduate | C17: =SUMIFS(Income!C:C,Income!$B:$B,"FY25/26") -> 82690698 | D17: =C17/C22 -> 0.38444857
A18: 2 | B18: International Postgraduate | C18: =SUMIFS(Income!F:F,Income!$B:$B,"FY25/26") -> 51248833 | D18: =C18/C22 -> 0.23826792
A19: 3 | B19: International Undergraduate | C19: =SUMIFS(Income!D:D,Income!$B:$B,"FY25/26") -> 40918842 | D19: =C19/C22 -> 0.19024135
A20: 4 | B20: UK Postgraduate | C20: =SUMIFS(Income!E:E,Income!$B:$B,"FY25/26") -> 32359275 | D20: =C20/C22 -> 0.15044591
A21: 5 | B21: Postgraduate Research (PGR) | C21: =SUMIFS(Income!G:G,Income!$B:$B,"FY25/26") -> 7871454.2 | D21: =C21/C22 -> 0.036596248
A22: Total | C22: =SUM(C17:C21) -> 2.150891e+08 | D22: =SUM(D17:D21) -> 1
A24: D. International Recruitment Dependency — FY25/26
A25: International Undergraduate tuition (£) | B25: =SUMIFS(Income!D:D,Income!$B:$B,"FY25/26") -> 40918842
A26: International Postgraduate tuition (£) | B26: =SUMIFS(Income!F:F,Income!$B:$B,"FY25/26") -> 51248833
A27: Total international tuition income (£) | B27: =B25+B26 -> 92167675
A28: Total tuition income, all categories (£) | B28: =C22 -> 2.150891e+08
A29: International share of total tuition income (%) | B29: =B27/B28 -> 0.42850927
A30: Total University income, FY25/26 (£) | B30: ='Income Statement'!B47 -> 3.1158911e+08
A31: International tuition as % of total University income | B31: =B27/B30 -> 0.29579877
A33: Sources: 'Income Statement' (annual summary, rows 45-47). Tuition income by category is summed directly from monthly actuals on the 'Income' tab via SUMIFS (not from the 'Historical performance' pivot tables, whose row positions shift whenever the pivot cache is refreshed). Staff Cost YoY % and Operating Expenditure YoY % are derived here (not present in the original Income Statement tab).

Sheet Scenario Assumptions
A1: Vector University — Scenario Assumptions (Base / Upside / Downside)
A2: Pick a scenario in the selector below and 'Forecast Assumptions' — and everything downstream (Population, Income, Staff Cost, Opex, Forecast Income Statement, Cash Flow) — recalculates for it. Base Case values are the original assumptions from the initial build; Upside and Downside are point-in-time adjustments (in percentage points) applied on top of them for the three tested levers.
A4: A. Scenario Selector
A5: Active Scenario: | B5: Base
A7: B. Scenario Adjustment Levers (percentage points, applied on top of Base)
A8: Lever | B8: Base | C8: Upside | D8: Downside
A9: Recruitment Growth Adjustment (applied to every category's Application Growth %, every year) | B9: 0 | C9: 0.02 | D9: -0.03
A10: Salary Inflation Adjustment (applied to Academic & Professional Services Salary Inflation %, every year) | B10: 0 | C10: -0.01 | D10: 0.015
A11: Operating Cost Inflation Adjustment (applied to Utilities & General Operating Cost Inflation %, every year) | B11: 0 | C11: -0.005 | D11: 0.01
A13: C. Selected Adjustment (driven by the Scenario Selector above)
A14: Lever | B14: Selected Value
A15: Recruitment Growth Adjustment (applied to every category's Application Growth %, every year) | B15: =IF(B5="Base",B9,IF(B5="Upside",C9,D9)) -> 0
A16: Salary Inflation Adjustment (applied to Academic & Professional Services Salary Inflation %, every year) | B16: =IF(B5="Base",B10,IF(B5="Upside",C10,D10)) -> 0
A17: Operating Cost Inflation Adjustment (applied to Utilities & General Operating Cost Inflation %, every year) | B17: =IF(B5="Base",B11,IF(B5="Upside",C11,D11)) -> 0
A19: D. Base Case Reference Values (original FY26/27–FY28/29 assumptions)
A20: Item | B20: FY26/27 | C20: FY27/28 | D20: FY28/29
A21: D1. Application Growth % by category
A22: UK Undergraduate | B22: 0.02 | C22: 0.02 | D22: 0.02
A23: International Undergraduate | B23: 0.01 | C23: 0.01 | D23: 0.02
A24: UK Postgraduate | B24: 0.02 | C24: 0.02 | D24: 0.02
A25: International Postgraduate | B25: 0.01 | C25: 0.02 | D25: 0.02
A26: Postgraduate Research (PGR) | B26: 0.02 | C26: 0.02 | D26: 0.02
A28: D2. Salary Inflation % by staff group
A29: Academic | B29: 0.045 | C29: 0.04 | D29: 0.04
A30: Professional Services | B30: 0.04 | C30: 0.04 | D30: 0.04
A32: D3. Operating Cost Inflation % by line
A33: Utilities | B33: 0.05 | C33: 0.04 | D33: 0.035
A34: General (IT/Estates/Student Services/Marketing/Prof Fees/Admin/Other) | B34: 0.035 | C34: 0.035 | D34: 0.035
A36: Blue cells are the editable inputs. Section D holds the original Base Case numbers (now referenced by 'Forecast Assumptions' rather than typed there directly); Section B holds the Upside/Downside deltas; Section C shows which delta is currently active. Change the selector in Section A to switch the whole model.

Sheet Forecast Assumptions
A1: Vector University — Forecast Assumptions (FY26/27 – FY28/29)
A4: A. Student Recruitment Assumptions (by category)
A5: Category | B5: Assumption | C5: FY26/27 | D5: FY27/28 | E5: FY28/29
A6: UK Undergraduate | B6: Application Growth % | C6: ='Scenario Assumptions'!B22+'Scenario Assumptions'!$B$15 -> 0.02 | D6: ='Scenario Assumptions'!C22+'Scenario Assumptions'!$B$15 -> 0.02 | E6: ='Scenario Assumptions'!D22+'Scenario Assumptions'!$B$15 -> 0.02
B7: Offer Rate % | C7: 0.78 | D7: 0.78 | E7: 0.78
B8: Acceptance / Yield Rate % | C8: 0.62 | D8: 0.62 | E8: 0.63
B9: Annual Withdrawal Rate % | C9: 0.018 | D9: 0.018 | E9: 0.018
B10: Typical Course Length (Years) | C10: 3 | D10: 3 | E10: 3
A11: International Undergraduate | B11: Application Growth % | C11: ='Scenario Assumptions'!B23+'Scenario Assumptions'!$B$15 -> 0.01 | D11: ='Scenario Assumptions'!C23+'Scenario Assumptions'!$B$15 -> 0.01 | E11: ='Scenario Assumptions'!D23+'Scenario Assumptions'!$B$15 -> 0.02
B12: Offer Rate % | C12: 0.7 | D12: 0.7 | E12: 0.7
B13: Acceptance / Yield Rate % | C13: 0.44 | D13: 0.44 | E13: 0.45
B14: Annual Withdrawal Rate % | C14: 0.033 | D14: 0.033 | E14: 0.033
B15: Typical Course Length (Years) | C15: 3 | D15: 3 | E15: 3
A16: UK Postgraduate | B16: Application Growth % | C16: ='Scenario Assumptions'!B24+'Scenario Assumptions'!$B$15 -> 0.02 | D16: ='Scenario Assumptions'!C24+'Scenario Assumptions'!$B$15 -> 0.02 | E16: ='Scenario Assumptions'!D24+'Scenario Assumptions'!$B$15 -> 0.02
B17: Offer Rate % | C17: 0.82 | D17: 0.82 | E17: 0.82
B18: Acceptance / Yield Rate % | C18: 0.68 | D18: 0.68 | E18: 0.69
B19: Annual Withdrawal Rate % | C19: 0.02 | D19: 0.02 | E19: 0.02
B20: Typical Course Length (Years) | C20: 1 | D20: 1 | E20: 1
A21: International Postgraduate | B21: Application Growth % | C21: ='Scenario Assumptions'!B25+'Scenario Assumptions'!$B$15 -> 0.01 | D21: ='Scenario Assumptions'!C25+'Scenario Assumptions'!$B$15 -> 0.02 | E21: ='Scenario Assumptions'!D25+'Scenario Assumptions'!$B$15 -> 0.02
B22: Offer Rate % | C22: 0.74 | D22: 0.73 | E22: 0.73
B23: Acceptance / Yield Rate % | C23: 0.44 | D23: 0.45 | E23: 0.45
B24: Annual Withdrawal Rate % | C24: 0.025 | D24: 0.025 | E24: 0.025
B25: Typical Course Length (Years) | C25: 1 | D25: 1 | E25: 1
A26: Postgraduate Research (PGR) | B26: Application Growth % | C26: ='Scenario Assumptions'!B26+'Scenario Assumptions'!$B$15 -> 0.02 | D26: ='Scenario Assumptions'!C26+'Scenario Assumptions'!$B$15 -> 0.02 | E26: ='Scenario Assumptions'!D26+'Scenario Assumptions'!$B$15 -> 0.02
B27: Offer Rate % | C27: 0.58 | D27: 0.58 | E27: 0.58
B28: Acceptance / Yield Rate % | C28: 0.75 | D28: 0.75 | E28: 0.75
B29: Annual Withdrawal Rate % | C29: 0.012 | D29: 0.012 | E29: 0.012
B30: Typical Course Length (Years) | C30: 4 | D30: 4 | E30: 4
A32: B. Tuition Fee Increase Assumptions (% YoY, by category)
A33: Item | B33: FY26/27 | C33: FY27/28 | D33: FY28/29
A34: UK Undergraduate | B34: 0 | C34: 0.02 | D34: 0.02
A35: International Undergraduate | B35: 0.04 | C35: 0.04 | D35: 0.045
A36: UK Postgraduate | B36: 0.03 | C36: 0.03 | D36: 0.03
A37: International Postgraduate | B37: 0.04 | C37: 0.04 | D37: 0.045
A38: Postgraduate Research (PGR) | B38: 0.03 | C38: 0.03 | D38: 0.03
A40: C. Other Income Growth Assumptions (% YoY, by income line)
A41: Item | B41: FY26/27 | C41: FY27/28 | D41: FY28/29
A42: Research Grants & Contracts | B42: 0.03 | C42: 0.03 | D42: 0.03
A43: Government & Funding Body Grants | B43: 0 | C43: 0 | D43: 0.01
A44: Student Accommodation Income | B44: 0.04 | C44: 0.04 | D44: 0.04
...

Sheet Population Forecast
A1: Vector University — 36-Month Student Population Forecast (FY26/27 – FY28/29)
A2: Methodology: Applications are back-solved from FY25/26 New Enrolments ÷ (Offer Rate × Yield Rate), then grown by each category's Application Growth % assumption; New Enrolments = Applications × Offer Rate × Yield Rate for that year. Monthly population = the forecast September (intake-month) population for that financial year, shaped by the category's FY25/26 monthly seasonal pattern — which is why Undergraduate and PGR populations stay relatively stable month to month while taught Postgraduate populations show the sharp September-intake, steady-decay pattern seen in the historical data.
A4: A. Annual New Enrolment & Population Roll-Forward (FY26/27 – FY28/29)
A5: Category | B5: FY | C5: Opening Population | D5: Applications | E5: Application Growth % | F5: Offer Rate % | G5: Yield Rate % | H5: New Enrolments | I5: Withdrawal Rate % | J5: Withdrawals | K5: Graduates | L5: Closing Population | M5: Retention Rate %
A6: UK Undergraduate | B6: FY26/27 | C6: ='Student Flow Summary'!G7 -> 6273 | D6: =('Student Flow Summary'!D7/(F6*G6))*(1+E6) -> 6538.4615 | E6: ='Forecast Assumptions'!C6 -> 0.02 | F6: ='Forecast Assumptions'!C7 -> 0.78 | G6: ='Forecast Assumptions'!C8 -> 0.62 | H6: =D6*F6*G6 -> 3162 | I6: ='Forecast Assumptions'!C9 -> 0.018 | J6: =I6*(C6+H6) -> 169.83 | K6: ='Student Flow Summary'!F7*(H6/'Student Flow Summary'!D7) -> 2907 | L6: =C6+H6-J6-K6 -> 6358.17 | M6: =1-J6/(C6+H6) -> 0.982
A7: UK Undergraduate | B7: FY27/28 | C7: =L6 -> 6358.17 | D7: =D6*(1+E7) -> 6669.2308 | E7: ='Forecast Assumptions'!D6 -> 0.02 | F7: ='Forecast Assumptions'!D7 -> 0.78 | G7: ='Forecast Assumptions'!D8 -> 0.62 | H7: =D7*F7*G7 -> 3225.24 | I7: ='Forecast Assumptions'!D9 -> 0.018 | J7: =I7*(C7+H7) -> 172.50138 | K7: =K6*(H7/H6) -> 2965.14 | L7: =C7+H7-J7-K7 -> 6445.7686 | M7: =1-J7/(C7+H7) -> 0.982
A8: UK Undergraduate | B8: FY28/29 | C8: =L7 -> 6445.7686 | D8: =D7*(1+E8) -> 6802.6154 | E8: ='Forecast Assumptions'!E6 -> 0.02 | F8: ='Forecast Assumptions'!E7 -> 0.78 | G8: ='Forecast Assumptions'!E8 -> 0.63 | H8: =D8*F8*G8 -> 3342.8052 | I8: ='Forecast Assumptions'!E9 -> 0.018 | J8: =I8*(C8+H8) -> 176.19433 | K8: =K7*(H8/H7) -> 3073.2241 | L8: =C8+H8-J8-K8 -> 6539.1554 | M8: =1-J8/(C8+H8) -> 0.982
A9: International Undergraduate | B9: FY26/27 | C9: ='Student Flow Summary'!G10 -> 1408 | D9: =('Student Flow Summary'!D10/(F9*G9))*(1+E9) -> 2115.0974 | E9: ='Forecast Assumptions'!C11 -> 0.01 | F9: ='Forecast Assumptions'!C12 -> 0.7 | G9: ='Forecast Assumptions'!C13 -> 0.44 | H9: =D9*F9*G9 -> 651.45 | I9: ='Forecast Assumptions'!C14 -> 0.033 | J9: =I9*(C9+H9) -> 67.96185 | K9: ='Student Flow Summary'!F10*(H9/'Student Flow Summary'!D10) -> 628.22 | L9: =C9+H9-J9-K9 -> 1363.2682 | M9: =1-J9/(C9+H9) -> 0.967
A10: International Undergraduate | B10: FY27/28 | C10: =L9 -> 1363.2682 | D10: =D9*(1+E10) -> 2136.2484 | E10: ='Forecast Assumptions'!D11 -> 0.01 | F10: ='Forecast Assumptions'!D12 -> 0.7 | G10: ='Forecast Assumptions'!D13 -> 0.44 | H10: =D10*F10*G10 -> 657.9645 | I10: ='Forecast Assumptions'!D14 -> 0.033 | J10: =I10*(C10+H10) -> 66.700677 | K10: =K9*(H10/H9) -> 634.5022 | L10: =C10+H10-J10-K10 -> 1320.0298 | M10: =1-J10/(C10+H10) -> 0.967
A11: International Undergraduate | B11: FY28/29 | C11: =L10 -> 1320.0298 | D11: =D10*(1+E11) -> 2178.9733 | E11: ='Forecast Assumptions'!E11 -> 0.02 | F11: ='Forecast Assumptions'!E12 -> 0.7 | G11: ='Forecast Assumptions'!E13 -> 0.45 | H11: =D11*F11*G11 -> 686.3766 | I11: ='Forecast Assumptions'!E14 -> 0.033 | J11: =I11*(C11+H11) -> 66.21141 | K11: =K10*(H11/H10) -> 661.90116 | L11: =C11+H11-J11-K11 -> 1278.2938 | M11: =1-J11/(C11+H11) -> 0.967
A12: UK Postgraduate | B12: FY26/27 | C12: ='Student Flow Summary'!G13 -> 947 | D12: =('Student Flow Summary'!D13/(F12*G12))*(1+E12) -> 13759.756 | E12: ='Forecast Assumptions'!C16 -> 0.02 | F12: ='Forecast Assumptions'!C17 -> 0.82 | G12: ='Forecast Assumptions'!C18 -> 0.68 | H12: =D12*F12*G12 -> 7672.44 | I12: ='Forecast Assumptions'!C19 -> 0.02 | J12: =I12*(C12+H12) -> 172.3888 | K12: ='Student Flow Summary'!F13*(H12/'Student Flow Summary'!D13) -> 7038 | L12: =C12+H12-J12-K12 -> 1409.0512 | M12: =1-J12/(C12+H12) -> 0.98
A13: UK Postgraduate | B13: FY27/28 | C13: =L12 -> 1409.0512 | D13: =D12*(1+E13) -> 14034.951 | E13: ='Forecast Assumptions'!D16 -> 0.02 | F13: ='Forecast Assumptions'!D17 -> 0.82 | G13: ='Forecast Assumptions'!D18 -> 0.68 | H13: =D13*F13*G13 -> 7825.8888 | I13: ='Forecast Assumptions'!D19 -> 0.02 | J13: =I13*(C13+H13) -> 184.6988 | K13: =K12*(H13/H12) -> 7178.76 | L13: =C13+H13-J13-K13 -> 1871.4812 | M13: =1-J13/(C13+H13) -> 0.98
A14: UK Postgraduate | B14: FY28/29 | C14: =L13 -> 1871.4812 | D14: =D13*(1+E14) -> 14315.65 | E14: ='Forecast Assumptions'!E16 -> 0.02 | F14: ='Forecast Assumptions'!E17 -> 0.82 | G14: ='Forecast Assumptions'!E18 -> 0.69 | H14: =D14*F14*G14 -> 8099.7949 | I14: ='Forecast Assumptions'!E19 -> 0.02 | J14: =I14*(C14+H14) -> 199.42552 | K14: =K13*(H14/H13) -> 7430.0166 | L14: =C14+H14-J14-K14 -> 2341.834 | M14: =1-J14/(C14+H14) -> 0.98
A15: International Postgraduate | B15: FY26/27 | C15: ='Student Flow Summary'!G16 -> 689 | D15: =('Student Flow Summary'!D16/(F15*G15))*(1+E15) -> 17938.667 | E15: ='Forecast Assumptions'!C21 -> 0.01 | F15: ='Forecast Assumptions'!C22 -> 0.74 | G15: ='Forecast Assumptions'!C23 -> 0.44 | H15: =D15*F15*G15 -> 5840.83 | I15: ='Forecast Assumptions'!C24 -> 0.025 | J15: =I15*(C15+H15) -> 163.24575 | K15: ='Student Flow Summary'!F16*(H15/'Student Flow Summary'!D16) -> 5477.23 | L15: =C15+H15-J15-K15 -> 889.35425 | M15: =1-J15/(C15+H15) -> 0.975
A16: International Postgraduate | B16: FY27/28 | C16: =L15 -> 889.35425 | D16: =D15*(1+E16) -> 18297.44 | E16: ='Forecast Assumptions'!D21 -> 0.02 | F16: ='Forecast Assumptions'!D22 -> 0.73 | G16: ='Forecast Assumptions'!D23 -> 0.45 | H16: =D16*F16*G16 -> 6010.7092 | I16: ='Forecast Assumptions'!D24 -> 0.025 | J16: =I16*(C16+H16) -> 172.50159 | K16: =K15*(H16/H15) -> 5636.534 | L16: =C16+H16-J16-K16 -> 1091.0279 | M16: =1-J16/(C16+H16) -> 0.975
A17: International Postgraduate | B17: FY28/29 | C17: =L16 -> 1091.0279 | D17: =D16*(1+E17) -> 18663.389 | E17: ='Forecast Assumptions'!E21 -> 0.02 | F17: ='Forecast Assumptions'!E22 -> 0.73 | G17: ='Forecast Assumptions'!E23 -> 0.45 | H17: =D17*F17*G17 -> 6130.9234 | I17: ='Forecast Assumptions'!E24 -> 0.025 | J17: =I17*(C17+H17) -> 180.54878 | K17: =K16*(H17/H16) -> 5749.2646 | L17: =C17+H17-J17-K17 -> 1292.1378 | M17: =1-J17/(C17+H17) -> 0.975
